[03.04.2024 01:22:37 - ERROR] Internal Server Error: /api/v1/order/create/, PATH: A:\test\AnturajSurgut\.venv\Lib\site-packages\django\utils\log.py, line: 241
Traceback (most recent call last):
  File "A:\test\AnturajSurgut\.venv\Lib\site-packages\django\core\handlers\exception.py", line 55, in inner
    response = get_response(request)
               ^^^^^^^^^^^^^^^^^^^^^
  File "A:\test\AnturajSurgut\.venv\Lib\site-packages\django\core\handlers\base.py", line 197, in _get_response
    response = wrapped_callback(request, *callback_args, **callback_kwargs)
               ^^^^^^^^^^^^^^^^^^^^^^^^^^^^^^^^^^^^^^^^^^^^^^^^^^^^^^^^^^^^
  File "A:\test\AnturajSurgut\.venv\Lib\site-packages\django\views\decorators\csrf.py", line 65, in _view_wrapper
    return view_func(request, *args, **kwargs)
           ^^^^^^^^^^^^^^^^^^^^^^^^^^^^^^^^^^^
  File "A:\test\AnturajSurgut\.venv\Lib\site-packages\django\views\generic\base.py", line 104, in view
    return self.dispatch(request, *args, **kwargs)
           ^^^^^^^^^^^^^^^^^^^^^^^^^^^^^^^^^^^^^^^
  File "A:\test\AnturajSurgut\.venv\Lib\site-packages\rest_framework\views.py", line 509, in dispatch
    response = self.handle_exception(exc)
               ^^^^^^^^^^^^^^^^^^^^^^^^^^
  File "A:\test\AnturajSurgut\.venv\Lib\site-packages\rest_framework\views.py", line 469, in handle_exception
    self.raise_uncaught_exception(exc)
  File "A:\test\AnturajSurgut\.venv\Lib\site-packages\rest_framework\views.py", line 480, in raise_uncaught_exception
    raise exc
  File "A:\test\AnturajSurgut\.venv\Lib\site-packages\rest_framework\views.py", line 506, in dispatch
    response = handler(request, *args, **kwargs)
               ^^^^^^^^^^^^^^^^^^^^^^^^^^^^^^^^^
  File "A:\test\AnturajSurgut\.venv\Lib\site-packages\rest_framework\decorators.py", line 50, in handler
    return func(*args, **kwargs)
           ^^^^^^^^^^^^^^^^^^^^^
  File "A:\test\AnturajSurgut\backend\order\views.py", line 34, in create_order
    serializer.save()
  File "A:\test\AnturajSurgut\.venv\Lib\site-packages\rest_framework\serializers.py", line 212, in save
    self.instance = self.create(validated_data)
                    ^^^^^^^^^^^^^^^^^^^^^^^^^^^
  File "A:\test\AnturajSurgut\backend\order\serializers\OrderSerializers.py", line 110, in create
    order = Order.objects.create(**validated_data)
            ^^^^^^^^^^^^^^^^^^^^^^^^^^^^^^^^^^^^^^
  File "A:\test\AnturajSurgut\.venv\Lib\site-packages\django\db\models\manager.py", line 87, in manager_method
    return getattr(self.get_queryset(), name)(*args, **kwargs)
           ^^^^^^^^^^^^^^^^^^^^^^^^^^^^^^^^^^^^^^^^^^^^^^^^^^^
  File "A:\test\AnturajSurgut\.venv\Lib\site-packages\django\db\models\query.py", line 677, in create
    obj.save(force_insert=True, using=self.db)
  File "A:\test\AnturajSurgut\backend\order\models.py", line 170, in save
    self.full_clean()
  File "A:\test\AnturajSurgut\.venv\Lib\site-packages\django\db\models\base.py", line 1552, in full_clean
    raise ValidationError(errors)
django.core.exceptions.ValidationError: {'payment_type': ['Это поле не может иметь значение NULL.']}
[03.04.2024 01:23:01 - ERROR] Internal Server Error: /api/v1/order/create/, PATH: A:\test\AnturajSurgut\.venv\Lib\site-packages\django\utils\log.py, line: 241
Traceback (most recent call last):
  File "A:\test\AnturajSurgut\.venv\Lib\site-packages\django\core\handlers\exception.py", line 55, in inner
    response = get_response(request)
               ^^^^^^^^^^^^^^^^^^^^^
  File "A:\test\AnturajSurgut\.venv\Lib\site-packages\django\core\handlers\base.py", line 197, in _get_response
    response = wrapped_callback(request, *callback_args, **callback_kwargs)
               ^^^^^^^^^^^^^^^^^^^^^^^^^^^^^^^^^^^^^^^^^^^^^^^^^^^^^^^^^^^^
  File "A:\test\AnturajSurgut\.venv\Lib\site-packages\django\views\decorators\csrf.py", line 65, in _view_wrapper
    return view_func(request, *args, **kwargs)
           ^^^^^^^^^^^^^^^^^^^^^^^^^^^^^^^^^^^
  File "A:\test\AnturajSurgut\.venv\Lib\site-packages\django\views\generic\base.py", line 104, in view
    return self.dispatch(request, *args, **kwargs)
           ^^^^^^^^^^^^^^^^^^^^^^^^^^^^^^^^^^^^^^^
  File "A:\test\AnturajSurgut\.venv\Lib\site-packages\rest_framework\views.py", line 509, in dispatch
    response = self.handle_exception(exc)
               ^^^^^^^^^^^^^^^^^^^^^^^^^^
  File "A:\test\AnturajSurgut\.venv\Lib\site-packages\rest_framework\views.py", line 469, in handle_exception
    self.raise_uncaught_exception(exc)
  File "A:\test\AnturajSurgut\.venv\Lib\site-packages\rest_framework\views.py", line 480, in raise_uncaught_exception
    raise exc
  File "A:\test\AnturajSurgut\.venv\Lib\site-packages\rest_framework\views.py", line 506, in dispatch
    response = handler(request, *args, **kwargs)
               ^^^^^^^^^^^^^^^^^^^^^^^^^^^^^^^^^
  File "A:\test\AnturajSurgut\.venv\Lib\site-packages\rest_framework\decorators.py", line 50, in handler
    return func(*args, **kwargs)
           ^^^^^^^^^^^^^^^^^^^^^
  File "A:\test\AnturajSurgut\backend\order\views.py", line 34, in create_order
    serializer.save()
  File "A:\test\AnturajSurgut\.venv\Lib\site-packages\rest_framework\serializers.py", line 212, in save
    self.instance = self.create(validated_data)
                    ^^^^^^^^^^^^^^^^^^^^^^^^^^^
  File "A:\test\AnturajSurgut\backend\order\serializers\OrderSerializers.py", line 110, in create
    order = Order.objects.create(**validated_data)
            ^^^^^^^^^^^^^^^^^^^^^^^^^^^^^^^^^^^^^^
  File "A:\test\AnturajSurgut\.venv\Lib\site-packages\django\db\models\manager.py", line 87, in manager_method
    return getattr(self.get_queryset(), name)(*args, **kwargs)
           ^^^^^^^^^^^^^^^^^^^^^^^^^^^^^^^^^^^^^^^^^^^^^^^^^^^
  File "A:\test\AnturajSurgut\.venv\Lib\site-packages\django\db\models\query.py", line 675, in create
    obj = self.model(**kwargs)
          ^^^^^^^^^^^^^^^^^^^^
  File "A:\test\AnturajSurgut\.venv\Lib\site-packages\django\db\models\base.py", line 543, in __init__
    _setattr(self, field.name, rel_obj)
  File "A:\test\AnturajSurgut\.venv\Lib\site-packages\django\db\models\fields\related_descriptors.py", line 283, in __set__
    raise ValueError(
ValueError: Cannot assign "'1'": "Order.payment_type" must be a "PaymentType" instance.
[03.04.2024 01:23:27 - ERROR] Internal Server Error: /api/v1/order/create/, PATH: A:\test\AnturajSurgut\.venv\Lib\site-packages\django\utils\log.py, line: 241
Traceback (most recent call last):
  File "A:\test\AnturajSurgut\.venv\Lib\site-packages\django\core\handlers\exception.py", line 55, in inner
    response = get_response(request)
               ^^^^^^^^^^^^^^^^^^^^^
  File "A:\test\AnturajSurgut\.venv\Lib\site-packages\django\core\handlers\base.py", line 197, in _get_response
    response = wrapped_callback(request, *callback_args, **callback_kwargs)
               ^^^^^^^^^^^^^^^^^^^^^^^^^^^^^^^^^^^^^^^^^^^^^^^^^^^^^^^^^^^^
  File "A:\test\AnturajSurgut\.venv\Lib\site-packages\django\views\decorators\csrf.py", line 65, in _view_wrapper
    return view_func(request, *args, **kwargs)
           ^^^^^^^^^^^^^^^^^^^^^^^^^^^^^^^^^^^
  File "A:\test\AnturajSurgut\.venv\Lib\site-packages\django\views\generic\base.py", line 104, in view
    return self.dispatch(request, *args, **kwargs)
           ^^^^^^^^^^^^^^^^^^^^^^^^^^^^^^^^^^^^^^^
  File "A:\test\AnturajSurgut\.venv\Lib\site-packages\rest_framework\views.py", line 509, in dispatch
    response = self.handle_exception(exc)
               ^^^^^^^^^^^^^^^^^^^^^^^^^^
  File "A:\test\AnturajSurgut\.venv\Lib\site-packages\rest_framework\views.py", line 469, in handle_exception
    self.raise_uncaught_exception(exc)
  File "A:\test\AnturajSurgut\.venv\Lib\site-packages\rest_framework\views.py", line 480, in raise_uncaught_exception
    raise exc
  File "A:\test\AnturajSurgut\.venv\Lib\site-packages\rest_framework\views.py", line 506, in dispatch
    response = handler(request, *args, **kwargs)
               ^^^^^^^^^^^^^^^^^^^^^^^^^^^^^^^^^
  File "A:\test\AnturajSurgut\.venv\Lib\site-packages\rest_framework\decorators.py", line 50, in handler
    return func(*args, **kwargs)
           ^^^^^^^^^^^^^^^^^^^^^
  File "A:\test\AnturajSurgut\backend\order\views.py", line 34, in create_order
    serializer.save()
  File "A:\test\AnturajSurgut\.venv\Lib\site-packages\rest_framework\serializers.py", line 212, in save
    self.instance = self.create(validated_data)
                    ^^^^^^^^^^^^^^^^^^^^^^^^^^^
  File "A:\test\AnturajSurgut\backend\order\serializers\OrderSerializers.py", line 110, in create
    order = Order.objects.create(**validated_data)
            ^^^^^^^^^^^^^^^^^^^^^^^^^^^^^^^^^^^^^^
  File "A:\test\AnturajSurgut\.venv\Lib\site-packages\django\db\models\manager.py", line 87, in manager_method
    return getattr(self.get_queryset(), name)(*args, **kwargs)
           ^^^^^^^^^^^^^^^^^^^^^^^^^^^^^^^^^^^^^^^^^^^^^^^^^^^
  File "A:\test\AnturajSurgut\.venv\Lib\site-packages\django\db\models\query.py", line 675, in create
    obj = self.model(**kwargs)
          ^^^^^^^^^^^^^^^^^^^^
  File "A:\test\AnturajSurgut\.venv\Lib\site-packages\django\db\models\base.py", line 543, in __init__
    _setattr(self, field.name, rel_obj)
  File "A:\test\AnturajSurgut\.venv\Lib\site-packages\django\db\models\fields\related_descriptors.py", line 283, in __set__
    raise ValueError(
ValueError: Cannot assign "'1'": "Order.payment_type" must be a "PaymentType" instance.
[03.04.2024 01:23:37 - ERROR] Internal Server Error: /api/v1/order/create/, PATH: A:\test\AnturajSurgut\.venv\Lib\site-packages\django\utils\log.py, line: 241
Traceback (most recent call last):
  File "A:\test\AnturajSurgut\.venv\Lib\site-packages\django\core\handlers\exception.py", line 55, in inner
    response = get_response(request)
               ^^^^^^^^^^^^^^^^^^^^^
  File "A:\test\AnturajSurgut\.venv\Lib\site-packages\django\core\handlers\base.py", line 197, in _get_response
    response = wrapped_callback(request, *callback_args, **callback_kwargs)
               ^^^^^^^^^^^^^^^^^^^^^^^^^^^^^^^^^^^^^^^^^^^^^^^^^^^^^^^^^^^^
  File "A:\test\AnturajSurgut\.venv\Lib\site-packages\django\views\decorators\csrf.py", line 65, in _view_wrapper
    return view_func(request, *args, **kwargs)
           ^^^^^^^^^^^^^^^^^^^^^^^^^^^^^^^^^^^
  File "A:\test\AnturajSurgut\.venv\Lib\site-packages\django\views\generic\base.py", line 104, in view
    return self.dispatch(request, *args, **kwargs)
           ^^^^^^^^^^^^^^^^^^^^^^^^^^^^^^^^^^^^^^^
  File "A:\test\AnturajSurgut\.venv\Lib\site-packages\rest_framework\views.py", line 509, in dispatch
    response = self.handle_exception(exc)
               ^^^^^^^^^^^^^^^^^^^^^^^^^^
  File "A:\test\AnturajSurgut\.venv\Lib\site-packages\rest_framework\views.py", line 469, in handle_exception
    self.raise_uncaught_exception(exc)
  File "A:\test\AnturajSurgut\.venv\Lib\site-packages\rest_framework\views.py", line 480, in raise_uncaught_exception
    raise exc
  File "A:\test\AnturajSurgut\.venv\Lib\site-packages\rest_framework\views.py", line 506, in dispatch
    response = handler(request, *args, **kwargs)
               ^^^^^^^^^^^^^^^^^^^^^^^^^^^^^^^^^
  File "A:\test\AnturajSurgut\.venv\Lib\site-packages\rest_framework\decorators.py", line 50, in handler
    return func(*args, **kwargs)
           ^^^^^^^^^^^^^^^^^^^^^
  File "A:\test\AnturajSurgut\backend\order\views.py", line 34, in create_order
    serializer.save()
  File "A:\test\AnturajSurgut\.venv\Lib\site-packages\rest_framework\serializers.py", line 212, in save
    self.instance = self.create(validated_data)
                    ^^^^^^^^^^^^^^^^^^^^^^^^^^^
  File "A:\test\AnturajSurgut\backend\order\serializers\OrderSerializers.py", line 110, in create
    order = Order.objects.create(**validated_data)
            ^^^^^^^^^^^^^^^^^^^^^^^^^^^^^^^^^^^^^^
  File "A:\test\AnturajSurgut\.venv\Lib\site-packages\django\db\models\manager.py", line 87, in manager_method
    return getattr(self.get_queryset(), name)(*args, **kwargs)
           ^^^^^^^^^^^^^^^^^^^^^^^^^^^^^^^^^^^^^^^^^^^^^^^^^^^
  File "A:\test\AnturajSurgut\.venv\Lib\site-packages\django\db\models\query.py", line 675, in create
    obj = self.model(**kwargs)
          ^^^^^^^^^^^^^^^^^^^^
  File "A:\test\AnturajSurgut\.venv\Lib\site-packages\django\db\models\base.py", line 543, in __init__
    _setattr(self, field.name, rel_obj)
  File "A:\test\AnturajSurgut\.venv\Lib\site-packages\django\db\models\fields\related_descriptors.py", line 283, in __set__
    raise ValueError(
ValueError: Cannot assign "'1'": "Order.payment_type" must be a "PaymentType" instance.
[03.04.2024 01:24:23 - ERROR] Internal Server Error: /api/v1/order/create/, PATH: A:\test\AnturajSurgut\.venv\Lib\site-packages\django\utils\log.py, line: 241
Traceback (most recent call last):
  File "A:\test\AnturajSurgut\.venv\Lib\site-packages\django\core\handlers\exception.py", line 55, in inner
    response = get_response(request)
               ^^^^^^^^^^^^^^^^^^^^^
  File "A:\test\AnturajSurgut\.venv\Lib\site-packages\django\core\handlers\base.py", line 197, in _get_response
    response = wrapped_callback(request, *callback_args, **callback_kwargs)
               ^^^^^^^^^^^^^^^^^^^^^^^^^^^^^^^^^^^^^^^^^^^^^^^^^^^^^^^^^^^^
  File "A:\test\AnturajSurgut\.venv\Lib\site-packages\django\views\decorators\csrf.py", line 65, in _view_wrapper
    return view_func(request, *args, **kwargs)
           ^^^^^^^^^^^^^^^^^^^^^^^^^^^^^^^^^^^
  File "A:\test\AnturajSurgut\.venv\Lib\site-packages\django\views\generic\base.py", line 104, in view
    return self.dispatch(request, *args, **kwargs)
           ^^^^^^^^^^^^^^^^^^^^^^^^^^^^^^^^^^^^^^^
  File "A:\test\AnturajSurgut\.venv\Lib\site-packages\rest_framework\views.py", line 509, in dispatch
    response = self.handle_exception(exc)
               ^^^^^^^^^^^^^^^^^^^^^^^^^^
  File "A:\test\AnturajSurgut\.venv\Lib\site-packages\rest_framework\views.py", line 469, in handle_exception
    self.raise_uncaught_exception(exc)
  File "A:\test\AnturajSurgut\.venv\Lib\site-packages\rest_framework\views.py", line 480, in raise_uncaught_exception
    raise exc
  File "A:\test\AnturajSurgut\.venv\Lib\site-packages\rest_framework\views.py", line 506, in dispatch
    response = handler(request, *args, **kwargs)
               ^^^^^^^^^^^^^^^^^^^^^^^^^^^^^^^^^
  File "A:\test\AnturajSurgut\.venv\Lib\site-packages\rest_framework\decorators.py", line 50, in handler
    return func(*args, **kwargs)
           ^^^^^^^^^^^^^^^^^^^^^
  File "A:\test\AnturajSurgut\backend\order\views.py", line 34, in create_order
    serializer.save()
  File "A:\test\AnturajSurgut\.venv\Lib\site-packages\rest_framework\serializers.py", line 212, in save
    self.instance = self.create(validated_data)
                    ^^^^^^^^^^^^^^^^^^^^^^^^^^^
  File "A:\test\AnturajSurgut\backend\order\serializers\OrderSerializers.py", line 111, in create
    order = Order.objects.create(**validated_data)
            ^^^^^^^^^^^^^^^^^^^^^^^^^^^^^^^^^^^^^^
  File "A:\test\AnturajSurgut\.venv\Lib\site-packages\django\db\models\manager.py", line 87, in manager_method
    return getattr(self.get_queryset(), name)(*args, **kwargs)
           ^^^^^^^^^^^^^^^^^^^^^^^^^^^^^^^^^^^^^^^^^^^^^^^^^^^
  File "A:\test\AnturajSurgut\.venv\Lib\site-packages\django\db\models\query.py", line 675, in create
    obj = self.model(**kwargs)
          ^^^^^^^^^^^^^^^^^^^^
  File "A:\test\AnturajSurgut\.venv\Lib\site-packages\django\db\models\base.py", line 543, in __init__
    _setattr(self, field.name, rel_obj)
  File "A:\test\AnturajSurgut\.venv\Lib\site-packages\django\db\models\fields\related_descriptors.py", line 283, in __set__
    raise ValueError(
ValueError: Cannot assign "'1'": "Order.payment_type" must be a "PaymentType" instance.
[03.04.2024 01:28:11 - ERROR] Internal Server Error: /api/v1/order/create/, PATH: A:\test\AnturajSurgut\.venv\Lib\site-packages\django\utils\log.py, line: 241
Traceback (most recent call last):
  File "A:\test\AnturajSurgut\.venv\Lib\site-packages\django\core\handlers\exception.py", line 55, in inner
    response = get_response(request)
               ^^^^^^^^^^^^^^^^^^^^^
  File "A:\test\AnturajSurgut\.venv\Lib\site-packages\django\core\handlers\base.py", line 197, in _get_response
    response = wrapped_callback(request, *callback_args, **callback_kwargs)
               ^^^^^^^^^^^^^^^^^^^^^^^^^^^^^^^^^^^^^^^^^^^^^^^^^^^^^^^^^^^^
  File "A:\test\AnturajSurgut\.venv\Lib\site-packages\django\views\decorators\csrf.py", line 65, in _view_wrapper
    return view_func(request, *args, **kwargs)
           ^^^^^^^^^^^^^^^^^^^^^^^^^^^^^^^^^^^
  File "A:\test\AnturajSurgut\.venv\Lib\site-packages\django\views\generic\base.py", line 104, in view
    return self.dispatch(request, *args, **kwargs)
           ^^^^^^^^^^^^^^^^^^^^^^^^^^^^^^^^^^^^^^^
  File "A:\test\AnturajSurgut\.venv\Lib\site-packages\rest_framework\views.py", line 509, in dispatch
    response = self.handle_exception(exc)
               ^^^^^^^^^^^^^^^^^^^^^^^^^^
  File "A:\test\AnturajSurgut\.venv\Lib\site-packages\rest_framework\views.py", line 469, in handle_exception
    self.raise_uncaught_exception(exc)
  File "A:\test\AnturajSurgut\.venv\Lib\site-packages\rest_framework\views.py", line 480, in raise_uncaught_exception
    raise exc
  File "A:\test\AnturajSurgut\.venv\Lib\site-packages\rest_framework\views.py", line 506, in dispatch
    response = handler(request, *args, **kwargs)
               ^^^^^^^^^^^^^^^^^^^^^^^^^^^^^^^^^
  File "A:\test\AnturajSurgut\.venv\Lib\site-packages\rest_framework\decorators.py", line 50, in handler
    return func(*args, **kwargs)
           ^^^^^^^^^^^^^^^^^^^^^
  File "A:\test\AnturajSurgut\backend\order\views.py", line 34, in create_order
    serializer.save()
  File "A:\test\AnturajSurgut\.venv\Lib\site-packages\rest_framework\serializers.py", line 212, in save
    self.instance = self.create(validated_data)
                    ^^^^^^^^^^^^^^^^^^^^^^^^^^^
  File "A:\test\AnturajSurgut\backend\order\serializers\OrderSerializers.py", line 110, in create
    order = Order.objects.create(**validated_data)
            ^^^^^^^^^^^^^^^^^^^^^^^^^^^^^^^^^^^^^^
  File "A:\test\AnturajSurgut\.venv\Lib\site-packages\django\db\models\manager.py", line 87, in manager_method
    return getattr(self.get_queryset(), name)(*args, **kwargs)
           ^^^^^^^^^^^^^^^^^^^^^^^^^^^^^^^^^^^^^^^^^^^^^^^^^^^
  File "A:\test\AnturajSurgut\.venv\Lib\site-packages\django\db\models\query.py", line 675, in create
    obj = self.model(**kwargs)
          ^^^^^^^^^^^^^^^^^^^^
  File "A:\test\AnturajSurgut\.venv\Lib\site-packages\django\db\models\base.py", line 543, in __init__
    _setattr(self, field.name, rel_obj)
  File "A:\test\AnturajSurgut\.venv\Lib\site-packages\django\db\models\fields\related_descriptors.py", line 283, in __set__
    raise ValueError(
ValueError: Cannot assign "'1'": "Order.payment_type" must be a "PaymentType" instance.
[03.04.2024 01:33:46 - ERROR] Internal Server Error: /api/v1/order/create/, PATH: A:\test\AnturajSurgut\.venv\Lib\site-packages\django\utils\log.py, line: 241
Traceback (most recent call last):
  File "A:\test\AnturajSurgut\.venv\Lib\site-packages\redis\connection.py", line 264, in connect
    sock = self.retry.call_with_retry(
           ^^^^^^^^^^^^^^^^^^^^^^^^^^^
  File "A:\test\AnturajSurgut\.venv\Lib\site-packages\redis\retry.py", line 46, in call_with_retry
    return do()
           ^^^^
  File "A:\test\AnturajSurgut\.venv\Lib\site-packages\redis\connection.py", line 265, in <lambda>
    lambda: self._connect(), lambda error: self.disconnect(error)
            ^^^^^^^^^^^^^^^
  File "A:\test\AnturajSurgut\.venv\Lib\site-packages\redis\connection.py", line 595, in _connect
    for res in socket.getaddrinfo(
               ^^^^^^^^^^^^^^^^^^^
  File "C:\Program Files\Python312\Lib\socket.py", line 963, in getaddrinfo
    for res in _socket.getaddrinfo(host, port, family, type, proto, flags):
               ^^^^^^^^^^^^^^^^^^^^^^^^^^^^^^^^^^^^^^^^^^^^^^^^^^^^^^^^^^^
socket.gaierror: [Errno 11001] getaddrinfo failed

During handling of the above exception, another exception occurred:

Traceback (most recent call last):
  File "A:\test\AnturajSurgut\.venv\Lib\site-packages\celery\backends\redis.py", line 127, in reconnect_on_error
    yield
  File "A:\test\AnturajSurgut\.venv\Lib\site-packages\celery\backends\redis.py", line 177, in _consume_from
    self._pubsub.subscribe(key)
  File "A:\test\AnturajSurgut\.venv\Lib\site-packages\redis\client.py", line 916, in subscribe
    ret_val = self.execute_command("SUBSCRIBE", *new_channels.keys())
              ^^^^^^^^^^^^^^^^^^^^^^^^^^^^^^^^^^^^^^^^^^^^^^^^^^^^^^^
  File "A:\test\AnturajSurgut\.venv\Lib\site-packages\redis\client.py", line 749, in execute_command
    self.connection = self.connection_pool.get_connection(
                      ^^^^^^^^^^^^^^^^^^^^^^^^^^^^^^^^^^^^
  File "A:\test\AnturajSurgut\.venv\Lib\site-packages\redis\connection.py", line 1086, in get_connection
    connection.connect()
  File "A:\test\AnturajSurgut\.venv\Lib\site-packages\redis\connection.py", line 270, in connect
    raise ConnectionError(self._error_message(e))
redis.exceptions.ConnectionError: Error 11001 connecting to redis:6379. getaddrinfo failed.

During handling of the above exception, another exception occurred:

Traceback (most recent call last):
  File "A:\test\AnturajSurgut\.venv\Lib\site-packages\redis\connection.py", line 264, in connect
    sock = self.retry.call_with_retry(
           ^^^^^^^^^^^^^^^^^^^^^^^^^^^
  File "A:\test\AnturajSurgut\.venv\Lib\site-packages\redis\retry.py", line 46, in call_with_retry
    return do()
           ^^^^
  File "A:\test\AnturajSurgut\.venv\Lib\site-packages\redis\connection.py", line 265, in <lambda>
    lambda: self._connect(), lambda error: self.disconnect(error)
            ^^^^^^^^^^^^^^^
  File "A:\test\AnturajSurgut\.venv\Lib\site-packages\redis\connection.py", line 595, in _connect
    for res in socket.getaddrinfo(
               ^^^^^^^^^^^^^^^^^^^
  File "C:\Program Files\Python312\Lib\socket.py", line 963, in getaddrinfo
    for res in _socket.getaddrinfo(host, port, family, type, proto, flags):
               ^^^^^^^^^^^^^^^^^^^^^^^^^^^^^^^^^^^^^^^^^^^^^^^^^^^^^^^^^^^
socket.gaierror: [Errno 11001] getaddrinfo failed

During handling of the above exception, another exception occurred:

Traceback (most recent call last):
  File "A:\test\AnturajSurgut\.venv\Lib\site-packages\kombu\connection.py", line 472, in _reraise_as_library_errors
    yield
  File "A:\test\AnturajSurgut\.venv\Lib\site-packages\celery\app\base.py", line 798, in send_task
    self.backend.on_task_call(P, task_id)
  File "A:\test\AnturajSurgut\.venv\Lib\site-packages\celery\backends\redis.py", line 373, in on_task_call
    self.result_consumer.consume_from(task_id)
  File "A:\test\AnturajSurgut\.venv\Lib\site-packages\celery\backends\redis.py", line 169, in consume_from
    return self.start(task_id)
           ^^^^^^^^^^^^^^^^^^^
  File "A:\test\AnturajSurgut\.venv\Lib\site-packages\celery\backends\redis.py", line 147, in start
    self._consume_from(initial_task_id)
  File "A:\test\AnturajSurgut\.venv\Lib\site-packages\celery\backends\redis.py", line 176, in _consume_from
    with self.reconnect_on_error():
  File "C:\Program Files\Python312\Lib\contextlib.py", line 158, in __exit__
    self.gen.throw(value)
  File "A:\test\AnturajSurgut\.venv\Lib\site-packages\celery\backends\redis.py", line 130, in reconnect_on_error
    self._ensure(self._reconnect_pubsub, ())
  File "A:\test\AnturajSurgut\.venv\Lib\site-packages\celery\backends\redis.py", line 384, in ensure
    return retry_over_time(
           ^^^^^^^^^^^^^^^^
  File "A:\test\AnturajSurgut\.venv\Lib\site-packages\kombu\utils\functional.py", line 318, in retry_over_time
    return fun(*args, **kwargs)
           ^^^^^^^^^^^^^^^^^^^^
  File "A:\test\AnturajSurgut\.venv\Lib\site-packages\celery\backends\redis.py", line 106, in _reconnect_pubsub
    metas = self.backend.client.mget(self.subscribed_to)
            ^^^^^^^^^^^^^^^^^^^^^^^^^^^^^^^^^^^^^^^^^^^^
  File "A:\test\AnturajSurgut\.venv\Lib\site-packages\redis\commands\core.py", line 2015, in mget
    return self.execute_command("MGET", *args, **options)
           ^^^^^^^^^^^^^^^^^^^^^^^^^^^^^^^^^^^^^^^^^^^^^^
  File "A:\test\AnturajSurgut\.venv\Lib\site-packages\redis\client.py", line 533, in execute_command
    conn = self.connection or pool.get_connection(command_name, **options)
                              ^^^^^^^^^^^^^^^^^^^^^^^^^^^^^^^^^^^^^^^^^^^^
  File "A:\test\AnturajSurgut\.venv\Lib\site-packages\redis\connection.py", line 1086, in get_connection
    connection.connect()
  File "A:\test\AnturajSurgut\.venv\Lib\site-packages\redis\connection.py", line 270, in connect
    raise ConnectionError(self._error_message(e))
redis.exceptions.ConnectionError: Error 11001 connecting to redis:6379. getaddrinfo failed.

The above exception was the direct cause of the following exception:

Traceback (most recent call last):
  File "A:\test\AnturajSurgut\.venv\Lib\site-packages\django\core\handlers\exception.py", line 55, in inner
    response = get_response(request)
               ^^^^^^^^^^^^^^^^^^^^^
  File "A:\test\AnturajSurgut\.venv\Lib\site-packages\django\core\handlers\base.py", line 197, in _get_response
    response = wrapped_callback(request, *callback_args, **callback_kwargs)
               ^^^^^^^^^^^^^^^^^^^^^^^^^^^^^^^^^^^^^^^^^^^^^^^^^^^^^^^^^^^^
  File "A:\test\AnturajSurgut\.venv\Lib\site-packages\django\views\decorators\csrf.py", line 65, in _view_wrapper
    return view_func(request, *args, **kwargs)
           ^^^^^^^^^^^^^^^^^^^^^^^^^^^^^^^^^^^
  File "A:\test\AnturajSurgut\.venv\Lib\site-packages\django\views\generic\base.py", line 104, in view
    return self.dispatch(request, *args, **kwargs)
           ^^^^^^^^^^^^^^^^^^^^^^^^^^^^^^^^^^^^^^^
  File "A:\test\AnturajSurgut\.venv\Lib\site-packages\rest_framework\views.py", line 509, in dispatch
    response = self.handle_exception(exc)
               ^^^^^^^^^^^^^^^^^^^^^^^^^^
  File "A:\test\AnturajSurgut\.venv\Lib\site-packages\rest_framework\views.py", line 469, in handle_exception
    self.raise_uncaught_exception(exc)
  File "A:\test\AnturajSurgut\.venv\Lib\site-packages\rest_framework\views.py", line 480, in raise_uncaught_exception
    raise exc
  File "A:\test\AnturajSurgut\.venv\Lib\site-packages\rest_framework\views.py", line 506, in dispatch
    response = handler(request, *args, **kwargs)
               ^^^^^^^^^^^^^^^^^^^^^^^^^^^^^^^^^
  File "A:\test\AnturajSurgut\.venv\Lib\site-packages\rest_framework\decorators.py", line 50, in handler
    return func(*args, **kwargs)
           ^^^^^^^^^^^^^^^^^^^^^
  File "A:\test\AnturajSurgut\backend\order\views.py", line 34, in create_order
    serializer.save()
  File "A:\test\AnturajSurgut\.venv\Lib\site-packages\rest_framework\serializers.py", line 212, in save
    self.instance = self.create(validated_data)
                    ^^^^^^^^^^^^^^^^^^^^^^^^^^^
  File "A:\test\AnturajSurgut\backend\order\serializers\OrderSerializers.py", line 120, in create
    order = Order.objects.create(**validated_data)
            ^^^^^^^^^^^^^^^^^^^^^^^^^^^^^^^^^^^^^^
  File "A:\test\AnturajSurgut\.venv\Lib\site-packages\django\db\models\manager.py", line 87, in manager_method
    return getattr(self.get_queryset(), name)(*args, **kwargs)
           ^^^^^^^^^^^^^^^^^^^^^^^^^^^^^^^^^^^^^^^^^^^^^^^^^^^
  File "A:\test\AnturajSurgut\.venv\Lib\site-packages\django\db\models\query.py", line 677, in create
    obj.save(force_insert=True, using=self.db)
  File "A:\test\AnturajSurgut\backend\order\models.py", line 171, in save
    super(Order, self).save(*args, **kwargs)
  File "A:\test\AnturajSurgut\.venv\Lib\site-packages\django\db\models\base.py", line 822, in save
    self.save_base(
  File "A:\test\AnturajSurgut\.venv\Lib\site-packages\django\db\models\base.py", line 924, in save_base
    post_save.send(
  File "A:\test\AnturajSurgut\.venv\Lib\site-packages\django\dispatch\dispatcher.py", line 189, in send
    response = receiver(signal=self, sender=sender, **named)
               ^^^^^^^^^^^^^^^^^^^^^^^^^^^^^^^^^^^^^^^^^^^^^
  File "A:\test\AnturajSurgut\backend\DB\Signals\Order\Notify\signal_order_create.py", line 28, in send_email_order
    send_order_confirmation_email.delay(instance.order_number)
  File "A:\test\AnturajSurgut\.venv\Lib\site-packages\celery\app\task.py", line 444, in delay
    return self.apply_async(args, kwargs)
           ^^^^^^^^^^^^^^^^^^^^^^^^^^^^^^
  File "A:\test\AnturajSurgut\.venv\Lib\site-packages\celery\app\task.py", line 594, in apply_async
    return app.send_task(
           ^^^^^^^^^^^^^^
  File "A:\test\AnturajSurgut\.venv\Lib\site-packages\celery\app\base.py", line 796, in send_task
    with P.connection._reraise_as_library_errors():
  File "C:\Program Files\Python312\Lib\contextlib.py", line 158, in __exit__
    self.gen.throw(value)
  File "A:\test\AnturajSurgut\.venv\Lib\site-packages\kombu\connection.py", line 476, in _reraise_as_library_errors
    raise ConnectionError(str(exc)) from exc
kombu.exceptions.OperationalError: Error 11001 connecting to redis:6379. getaddrinfo failed.
[03.04.2024 01:34:09 - ERROR] Internal Server Error: /api/v1/order/create/, PATH: A:\test\AnturajSurgut\.venv\Lib\site-packages\django\utils\log.py, line: 241
Traceback (most recent call last):
  File "A:\test\AnturajSurgut\.venv\Lib\site-packages\redis\connection.py", line 264, in connect
    sock = self.retry.call_with_retry(
           ^^^^^^^^^^^^^^^^^^^^^^^^^^^
  File "A:\test\AnturajSurgut\.venv\Lib\site-packages\redis\retry.py", line 46, in call_with_retry
    return do()
           ^^^^
  File "A:\test\AnturajSurgut\.venv\Lib\site-packages\redis\connection.py", line 265, in <lambda>
    lambda: self._connect(), lambda error: self.disconnect(error)
            ^^^^^^^^^^^^^^^
  File "A:\test\AnturajSurgut\.venv\Lib\site-packages\redis\connection.py", line 595, in _connect
    for res in socket.getaddrinfo(
               ^^^^^^^^^^^^^^^^^^^
  File "C:\Program Files\Python312\Lib\socket.py", line 963, in getaddrinfo
    for res in _socket.getaddrinfo(host, port, family, type, proto, flags):
               ^^^^^^^^^^^^^^^^^^^^^^^^^^^^^^^^^^^^^^^^^^^^^^^^^^^^^^^^^^^
socket.gaierror: [Errno 11001] getaddrinfo failed

During handling of the above exception, another exception occurred:

Traceback (most recent call last):
  File "A:\test\AnturajSurgut\.venv\Lib\site-packages\celery\backends\redis.py", line 127, in reconnect_on_error
    yield
  File "A:\test\AnturajSurgut\.venv\Lib\site-packages\celery\backends\redis.py", line 177, in _consume_from
    self._pubsub.subscribe(key)
  File "A:\test\AnturajSurgut\.venv\Lib\site-packages\redis\client.py", line 916, in subscribe
    ret_val = self.execute_command("SUBSCRIBE", *new_channels.keys())
              ^^^^^^^^^^^^^^^^^^^^^^^^^^^^^^^^^^^^^^^^^^^^^^^^^^^^^^^
  File "A:\test\AnturajSurgut\.venv\Lib\site-packages\redis\client.py", line 749, in execute_command
    self.connection = self.connection_pool.get_connection(
                      ^^^^^^^^^^^^^^^^^^^^^^^^^^^^^^^^^^^^
  File "A:\test\AnturajSurgut\.venv\Lib\site-packages\redis\connection.py", line 1086, in get_connection
    connection.connect()
  File "A:\test\AnturajSurgut\.venv\Lib\site-packages\redis\connection.py", line 270, in connect
    raise ConnectionError(self._error_message(e))
redis.exceptions.ConnectionError: Error 11001 connecting to redis:6379. getaddrinfo failed.

During handling of the above exception, another exception occurred:

Traceback (most recent call last):
  File "A:\test\AnturajSurgut\.venv\Lib\site-packages\redis\connection.py", line 264, in connect
    sock = self.retry.call_with_retry(
           ^^^^^^^^^^^^^^^^^^^^^^^^^^^
  File "A:\test\AnturajSurgut\.venv\Lib\site-packages\redis\retry.py", line 46, in call_with_retry
    return do()
           ^^^^
  File "A:\test\AnturajSurgut\.venv\Lib\site-packages\redis\connection.py", line 265, in <lambda>
    lambda: self._connect(), lambda error: self.disconnect(error)
            ^^^^^^^^^^^^^^^
  File "A:\test\AnturajSurgut\.venv\Lib\site-packages\redis\connection.py", line 595, in _connect
    for res in socket.getaddrinfo(
               ^^^^^^^^^^^^^^^^^^^
  File "C:\Program Files\Python312\Lib\socket.py", line 963, in getaddrinfo
    for res in _socket.getaddrinfo(host, port, family, type, proto, flags):
               ^^^^^^^^^^^^^^^^^^^^^^^^^^^^^^^^^^^^^^^^^^^^^^^^^^^^^^^^^^^
socket.gaierror: [Errno 11001] getaddrinfo failed

During handling of the above exception, another exception occurred:

Traceback (most recent call last):
  File "A:\test\AnturajSurgut\.venv\Lib\site-packages\kombu\connection.py", line 472, in _reraise_as_library_errors
    yield
  File "A:\test\AnturajSurgut\.venv\Lib\site-packages\celery\app\base.py", line 798, in send_task
    self.backend.on_task_call(P, task_id)
  File "A:\test\AnturajSurgut\.venv\Lib\site-packages\celery\backends\redis.py", line 373, in on_task_call
    self.result_consumer.consume_from(task_id)
  File "A:\test\AnturajSurgut\.venv\Lib\site-packages\celery\backends\redis.py", line 169, in consume_from
    return self.start(task_id)
           ^^^^^^^^^^^^^^^^^^^
  File "A:\test\AnturajSurgut\.venv\Lib\site-packages\celery\backends\redis.py", line 147, in start
    self._consume_from(initial_task_id)
  File "A:\test\AnturajSurgut\.venv\Lib\site-packages\celery\backends\redis.py", line 176, in _consume_from
    with self.reconnect_on_error():
  File "C:\Program Files\Python312\Lib\contextlib.py", line 158, in __exit__
    self.gen.throw(value)
  File "A:\test\AnturajSurgut\.venv\Lib\site-packages\celery\backends\redis.py", line 130, in reconnect_on_error
    self._ensure(self._reconnect_pubsub, ())
  File "A:\test\AnturajSurgut\.venv\Lib\site-packages\celery\backends\redis.py", line 384, in ensure
    return retry_over_time(
           ^^^^^^^^^^^^^^^^
  File "A:\test\AnturajSurgut\.venv\Lib\site-packages\kombu\utils\functional.py", line 318, in retry_over_time
    return fun(*args, **kwargs)
           ^^^^^^^^^^^^^^^^^^^^
  File "A:\test\AnturajSurgut\.venv\Lib\site-packages\celery\backends\redis.py", line 106, in _reconnect_pubsub
    metas = self.backend.client.mget(self.subscribed_to)
            ^^^^^^^^^^^^^^^^^^^^^^^^^^^^^^^^^^^^^^^^^^^^
  File "A:\test\AnturajSurgut\.venv\Lib\site-packages\redis\commands\core.py", line 2015, in mget
    return self.execute_command("MGET", *args, **options)
           ^^^^^^^^^^^^^^^^^^^^^^^^^^^^^^^^^^^^^^^^^^^^^^
  File "A:\test\AnturajSurgut\.venv\Lib\site-packages\redis\client.py", line 533, in execute_command
    conn = self.connection or pool.get_connection(command_name, **options)
                              ^^^^^^^^^^^^^^^^^^^^^^^^^^^^^^^^^^^^^^^^^^^^
  File "A:\test\AnturajSurgut\.venv\Lib\site-packages\redis\connection.py", line 1086, in get_connection
    connection.connect()
  File "A:\test\AnturajSurgut\.venv\Lib\site-packages\redis\connection.py", line 270, in connect
    raise ConnectionError(self._error_message(e))
redis.exceptions.ConnectionError: Error 11001 connecting to redis:6379. getaddrinfo failed.

The above exception was the direct cause of the following exception:

Traceback (most recent call last):
  File "A:\test\AnturajSurgut\.venv\Lib\site-packages\django\core\handlers\exception.py", line 55, in inner
    response = get_response(request)
               ^^^^^^^^^^^^^^^^^^^^^
  File "A:\test\AnturajSurgut\.venv\Lib\site-packages\django\core\handlers\base.py", line 197, in _get_response
    response = wrapped_callback(request, *callback_args, **callback_kwargs)
               ^^^^^^^^^^^^^^^^^^^^^^^^^^^^^^^^^^^^^^^^^^^^^^^^^^^^^^^^^^^^
  File "A:\test\AnturajSurgut\.venv\Lib\site-packages\django\views\decorators\csrf.py", line 65, in _view_wrapper
    return view_func(request, *args, **kwargs)
           ^^^^^^^^^^^^^^^^^^^^^^^^^^^^^^^^^^^
  File "A:\test\AnturajSurgut\.venv\Lib\site-packages\django\views\generic\base.py", line 104, in view
    return self.dispatch(request, *args, **kwargs)
           ^^^^^^^^^^^^^^^^^^^^^^^^^^^^^^^^^^^^^^^
  File "A:\test\AnturajSurgut\.venv\Lib\site-packages\rest_framework\views.py", line 509, in dispatch
    response = self.handle_exception(exc)
               ^^^^^^^^^^^^^^^^^^^^^^^^^^
  File "A:\test\AnturajSurgut\.venv\Lib\site-packages\rest_framework\views.py", line 469, in handle_exception
    self.raise_uncaught_exception(exc)
  File "A:\test\AnturajSurgut\.venv\Lib\site-packages\rest_framework\views.py", line 480, in raise_uncaught_exception
    raise exc
  File "A:\test\AnturajSurgut\.venv\Lib\site-packages\rest_framework\views.py", line 506, in dispatch
    response = handler(request, *args, **kwargs)
               ^^^^^^^^^^^^^^^^^^^^^^^^^^^^^^^^^
  File "A:\test\AnturajSurgut\.venv\Lib\site-packages\rest_framework\decorators.py", line 50, in handler
    return func(*args, **kwargs)
           ^^^^^^^^^^^^^^^^^^^^^
  File "A:\test\AnturajSurgut\backend\order\views.py", line 34, in create_order
    serializer.save()
  File "A:\test\AnturajSurgut\.venv\Lib\site-packages\rest_framework\serializers.py", line 212, in save
    self.instance = self.create(validated_data)
                    ^^^^^^^^^^^^^^^^^^^^^^^^^^^
  File "A:\test\AnturajSurgut\backend\order\serializers\OrderSerializers.py", line 120, in create
    order = Order.objects.create(**validated_data)
            ^^^^^^^^^^^^^^^^^^^^^^^^^^^^^^^^^^^^^^
  File "A:\test\AnturajSurgut\.venv\Lib\site-packages\django\db\models\manager.py", line 87, in manager_method
    return getattr(self.get_queryset(), name)(*args, **kwargs)
           ^^^^^^^^^^^^^^^^^^^^^^^^^^^^^^^^^^^^^^^^^^^^^^^^^^^
  File "A:\test\AnturajSurgut\.venv\Lib\site-packages\django\db\models\query.py", line 677, in create
    obj.save(force_insert=True, using=self.db)
  File "A:\test\AnturajSurgut\backend\order\models.py", line 171, in save
    super(Order, self).save(*args, **kwargs)
  File "A:\test\AnturajSurgut\.venv\Lib\site-packages\django\db\models\base.py", line 822, in save
    self.save_base(
  File "A:\test\AnturajSurgut\.venv\Lib\site-packages\django\db\models\base.py", line 924, in save_base
    post_save.send(
  File "A:\test\AnturajSurgut\.venv\Lib\site-packages\django\dispatch\dispatcher.py", line 189, in send
    response = receiver(signal=self, sender=sender, **named)
               ^^^^^^^^^^^^^^^^^^^^^^^^^^^^^^^^^^^^^^^^^^^^^
  File "A:\test\AnturajSurgut\backend\DB\Signals\Order\Notify\signal_order_create.py", line 28, in send_email_order
    send_order_confirmation_email.delay(instance.order_number)
  File "A:\test\AnturajSurgut\.venv\Lib\site-packages\celery\app\task.py", line 444, in delay
    return self.apply_async(args, kwargs)
           ^^^^^^^^^^^^^^^^^^^^^^^^^^^^^^
  File "A:\test\AnturajSurgut\.venv\Lib\site-packages\celery\app\task.py", line 594, in apply_async
    return app.send_task(
           ^^^^^^^^^^^^^^
  File "A:\test\AnturajSurgut\.venv\Lib\site-packages\celery\app\base.py", line 796, in send_task
    with P.connection._reraise_as_library_errors():
  File "C:\Program Files\Python312\Lib\contextlib.py", line 158, in __exit__
    self.gen.throw(value)
  File "A:\test\AnturajSurgut\.venv\Lib\site-packages\kombu\connection.py", line 476, in _reraise_as_library_errors
    raise ConnectionError(str(exc)) from exc
kombu.exceptions.OperationalError: Error 11001 connecting to redis:6379. getaddrinfo failed.
[03.04.2024 01:34:11 - ERROR] Internal Server Error: /api/v1/order/create/, PATH: A:\test\AnturajSurgut\.venv\Lib\site-packages\django\utils\log.py, line: 241
Traceback (most recent call last):
  File "A:\test\AnturajSurgut\.venv\Lib\site-packages\redis\connection.py", line 264, in connect
    sock = self.retry.call_with_retry(
           ^^^^^^^^^^^^^^^^^^^^^^^^^^^
  File "A:\test\AnturajSurgut\.venv\Lib\site-packages\redis\retry.py", line 46, in call_with_retry
    return do()
           ^^^^
  File "A:\test\AnturajSurgut\.venv\Lib\site-packages\redis\connection.py", line 265, in <lambda>
    lambda: self._connect(), lambda error: self.disconnect(error)
            ^^^^^^^^^^^^^^^
  File "A:\test\AnturajSurgut\.venv\Lib\site-packages\redis\connection.py", line 595, in _connect
    for res in socket.getaddrinfo(
               ^^^^^^^^^^^^^^^^^^^
  File "C:\Program Files\Python312\Lib\socket.py", line 963, in getaddrinfo
    for res in _socket.getaddrinfo(host, port, family, type, proto, flags):
               ^^^^^^^^^^^^^^^^^^^^^^^^^^^^^^^^^^^^^^^^^^^^^^^^^^^^^^^^^^^
socket.gaierror: [Errno 11001] getaddrinfo failed

During handling of the above exception, another exception occurred:

Traceback (most recent call last):
  File "A:\test\AnturajSurgut\.venv\Lib\site-packages\celery\backends\redis.py", line 127, in reconnect_on_error
    yield
  File "A:\test\AnturajSurgut\.venv\Lib\site-packages\celery\backends\redis.py", line 177, in _consume_from
    self._pubsub.subscribe(key)
  File "A:\test\AnturajSurgut\.venv\Lib\site-packages\redis\client.py", line 916, in subscribe
    ret_val = self.execute_command("SUBSCRIBE", *new_channels.keys())
              ^^^^^^^^^^^^^^^^^^^^^^^^^^^^^^^^^^^^^^^^^^^^^^^^^^^^^^^
  File "A:\test\AnturajSurgut\.venv\Lib\site-packages\redis\client.py", line 749, in execute_command
    self.connection = self.connection_pool.get_connection(
                      ^^^^^^^^^^^^^^^^^^^^^^^^^^^^^^^^^^^^
  File "A:\test\AnturajSurgut\.venv\Lib\site-packages\redis\connection.py", line 1086, in get_connection
    connection.connect()
  File "A:\test\AnturajSurgut\.venv\Lib\site-packages\redis\connection.py", line 270, in connect
    raise ConnectionError(self._error_message(e))
redis.exceptions.ConnectionError: Error 11001 connecting to redis:6379. getaddrinfo failed.

During handling of the above exception, another exception occurred:

Traceback (most recent call last):
  File "A:\test\AnturajSurgut\.venv\Lib\site-packages\redis\connection.py", line 264, in connect
    sock = self.retry.call_with_retry(
           ^^^^^^^^^^^^^^^^^^^^^^^^^^^
  File "A:\test\AnturajSurgut\.venv\Lib\site-packages\redis\retry.py", line 46, in call_with_retry
    return do()
           ^^^^
  File "A:\test\AnturajSurgut\.venv\Lib\site-packages\redis\connection.py", line 265, in <lambda>
    lambda: self._connect(), lambda error: self.disconnect(error)
            ^^^^^^^^^^^^^^^
  File "A:\test\AnturajSurgut\.venv\Lib\site-packages\redis\connection.py", line 595, in _connect
    for res in socket.getaddrinfo(
               ^^^^^^^^^^^^^^^^^^^
  File "C:\Program Files\Python312\Lib\socket.py", line 963, in getaddrinfo
    for res in _socket.getaddrinfo(host, port, family, type, proto, flags):
               ^^^^^^^^^^^^^^^^^^^^^^^^^^^^^^^^^^^^^^^^^^^^^^^^^^^^^^^^^^^
socket.gaierror: [Errno 11001] getaddrinfo failed

During handling of the above exception, another exception occurred:

Traceback (most recent call last):
  File "A:\test\AnturajSurgut\.venv\Lib\site-packages\kombu\connection.py", line 472, in _reraise_as_library_errors
    yield
  File "A:\test\AnturajSurgut\.venv\Lib\site-packages\celery\app\base.py", line 798, in send_task
    self.backend.on_task_call(P, task_id)
  File "A:\test\AnturajSurgut\.venv\Lib\site-packages\celery\backends\redis.py", line 373, in on_task_call
    self.result_consumer.consume_from(task_id)
  File "A:\test\AnturajSurgut\.venv\Lib\site-packages\celery\backends\redis.py", line 169, in consume_from
    return self.start(task_id)
           ^^^^^^^^^^^^^^^^^^^
  File "A:\test\AnturajSurgut\.venv\Lib\site-packages\celery\backends\redis.py", line 147, in start
    self._consume_from(initial_task_id)
  File "A:\test\AnturajSurgut\.venv\Lib\site-packages\celery\backends\redis.py", line 176, in _consume_from
    with self.reconnect_on_error():
  File "C:\Program Files\Python312\Lib\contextlib.py", line 158, in __exit__
    self.gen.throw(value)
  File "A:\test\AnturajSurgut\.venv\Lib\site-packages\celery\backends\redis.py", line 130, in reconnect_on_error
    self._ensure(self._reconnect_pubsub, ())
  File "A:\test\AnturajSurgut\.venv\Lib\site-packages\celery\backends\redis.py", line 384, in ensure
    return retry_over_time(
           ^^^^^^^^^^^^^^^^
  File "A:\test\AnturajSurgut\.venv\Lib\site-packages\kombu\utils\functional.py", line 318, in retry_over_time
    return fun(*args, **kwargs)
           ^^^^^^^^^^^^^^^^^^^^
  File "A:\test\AnturajSurgut\.venv\Lib\site-packages\celery\backends\redis.py", line 106, in _reconnect_pubsub
    metas = self.backend.client.mget(self.subscribed_to)
            ^^^^^^^^^^^^^^^^^^^^^^^^^^^^^^^^^^^^^^^^^^^^
  File "A:\test\AnturajSurgut\.venv\Lib\site-packages\redis\commands\core.py", line 2015, in mget
    return self.execute_command("MGET", *args, **options)
           ^^^^^^^^^^^^^^^^^^^^^^^^^^^^^^^^^^^^^^^^^^^^^^
  File "A:\test\AnturajSurgut\.venv\Lib\site-packages\redis\client.py", line 533, in execute_command
    conn = self.connection or pool.get_connection(command_name, **options)
                              ^^^^^^^^^^^^^^^^^^^^^^^^^^^^^^^^^^^^^^^^^^^^
  File "A:\test\AnturajSurgut\.venv\Lib\site-packages\redis\connection.py", line 1086, in get_connection
    connection.connect()
  File "A:\test\AnturajSurgut\.venv\Lib\site-packages\redis\connection.py", line 270, in connect
    raise ConnectionError(self._error_message(e))
redis.exceptions.ConnectionError: Error 11001 connecting to redis:6379. getaddrinfo failed.

The above exception was the direct cause of the following exception:

Traceback (most recent call last):
  File "A:\test\AnturajSurgut\.venv\Lib\site-packages\django\core\handlers\exception.py", line 55, in inner
    response = get_response(request)
               ^^^^^^^^^^^^^^^^^^^^^
  File "A:\test\AnturajSurgut\.venv\Lib\site-packages\django\core\handlers\base.py", line 197, in _get_response
    response = wrapped_callback(request, *callback_args, **callback_kwargs)
               ^^^^^^^^^^^^^^^^^^^^^^^^^^^^^^^^^^^^^^^^^^^^^^^^^^^^^^^^^^^^
  File "A:\test\AnturajSurgut\.venv\Lib\site-packages\django\views\decorators\csrf.py", line 65, in _view_wrapper
    return view_func(request, *args, **kwargs)
           ^^^^^^^^^^^^^^^^^^^^^^^^^^^^^^^^^^^
  File "A:\test\AnturajSurgut\.venv\Lib\site-packages\django\views\generic\base.py", line 104, in view
    return self.dispatch(request, *args, **kwargs)
           ^^^^^^^^^^^^^^^^^^^^^^^^^^^^^^^^^^^^^^^
  File "A:\test\AnturajSurgut\.venv\Lib\site-packages\rest_framework\views.py", line 509, in dispatch
    response = self.handle_exception(exc)
               ^^^^^^^^^^^^^^^^^^^^^^^^^^
  File "A:\test\AnturajSurgut\.venv\Lib\site-packages\rest_framework\views.py", line 469, in handle_exception
    self.raise_uncaught_exception(exc)
  File "A:\test\AnturajSurgut\.venv\Lib\site-packages\rest_framework\views.py", line 480, in raise_uncaught_exception
    raise exc
  File "A:\test\AnturajSurgut\.venv\Lib\site-packages\rest_framework\views.py", line 506, in dispatch
    response = handler(request, *args, **kwargs)
               ^^^^^^^^^^^^^^^^^^^^^^^^^^^^^^^^^
  File "A:\test\AnturajSurgut\.venv\Lib\site-packages\rest_framework\decorators.py", line 50, in handler
    return func(*args, **kwargs)
           ^^^^^^^^^^^^^^^^^^^^^
  File "A:\test\AnturajSurgut\backend\order\views.py", line 34, in create_order
    serializer.save()
  File "A:\test\AnturajSurgut\.venv\Lib\site-packages\rest_framework\serializers.py", line 212, in save
    self.instance = self.create(validated_data)
                    ^^^^^^^^^^^^^^^^^^^^^^^^^^^
  File "A:\test\AnturajSurgut\backend\order\serializers\OrderSerializers.py", line 120, in create
    order = Order.objects.create(**validated_data)
            ^^^^^^^^^^^^^^^^^^^^^^^^^^^^^^^^^^^^^^
  File "A:\test\AnturajSurgut\.venv\Lib\site-packages\django\db\models\manager.py", line 87, in manager_method
    return getattr(self.get_queryset(), name)(*args, **kwargs)
           ^^^^^^^^^^^^^^^^^^^^^^^^^^^^^^^^^^^^^^^^^^^^^^^^^^^
  File "A:\test\AnturajSurgut\.venv\Lib\site-packages\django\db\models\query.py", line 677, in create
    obj.save(force_insert=True, using=self.db)
  File "A:\test\AnturajSurgut\backend\order\models.py", line 171, in save
    super(Order, self).save(*args, **kwargs)
  File "A:\test\AnturajSurgut\.venv\Lib\site-packages\django\db\models\base.py", line 822, in save
    self.save_base(
  File "A:\test\AnturajSurgut\.venv\Lib\site-packages\django\db\models\base.py", line 924, in save_base
    post_save.send(
  File "A:\test\AnturajSurgut\.venv\Lib\site-packages\django\dispatch\dispatcher.py", line 189, in send
    response = receiver(signal=self, sender=sender, **named)
               ^^^^^^^^^^^^^^^^^^^^^^^^^^^^^^^^^^^^^^^^^^^^^
  File "A:\test\AnturajSurgut\backend\DB\Signals\Order\Notify\signal_order_create.py", line 28, in send_email_order
    send_order_confirmation_email.delay(instance.order_number)
  File "A:\test\AnturajSurgut\.venv\Lib\site-packages\celery\app\task.py", line 444, in delay
    return self.apply_async(args, kwargs)
           ^^^^^^^^^^^^^^^^^^^^^^^^^^^^^^
  File "A:\test\AnturajSurgut\.venv\Lib\site-packages\celery\app\task.py", line 594, in apply_async
    return app.send_task(
           ^^^^^^^^^^^^^^
  File "A:\test\AnturajSurgut\.venv\Lib\site-packages\celery\app\base.py", line 796, in send_task
    with P.connection._reraise_as_library_errors():
  File "C:\Program Files\Python312\Lib\contextlib.py", line 158, in __exit__
    self.gen.throw(value)
  File "A:\test\AnturajSurgut\.venv\Lib\site-packages\kombu\connection.py", line 476, in _reraise_as_library_errors
    raise ConnectionError(str(exc)) from exc
kombu.exceptions.OperationalError: Error 11001 connecting to redis:6379. getaddrinfo failed.
[03.04.2024 01:34:50 - ERROR] Internal Server Error: /api/v1/order/create/, PATH: A:\test\AnturajSurgut\.venv\Lib\site-packages\django\utils\log.py, line: 241
Traceback (most recent call last):
  File "A:\test\AnturajSurgut\.venv\Lib\site-packages\redis\connection.py", line 264, in connect
    sock = self.retry.call_with_retry(
           ^^^^^^^^^^^^^^^^^^^^^^^^^^^
  File "A:\test\AnturajSurgut\.venv\Lib\site-packages\redis\retry.py", line 46, in call_with_retry
    return do()
           ^^^^
  File "A:\test\AnturajSurgut\.venv\Lib\site-packages\redis\connection.py", line 265, in <lambda>
    lambda: self._connect(), lambda error: self.disconnect(error)
            ^^^^^^^^^^^^^^^
  File "A:\test\AnturajSurgut\.venv\Lib\site-packages\redis\connection.py", line 595, in _connect
    for res in socket.getaddrinfo(
               ^^^^^^^^^^^^^^^^^^^
  File "C:\Program Files\Python312\Lib\socket.py", line 963, in getaddrinfo
    for res in _socket.getaddrinfo(host, port, family, type, proto, flags):
               ^^^^^^^^^^^^^^^^^^^^^^^^^^^^^^^^^^^^^^^^^^^^^^^^^^^^^^^^^^^
socket.gaierror: [Errno 11001] getaddrinfo failed

During handling of the above exception, another exception occurred:

Traceback (most recent call last):
  File "A:\test\AnturajSurgut\.venv\Lib\site-packages\celery\backends\redis.py", line 127, in reconnect_on_error
    yield
  File "A:\test\AnturajSurgut\.venv\Lib\site-packages\celery\backends\redis.py", line 177, in _consume_from
    self._pubsub.subscribe(key)
  File "A:\test\AnturajSurgut\.venv\Lib\site-packages\redis\client.py", line 916, in subscribe
    ret_val = self.execute_command("SUBSCRIBE", *new_channels.keys())
              ^^^^^^^^^^^^^^^^^^^^^^^^^^^^^^^^^^^^^^^^^^^^^^^^^^^^^^^
  File "A:\test\AnturajSurgut\.venv\Lib\site-packages\redis\client.py", line 749, in execute_command
    self.connection = self.connection_pool.get_connection(
                      ^^^^^^^^^^^^^^^^^^^^^^^^^^^^^^^^^^^^
  File "A:\test\AnturajSurgut\.venv\Lib\site-packages\redis\connection.py", line 1086, in get_connection
    connection.connect()
  File "A:\test\AnturajSurgut\.venv\Lib\site-packages\redis\connection.py", line 270, in connect
    raise ConnectionError(self._error_message(e))
redis.exceptions.ConnectionError: Error 11001 connecting to redis:6379. getaddrinfo failed.

During handling of the above exception, another exception occurred:

Traceback (most recent call last):
  File "A:\test\AnturajSurgut\.venv\Lib\site-packages\redis\connection.py", line 264, in connect
    sock = self.retry.call_with_retry(
           ^^^^^^^^^^^^^^^^^^^^^^^^^^^
  File "A:\test\AnturajSurgut\.venv\Lib\site-packages\redis\retry.py", line 46, in call_with_retry
    return do()
           ^^^^
  File "A:\test\AnturajSurgut\.venv\Lib\site-packages\redis\connection.py", line 265, in <lambda>
    lambda: self._connect(), lambda error: self.disconnect(error)
            ^^^^^^^^^^^^^^^
  File "A:\test\AnturajSurgut\.venv\Lib\site-packages\redis\connection.py", line 595, in _connect
    for res in socket.getaddrinfo(
               ^^^^^^^^^^^^^^^^^^^
  File "C:\Program Files\Python312\Lib\socket.py", line 963, in getaddrinfo
    for res in _socket.getaddrinfo(host, port, family, type, proto, flags):
               ^^^^^^^^^^^^^^^^^^^^^^^^^^^^^^^^^^^^^^^^^^^^^^^^^^^^^^^^^^^
socket.gaierror: [Errno 11001] getaddrinfo failed

During handling of the above exception, another exception occurred:

Traceback (most recent call last):
  File "A:\test\AnturajSurgut\.venv\Lib\site-packages\kombu\connection.py", line 472, in _reraise_as_library_errors
    yield
  File "A:\test\AnturajSurgut\.venv\Lib\site-packages\celery\app\base.py", line 798, in send_task
    self.backend.on_task_call(P, task_id)
  File "A:\test\AnturajSurgut\.venv\Lib\site-packages\celery\backends\redis.py", line 373, in on_task_call
    self.result_consumer.consume_from(task_id)
  File "A:\test\AnturajSurgut\.venv\Lib\site-packages\celery\backends\redis.py", line 169, in consume_from
    return self.start(task_id)
           ^^^^^^^^^^^^^^^^^^^
  File "A:\test\AnturajSurgut\.venv\Lib\site-packages\celery\backends\redis.py", line 147, in start
    self._consume_from(initial_task_id)
  File "A:\test\AnturajSurgut\.venv\Lib\site-packages\celery\backends\redis.py", line 176, in _consume_from
    with self.reconnect_on_error():
  File "C:\Program Files\Python312\Lib\contextlib.py", line 158, in __exit__
    self.gen.throw(value)
  File "A:\test\AnturajSurgut\.venv\Lib\site-packages\celery\backends\redis.py", line 130, in reconnect_on_error
    self._ensure(self._reconnect_pubsub, ())
  File "A:\test\AnturajSurgut\.venv\Lib\site-packages\celery\backends\redis.py", line 384, in ensure
    return retry_over_time(
           ^^^^^^^^^^^^^^^^
  File "A:\test\AnturajSurgut\.venv\Lib\site-packages\kombu\utils\functional.py", line 318, in retry_over_time
    return fun(*args, **kwargs)
           ^^^^^^^^^^^^^^^^^^^^
  File "A:\test\AnturajSurgut\.venv\Lib\site-packages\celery\backends\redis.py", line 106, in _reconnect_pubsub
    metas = self.backend.client.mget(self.subscribed_to)
            ^^^^^^^^^^^^^^^^^^^^^^^^^^^^^^^^^^^^^^^^^^^^
  File "A:\test\AnturajSurgut\.venv\Lib\site-packages\redis\commands\core.py", line 2015, in mget
    return self.execute_command("MGET", *args, **options)
           ^^^^^^^^^^^^^^^^^^^^^^^^^^^^^^^^^^^^^^^^^^^^^^
  File "A:\test\AnturajSurgut\.venv\Lib\site-packages\redis\client.py", line 533, in execute_command
    conn = self.connection or pool.get_connection(command_name, **options)
                              ^^^^^^^^^^^^^^^^^^^^^^^^^^^^^^^^^^^^^^^^^^^^
  File "A:\test\AnturajSurgut\.venv\Lib\site-packages\redis\connection.py", line 1086, in get_connection
    connection.connect()
  File "A:\test\AnturajSurgut\.venv\Lib\site-packages\redis\connection.py", line 270, in connect
    raise ConnectionError(self._error_message(e))
redis.exceptions.ConnectionError: Error 11001 connecting to redis:6379. getaddrinfo failed.

The above exception was the direct cause of the following exception:

Traceback (most recent call last):
  File "A:\test\AnturajSurgut\.venv\Lib\site-packages\django\core\handlers\exception.py", line 55, in inner
    response = get_response(request)
               ^^^^^^^^^^^^^^^^^^^^^
  File "A:\test\AnturajSurgut\.venv\Lib\site-packages\django\core\handlers\base.py", line 197, in _get_response
    response = wrapped_callback(request, *callback_args, **callback_kwargs)
               ^^^^^^^^^^^^^^^^^^^^^^^^^^^^^^^^^^^^^^^^^^^^^^^^^^^^^^^^^^^^
  File "A:\test\AnturajSurgut\.venv\Lib\site-packages\django\views\decorators\csrf.py", line 65, in _view_wrapper
    return view_func(request, *args, **kwargs)
           ^^^^^^^^^^^^^^^^^^^^^^^^^^^^^^^^^^^
  File "A:\test\AnturajSurgut\.venv\Lib\site-packages\django\views\generic\base.py", line 104, in view
    return self.dispatch(request, *args, **kwargs)
           ^^^^^^^^^^^^^^^^^^^^^^^^^^^^^^^^^^^^^^^
  File "A:\test\AnturajSurgut\.venv\Lib\site-packages\rest_framework\views.py", line 509, in dispatch
    response = self.handle_exception(exc)
               ^^^^^^^^^^^^^^^^^^^^^^^^^^
  File "A:\test\AnturajSurgut\.venv\Lib\site-packages\rest_framework\views.py", line 469, in handle_exception
    self.raise_uncaught_exception(exc)
  File "A:\test\AnturajSurgut\.venv\Lib\site-packages\rest_framework\views.py", line 480, in raise_uncaught_exception
    raise exc
  File "A:\test\AnturajSurgut\.venv\Lib\site-packages\rest_framework\views.py", line 506, in dispatch
    response = handler(request, *args, **kwargs)
               ^^^^^^^^^^^^^^^^^^^^^^^^^^^^^^^^^
  File "A:\test\AnturajSurgut\.venv\Lib\site-packages\rest_framework\decorators.py", line 50, in handler
    return func(*args, **kwargs)
           ^^^^^^^^^^^^^^^^^^^^^
  File "A:\test\AnturajSurgut\backend\order\views.py", line 34, in create_order
    serializer.save()
  File "A:\test\AnturajSurgut\.venv\Lib\site-packages\rest_framework\serializers.py", line 212, in save
    self.instance = self.create(validated_data)
                    ^^^^^^^^^^^^^^^^^^^^^^^^^^^
  File "A:\test\AnturajSurgut\backend\order\serializers\OrderSerializers.py", line 120, in create
    order = Order.objects.create(**validated_data)
            ^^^^^^^^^^^^^^^^^^^^^^^^^^^^^^^^^^^^^^
  File "A:\test\AnturajSurgut\.venv\Lib\site-packages\django\db\models\manager.py", line 87, in manager_method
    return getattr(self.get_queryset(), name)(*args, **kwargs)
           ^^^^^^^^^^^^^^^^^^^^^^^^^^^^^^^^^^^^^^^^^^^^^^^^^^^
  File "A:\test\AnturajSurgut\.venv\Lib\site-packages\django\db\models\query.py", line 677, in create
    obj.save(force_insert=True, using=self.db)
  File "A:\test\AnturajSurgut\backend\order\models.py", line 171, in save
    super(Order, self).save(*args, **kwargs)
  File "A:\test\AnturajSurgut\.venv\Lib\site-packages\django\db\models\base.py", line 822, in save
    self.save_base(
  File "A:\test\AnturajSurgut\.venv\Lib\site-packages\django\db\models\base.py", line 924, in save_base
    post_save.send(
  File "A:\test\AnturajSurgut\.venv\Lib\site-packages\django\dispatch\dispatcher.py", line 189, in send
    response = receiver(signal=self, sender=sender, **named)
               ^^^^^^^^^^^^^^^^^^^^^^^^^^^^^^^^^^^^^^^^^^^^^
  File "A:\test\AnturajSurgut\backend\DB\Signals\Order\Notify\signal_order_create.py", line 28, in send_email_order
    send_order_confirmation_email.delay(instance.order_number)
  File "A:\test\AnturajSurgut\.venv\Lib\site-packages\celery\app\task.py", line 444, in delay
    return self.apply_async(args, kwargs)
           ^^^^^^^^^^^^^^^^^^^^^^^^^^^^^^
  File "A:\test\AnturajSurgut\.venv\Lib\site-packages\celery\app\task.py", line 594, in apply_async
    return app.send_task(
           ^^^^^^^^^^^^^^
  File "A:\test\AnturajSurgut\.venv\Lib\site-packages\celery\app\base.py", line 796, in send_task
    with P.connection._reraise_as_library_errors():
  File "C:\Program Files\Python312\Lib\contextlib.py", line 158, in __exit__
    self.gen.throw(value)
  File "A:\test\AnturajSurgut\.venv\Lib\site-packages\kombu\connection.py", line 476, in _reraise_as_library_errors
    raise ConnectionError(str(exc)) from exc
kombu.exceptions.OperationalError: Error 11001 connecting to redis:6379. getaddrinfo failed.
[03.04.2024 01:37:36 - ERROR] Internal Server Error: /api/v1/order/create/, PATH: A:\test\AnturajSurgut\.venv\Lib\site-packages\django\utils\log.py, line: 241
Traceback (most recent call last):
  File "A:\test\AnturajSurgut\.venv\Lib\site-packages\redis\connection.py", line 264, in connect
    sock = self.retry.call_with_retry(
           ^^^^^^^^^^^^^^^^^^^^^^^^^^^
  File "A:\test\AnturajSurgut\.venv\Lib\site-packages\redis\retry.py", line 46, in call_with_retry
    return do()
           ^^^^
  File "A:\test\AnturajSurgut\.venv\Lib\site-packages\redis\connection.py", line 265, in <lambda>
    lambda: self._connect(), lambda error: self.disconnect(error)
            ^^^^^^^^^^^^^^^
  File "A:\test\AnturajSurgut\.venv\Lib\site-packages\redis\connection.py", line 595, in _connect
    for res in socket.getaddrinfo(
               ^^^^^^^^^^^^^^^^^^^
  File "C:\Program Files\Python312\Lib\socket.py", line 963, in getaddrinfo
    for res in _socket.getaddrinfo(host, port, family, type, proto, flags):
               ^^^^^^^^^^^^^^^^^^^^^^^^^^^^^^^^^^^^^^^^^^^^^^^^^^^^^^^^^^^
socket.gaierror: [Errno 11001] getaddrinfo failed

During handling of the above exception, another exception occurred:

Traceback (most recent call last):
  File "A:\test\AnturajSurgut\.venv\Lib\site-packages\celery\backends\redis.py", line 127, in reconnect_on_error
    yield
  File "A:\test\AnturajSurgut\.venv\Lib\site-packages\celery\backends\redis.py", line 177, in _consume_from
    self._pubsub.subscribe(key)
  File "A:\test\AnturajSurgut\.venv\Lib\site-packages\redis\client.py", line 916, in subscribe
    ret_val = self.execute_command("SUBSCRIBE", *new_channels.keys())
              ^^^^^^^^^^^^^^^^^^^^^^^^^^^^^^^^^^^^^^^^^^^^^^^^^^^^^^^
  File "A:\test\AnturajSurgut\.venv\Lib\site-packages\redis\client.py", line 749, in execute_command
    self.connection = self.connection_pool.get_connection(
                      ^^^^^^^^^^^^^^^^^^^^^^^^^^^^^^^^^^^^
  File "A:\test\AnturajSurgut\.venv\Lib\site-packages\redis\connection.py", line 1086, in get_connection
    connection.connect()
  File "A:\test\AnturajSurgut\.venv\Lib\site-packages\redis\connection.py", line 270, in connect
    raise ConnectionError(self._error_message(e))
redis.exceptions.ConnectionError: Error 11001 connecting to redis:6379. getaddrinfo failed.

During handling of the above exception, another exception occurred:

Traceback (most recent call last):
  File "A:\test\AnturajSurgut\.venv\Lib\site-packages\redis\connection.py", line 264, in connect
    sock = self.retry.call_with_retry(
           ^^^^^^^^^^^^^^^^^^^^^^^^^^^
  File "A:\test\AnturajSurgut\.venv\Lib\site-packages\redis\retry.py", line 46, in call_with_retry
    return do()
           ^^^^
  File "A:\test\AnturajSurgut\.venv\Lib\site-packages\redis\connection.py", line 265, in <lambda>
    lambda: self._connect(), lambda error: self.disconnect(error)
            ^^^^^^^^^^^^^^^
  File "A:\test\AnturajSurgut\.venv\Lib\site-packages\redis\connection.py", line 595, in _connect
    for res in socket.getaddrinfo(
               ^^^^^^^^^^^^^^^^^^^
  File "C:\Program Files\Python312\Lib\socket.py", line 963, in getaddrinfo
    for res in _socket.getaddrinfo(host, port, family, type, proto, flags):
               ^^^^^^^^^^^^^^^^^^^^^^^^^^^^^^^^^^^^^^^^^^^^^^^^^^^^^^^^^^^
socket.gaierror: [Errno 11001] getaddrinfo failed

During handling of the above exception, another exception occurred:

Traceback (most recent call last):
  File "A:\test\AnturajSurgut\.venv\Lib\site-packages\kombu\connection.py", line 472, in _reraise_as_library_errors
    yield
  File "A:\test\AnturajSurgut\.venv\Lib\site-packages\celery\app\base.py", line 798, in send_task
    self.backend.on_task_call(P, task_id)
  File "A:\test\AnturajSurgut\.venv\Lib\site-packages\celery\backends\redis.py", line 373, in on_task_call
    self.result_consumer.consume_from(task_id)
  File "A:\test\AnturajSurgut\.venv\Lib\site-packages\celery\backends\redis.py", line 169, in consume_from
    return self.start(task_id)
           ^^^^^^^^^^^^^^^^^^^
  File "A:\test\AnturajSurgut\.venv\Lib\site-packages\celery\backends\redis.py", line 147, in start
    self._consume_from(initial_task_id)
  File "A:\test\AnturajSurgut\.venv\Lib\site-packages\celery\backends\redis.py", line 176, in _consume_from
    with self.reconnect_on_error():
  File "C:\Program Files\Python312\Lib\contextlib.py", line 158, in __exit__
    self.gen.throw(value)
  File "A:\test\AnturajSurgut\.venv\Lib\site-packages\celery\backends\redis.py", line 130, in reconnect_on_error
    self._ensure(self._reconnect_pubsub, ())
  File "A:\test\AnturajSurgut\.venv\Lib\site-packages\celery\backends\redis.py", line 384, in ensure
    return retry_over_time(
           ^^^^^^^^^^^^^^^^
  File "A:\test\AnturajSurgut\.venv\Lib\site-packages\kombu\utils\functional.py", line 318, in retry_over_time
    return fun(*args, **kwargs)
           ^^^^^^^^^^^^^^^^^^^^
  File "A:\test\AnturajSurgut\.venv\Lib\site-packages\celery\backends\redis.py", line 106, in _reconnect_pubsub
    metas = self.backend.client.mget(self.subscribed_to)
            ^^^^^^^^^^^^^^^^^^^^^^^^^^^^^^^^^^^^^^^^^^^^
  File "A:\test\AnturajSurgut\.venv\Lib\site-packages\redis\commands\core.py", line 2015, in mget
    return self.execute_command("MGET", *args, **options)
           ^^^^^^^^^^^^^^^^^^^^^^^^^^^^^^^^^^^^^^^^^^^^^^
  File "A:\test\AnturajSurgut\.venv\Lib\site-packages\redis\client.py", line 533, in execute_command
    conn = self.connection or pool.get_connection(command_name, **options)
                              ^^^^^^^^^^^^^^^^^^^^^^^^^^^^^^^^^^^^^^^^^^^^
  File "A:\test\AnturajSurgut\.venv\Lib\site-packages\redis\connection.py", line 1086, in get_connection
    connection.connect()
  File "A:\test\AnturajSurgut\.venv\Lib\site-packages\redis\connection.py", line 270, in connect
    raise ConnectionError(self._error_message(e))
redis.exceptions.ConnectionError: Error 11001 connecting to redis:6379. getaddrinfo failed.

The above exception was the direct cause of the following exception:

Traceback (most recent call last):
  File "A:\test\AnturajSurgut\.venv\Lib\site-packages\django\core\handlers\exception.py", line 55, in inner
    response = get_response(request)
               ^^^^^^^^^^^^^^^^^^^^^
  File "A:\test\AnturajSurgut\.venv\Lib\site-packages\django\core\handlers\base.py", line 197, in _get_response
    response = wrapped_callback(request, *callback_args, **callback_kwargs)
               ^^^^^^^^^^^^^^^^^^^^^^^^^^^^^^^^^^^^^^^^^^^^^^^^^^^^^^^^^^^^
  File "A:\test\AnturajSurgut\.venv\Lib\site-packages\django\views\decorators\csrf.py", line 65, in _view_wrapper
    return view_func(request, *args, **kwargs)
           ^^^^^^^^^^^^^^^^^^^^^^^^^^^^^^^^^^^
  File "A:\test\AnturajSurgut\.venv\Lib\site-packages\django\views\generic\base.py", line 104, in view
    return self.dispatch(request, *args, **kwargs)
           ^^^^^^^^^^^^^^^^^^^^^^^^^^^^^^^^^^^^^^^
  File "A:\test\AnturajSurgut\.venv\Lib\site-packages\rest_framework\views.py", line 509, in dispatch
    response = self.handle_exception(exc)
               ^^^^^^^^^^^^^^^^^^^^^^^^^^
  File "A:\test\AnturajSurgut\.venv\Lib\site-packages\rest_framework\views.py", line 469, in handle_exception
    self.raise_uncaught_exception(exc)
  File "A:\test\AnturajSurgut\.venv\Lib\site-packages\rest_framework\views.py", line 480, in raise_uncaught_exception
    raise exc
  File "A:\test\AnturajSurgut\.venv\Lib\site-packages\rest_framework\views.py", line 506, in dispatch
    response = handler(request, *args, **kwargs)
               ^^^^^^^^^^^^^^^^^^^^^^^^^^^^^^^^^
  File "A:\test\AnturajSurgut\.venv\Lib\site-packages\rest_framework\decorators.py", line 50, in handler
    return func(*args, **kwargs)
           ^^^^^^^^^^^^^^^^^^^^^
  File "A:\test\AnturajSurgut\backend\order\views.py", line 34, in create_order
    serializer.save()
  File "A:\test\AnturajSurgut\.venv\Lib\site-packages\rest_framework\serializers.py", line 212, in save
    self.instance = self.create(validated_data)
                    ^^^^^^^^^^^^^^^^^^^^^^^^^^^
  File "A:\test\AnturajSurgut\backend\order\serializers\OrderSerializers.py", line 121, in create
    order = Order.objects.create(**validated_data)
            ^^^^^^^^^^^^^^^^^^^^^^^^^^^^^^^^^^^^^^
  File "A:\test\AnturajSurgut\.venv\Lib\site-packages\django\db\models\manager.py", line 87, in manager_method
    return getattr(self.get_queryset(), name)(*args, **kwargs)
           ^^^^^^^^^^^^^^^^^^^^^^^^^^^^^^^^^^^^^^^^^^^^^^^^^^^
  File "A:\test\AnturajSurgut\.venv\Lib\site-packages\django\db\models\query.py", line 677, in create
    obj.save(force_insert=True, using=self.db)
  File "A:\test\AnturajSurgut\backend\order\models.py", line 171, in save
    super(Order, self).save(*args, **kwargs)
  File "A:\test\AnturajSurgut\.venv\Lib\site-packages\django\db\models\base.py", line 822, in save
    self.save_base(
  File "A:\test\AnturajSurgut\.venv\Lib\site-packages\django\db\models\base.py", line 924, in save_base
    post_save.send(
  File "A:\test\AnturajSurgut\.venv\Lib\site-packages\django\dispatch\dispatcher.py", line 189, in send
    response = receiver(signal=self, sender=sender, **named)
               ^^^^^^^^^^^^^^^^^^^^^^^^^^^^^^^^^^^^^^^^^^^^^
  File "A:\test\AnturajSurgut\backend\DB\Signals\Order\Notify\signal_order_create.py", line 28, in send_email_order
    send_order_confirmation_email.delay(instance.order_number)
  File "A:\test\AnturajSurgut\.venv\Lib\site-packages\celery\app\task.py", line 444, in delay
    return self.apply_async(args, kwargs)
           ^^^^^^^^^^^^^^^^^^^^^^^^^^^^^^
  File "A:\test\AnturajSurgut\.venv\Lib\site-packages\celery\app\task.py", line 594, in apply_async
    return app.send_task(
           ^^^^^^^^^^^^^^
  File "A:\test\AnturajSurgut\.venv\Lib\site-packages\celery\app\base.py", line 796, in send_task
    with P.connection._reraise_as_library_errors():
  File "C:\Program Files\Python312\Lib\contextlib.py", line 158, in __exit__
    self.gen.throw(value)
  File "A:\test\AnturajSurgut\.venv\Lib\site-packages\kombu\connection.py", line 476, in _reraise_as_library_errors
    raise ConnectionError(str(exc)) from exc
kombu.exceptions.OperationalError: Error 11001 connecting to redis:6379. getaddrinfo failed.
[03.04.2024 01:38:10 - ERROR] Internal Server Error: /api/v1/order/create/, PATH: A:\test\AnturajSurgut\.venv\Lib\site-packages\django\utils\log.py, line: 241
Traceback (most recent call last):
  File "A:\test\AnturajSurgut\.venv\Lib\site-packages\redis\connection.py", line 264, in connect
    sock = self.retry.call_with_retry(
           ^^^^^^^^^^^^^^^^^^^^^^^^^^^
  File "A:\test\AnturajSurgut\.venv\Lib\site-packages\redis\retry.py", line 46, in call_with_retry
    return do()
           ^^^^
  File "A:\test\AnturajSurgut\.venv\Lib\site-packages\redis\connection.py", line 265, in <lambda>
    lambda: self._connect(), lambda error: self.disconnect(error)
            ^^^^^^^^^^^^^^^
  File "A:\test\AnturajSurgut\.venv\Lib\site-packages\redis\connection.py", line 595, in _connect
    for res in socket.getaddrinfo(
               ^^^^^^^^^^^^^^^^^^^
  File "C:\Program Files\Python312\Lib\socket.py", line 963, in getaddrinfo
    for res in _socket.getaddrinfo(host, port, family, type, proto, flags):
               ^^^^^^^^^^^^^^^^^^^^^^^^^^^^^^^^^^^^^^^^^^^^^^^^^^^^^^^^^^^
socket.gaierror: [Errno 11001] getaddrinfo failed

During handling of the above exception, another exception occurred:

Traceback (most recent call last):
  File "A:\test\AnturajSurgut\.venv\Lib\site-packages\celery\backends\redis.py", line 127, in reconnect_on_error
    yield
  File "A:\test\AnturajSurgut\.venv\Lib\site-packages\celery\backends\redis.py", line 177, in _consume_from
    self._pubsub.subscribe(key)
  File "A:\test\AnturajSurgut\.venv\Lib\site-packages\redis\client.py", line 916, in subscribe
    ret_val = self.execute_command("SUBSCRIBE", *new_channels.keys())
              ^^^^^^^^^^^^^^^^^^^^^^^^^^^^^^^^^^^^^^^^^^^^^^^^^^^^^^^
  File "A:\test\AnturajSurgut\.venv\Lib\site-packages\redis\client.py", line 749, in execute_command
    self.connection = self.connection_pool.get_connection(
                      ^^^^^^^^^^^^^^^^^^^^^^^^^^^^^^^^^^^^
  File "A:\test\AnturajSurgut\.venv\Lib\site-packages\redis\connection.py", line 1086, in get_connection
    connection.connect()
  File "A:\test\AnturajSurgut\.venv\Lib\site-packages\redis\connection.py", line 270, in connect
    raise ConnectionError(self._error_message(e))
redis.exceptions.ConnectionError: Error 11001 connecting to redis:6379. getaddrinfo failed.

During handling of the above exception, another exception occurred:

Traceback (most recent call last):
  File "A:\test\AnturajSurgut\.venv\Lib\site-packages\redis\connection.py", line 264, in connect
    sock = self.retry.call_with_retry(
           ^^^^^^^^^^^^^^^^^^^^^^^^^^^
  File "A:\test\AnturajSurgut\.venv\Lib\site-packages\redis\retry.py", line 46, in call_with_retry
    return do()
           ^^^^
  File "A:\test\AnturajSurgut\.venv\Lib\site-packages\redis\connection.py", line 265, in <lambda>
    lambda: self._connect(), lambda error: self.disconnect(error)
            ^^^^^^^^^^^^^^^
  File "A:\test\AnturajSurgut\.venv\Lib\site-packages\redis\connection.py", line 595, in _connect
    for res in socket.getaddrinfo(
               ^^^^^^^^^^^^^^^^^^^
  File "C:\Program Files\Python312\Lib\socket.py", line 963, in getaddrinfo
    for res in _socket.getaddrinfo(host, port, family, type, proto, flags):
               ^^^^^^^^^^^^^^^^^^^^^^^^^^^^^^^^^^^^^^^^^^^^^^^^^^^^^^^^^^^
socket.gaierror: [Errno 11001] getaddrinfo failed

During handling of the above exception, another exception occurred:

Traceback (most recent call last):
  File "A:\test\AnturajSurgut\.venv\Lib\site-packages\kombu\connection.py", line 472, in _reraise_as_library_errors
    yield
  File "A:\test\AnturajSurgut\.venv\Lib\site-packages\celery\app\base.py", line 798, in send_task
    self.backend.on_task_call(P, task_id)
  File "A:\test\AnturajSurgut\.venv\Lib\site-packages\celery\backends\redis.py", line 373, in on_task_call
    self.result_consumer.consume_from(task_id)
  File "A:\test\AnturajSurgut\.venv\Lib\site-packages\celery\backends\redis.py", line 169, in consume_from
    return self.start(task_id)
           ^^^^^^^^^^^^^^^^^^^
  File "A:\test\AnturajSurgut\.venv\Lib\site-packages\celery\backends\redis.py", line 147, in start
    self._consume_from(initial_task_id)
  File "A:\test\AnturajSurgut\.venv\Lib\site-packages\celery\backends\redis.py", line 176, in _consume_from
    with self.reconnect_on_error():
  File "C:\Program Files\Python312\Lib\contextlib.py", line 158, in __exit__
    self.gen.throw(value)
  File "A:\test\AnturajSurgut\.venv\Lib\site-packages\celery\backends\redis.py", line 130, in reconnect_on_error
    self._ensure(self._reconnect_pubsub, ())
  File "A:\test\AnturajSurgut\.venv\Lib\site-packages\celery\backends\redis.py", line 384, in ensure
    return retry_over_time(
           ^^^^^^^^^^^^^^^^
  File "A:\test\AnturajSurgut\.venv\Lib\site-packages\kombu\utils\functional.py", line 318, in retry_over_time
    return fun(*args, **kwargs)
           ^^^^^^^^^^^^^^^^^^^^
  File "A:\test\AnturajSurgut\.venv\Lib\site-packages\celery\backends\redis.py", line 106, in _reconnect_pubsub
    metas = self.backend.client.mget(self.subscribed_to)
            ^^^^^^^^^^^^^^^^^^^^^^^^^^^^^^^^^^^^^^^^^^^^
  File "A:\test\AnturajSurgut\.venv\Lib\site-packages\redis\commands\core.py", line 2015, in mget
    return self.execute_command("MGET", *args, **options)
           ^^^^^^^^^^^^^^^^^^^^^^^^^^^^^^^^^^^^^^^^^^^^^^
  File "A:\test\AnturajSurgut\.venv\Lib\site-packages\redis\client.py", line 533, in execute_command
    conn = self.connection or pool.get_connection(command_name, **options)
                              ^^^^^^^^^^^^^^^^^^^^^^^^^^^^^^^^^^^^^^^^^^^^
  File "A:\test\AnturajSurgut\.venv\Lib\site-packages\redis\connection.py", line 1086, in get_connection
    connection.connect()
  File "A:\test\AnturajSurgut\.venv\Lib\site-packages\redis\connection.py", line 270, in connect
    raise ConnectionError(self._error_message(e))
redis.exceptions.ConnectionError: Error 11001 connecting to redis:6379. getaddrinfo failed.

The above exception was the direct cause of the following exception:

Traceback (most recent call last):
  File "A:\test\AnturajSurgut\.venv\Lib\site-packages\django\core\handlers\exception.py", line 55, in inner
    response = get_response(request)
               ^^^^^^^^^^^^^^^^^^^^^
  File "A:\test\AnturajSurgut\.venv\Lib\site-packages\django\core\handlers\base.py", line 197, in _get_response
    response = wrapped_callback(request, *callback_args, **callback_kwargs)
               ^^^^^^^^^^^^^^^^^^^^^^^^^^^^^^^^^^^^^^^^^^^^^^^^^^^^^^^^^^^^
  File "A:\test\AnturajSurgut\.venv\Lib\site-packages\django\views\decorators\csrf.py", line 65, in _view_wrapper
    return view_func(request, *args, **kwargs)
           ^^^^^^^^^^^^^^^^^^^^^^^^^^^^^^^^^^^
  File "A:\test\AnturajSurgut\.venv\Lib\site-packages\django\views\generic\base.py", line 104, in view
    return self.dispatch(request, *args, **kwargs)
           ^^^^^^^^^^^^^^^^^^^^^^^^^^^^^^^^^^^^^^^
  File "A:\test\AnturajSurgut\.venv\Lib\site-packages\rest_framework\views.py", line 509, in dispatch
    response = self.handle_exception(exc)
               ^^^^^^^^^^^^^^^^^^^^^^^^^^
  File "A:\test\AnturajSurgut\.venv\Lib\site-packages\rest_framework\views.py", line 469, in handle_exception
    self.raise_uncaught_exception(exc)
  File "A:\test\AnturajSurgut\.venv\Lib\site-packages\rest_framework\views.py", line 480, in raise_uncaught_exception
    raise exc
  File "A:\test\AnturajSurgut\.venv\Lib\site-packages\rest_framework\views.py", line 506, in dispatch
    response = handler(request, *args, **kwargs)
               ^^^^^^^^^^^^^^^^^^^^^^^^^^^^^^^^^
  File "A:\test\AnturajSurgut\.venv\Lib\site-packages\rest_framework\decorators.py", line 50, in handler
    return func(*args, **kwargs)
           ^^^^^^^^^^^^^^^^^^^^^
  File "A:\test\AnturajSurgut\backend\order\views.py", line 34, in create_order
    serializer.save()
  File "A:\test\AnturajSurgut\.venv\Lib\site-packages\rest_framework\serializers.py", line 212, in save
    self.instance = self.create(validated_data)
                    ^^^^^^^^^^^^^^^^^^^^^^^^^^^
  File "A:\test\AnturajSurgut\backend\order\serializers\OrderSerializers.py", line 121, in create
    order = Order.objects.create(**validated_data)
            ^^^^^^^^^^^^^^^^^^^^^^^^^^^^^^^^^^^^^^
  File "A:\test\AnturajSurgut\.venv\Lib\site-packages\django\db\models\manager.py", line 87, in manager_method
    return getattr(self.get_queryset(), name)(*args, **kwargs)
           ^^^^^^^^^^^^^^^^^^^^^^^^^^^^^^^^^^^^^^^^^^^^^^^^^^^
  File "A:\test\AnturajSurgut\.venv\Lib\site-packages\django\db\models\query.py", line 677, in create
    obj.save(force_insert=True, using=self.db)
  File "A:\test\AnturajSurgut\backend\order\models.py", line 171, in save
    super(Order, self).save(*args, **kwargs)
  File "A:\test\AnturajSurgut\.venv\Lib\site-packages\django\db\models\base.py", line 822, in save
    self.save_base(
  File "A:\test\AnturajSurgut\.venv\Lib\site-packages\django\db\models\base.py", line 924, in save_base
    post_save.send(
  File "A:\test\AnturajSurgut\.venv\Lib\site-packages\django\dispatch\dispatcher.py", line 189, in send
    response = receiver(signal=self, sender=sender, **named)
               ^^^^^^^^^^^^^^^^^^^^^^^^^^^^^^^^^^^^^^^^^^^^^
  File "A:\test\AnturajSurgut\backend\DB\Signals\Order\Notify\signal_order_create.py", line 28, in send_email_order
    send_order_confirmation_email.delay(instance.order_number)
  File "A:\test\AnturajSurgut\.venv\Lib\site-packages\celery\app\task.py", line 444, in delay
    return self.apply_async(args, kwargs)
           ^^^^^^^^^^^^^^^^^^^^^^^^^^^^^^
  File "A:\test\AnturajSurgut\.venv\Lib\site-packages\celery\app\task.py", line 594, in apply_async
    return app.send_task(
           ^^^^^^^^^^^^^^
  File "A:\test\AnturajSurgut\.venv\Lib\site-packages\celery\app\base.py", line 796, in send_task
    with P.connection._reraise_as_library_errors():
  File "C:\Program Files\Python312\Lib\contextlib.py", line 158, in __exit__
    self.gen.throw(value)
  File "A:\test\AnturajSurgut\.venv\Lib\site-packages\kombu\connection.py", line 476, in _reraise_as_library_errors
    raise ConnectionError(str(exc)) from exc
kombu.exceptions.OperationalError: Error 11001 connecting to redis:6379. getaddrinfo failed.
[03.04.2024 01:39:02 - ERROR] Internal Server Error: /api/v1/order/create/, PATH: A:\test\AnturajSurgut\.venv\Lib\site-packages\django\utils\log.py, line: 241
Traceback (most recent call last):
  File "A:\test\AnturajSurgut\.venv\Lib\site-packages\redis\connection.py", line 264, in connect
    sock = self.retry.call_with_retry(
           ^^^^^^^^^^^^^^^^^^^^^^^^^^^
  File "A:\test\AnturajSurgut\.venv\Lib\site-packages\redis\retry.py", line 46, in call_with_retry
    return do()
           ^^^^
  File "A:\test\AnturajSurgut\.venv\Lib\site-packages\redis\connection.py", line 265, in <lambda>
    lambda: self._connect(), lambda error: self.disconnect(error)
            ^^^^^^^^^^^^^^^
  File "A:\test\AnturajSurgut\.venv\Lib\site-packages\redis\connection.py", line 595, in _connect
    for res in socket.getaddrinfo(
               ^^^^^^^^^^^^^^^^^^^
  File "C:\Program Files\Python312\Lib\socket.py", line 963, in getaddrinfo
    for res in _socket.getaddrinfo(host, port, family, type, proto, flags):
               ^^^^^^^^^^^^^^^^^^^^^^^^^^^^^^^^^^^^^^^^^^^^^^^^^^^^^^^^^^^
socket.gaierror: [Errno 11001] getaddrinfo failed

During handling of the above exception, another exception occurred:

Traceback (most recent call last):
  File "A:\test\AnturajSurgut\.venv\Lib\site-packages\celery\backends\redis.py", line 127, in reconnect_on_error
    yield
  File "A:\test\AnturajSurgut\.venv\Lib\site-packages\celery\backends\redis.py", line 177, in _consume_from
    self._pubsub.subscribe(key)
  File "A:\test\AnturajSurgut\.venv\Lib\site-packages\redis\client.py", line 916, in subscribe
    ret_val = self.execute_command("SUBSCRIBE", *new_channels.keys())
              ^^^^^^^^^^^^^^^^^^^^^^^^^^^^^^^^^^^^^^^^^^^^^^^^^^^^^^^
  File "A:\test\AnturajSurgut\.venv\Lib\site-packages\redis\client.py", line 749, in execute_command
    self.connection = self.connection_pool.get_connection(
                      ^^^^^^^^^^^^^^^^^^^^^^^^^^^^^^^^^^^^
  File "A:\test\AnturajSurgut\.venv\Lib\site-packages\redis\connection.py", line 1086, in get_connection
    connection.connect()
  File "A:\test\AnturajSurgut\.venv\Lib\site-packages\redis\connection.py", line 270, in connect
    raise ConnectionError(self._error_message(e))
redis.exceptions.ConnectionError: Error 11001 connecting to redis:6379. getaddrinfo failed.

During handling of the above exception, another exception occurred:

Traceback (most recent call last):
  File "A:\test\AnturajSurgut\.venv\Lib\site-packages\redis\connection.py", line 264, in connect
    sock = self.retry.call_with_retry(
           ^^^^^^^^^^^^^^^^^^^^^^^^^^^
  File "A:\test\AnturajSurgut\.venv\Lib\site-packages\redis\retry.py", line 46, in call_with_retry
    return do()
           ^^^^
  File "A:\test\AnturajSurgut\.venv\Lib\site-packages\redis\connection.py", line 265, in <lambda>
    lambda: self._connect(), lambda error: self.disconnect(error)
            ^^^^^^^^^^^^^^^
  File "A:\test\AnturajSurgut\.venv\Lib\site-packages\redis\connection.py", line 595, in _connect
    for res in socket.getaddrinfo(
               ^^^^^^^^^^^^^^^^^^^
  File "C:\Program Files\Python312\Lib\socket.py", line 963, in getaddrinfo
    for res in _socket.getaddrinfo(host, port, family, type, proto, flags):
               ^^^^^^^^^^^^^^^^^^^^^^^^^^^^^^^^^^^^^^^^^^^^^^^^^^^^^^^^^^^
socket.gaierror: [Errno 11001] getaddrinfo failed

During handling of the above exception, another exception occurred:

Traceback (most recent call last):
  File "A:\test\AnturajSurgut\.venv\Lib\site-packages\kombu\connection.py", line 472, in _reraise_as_library_errors
    yield
  File "A:\test\AnturajSurgut\.venv\Lib\site-packages\celery\app\base.py", line 798, in send_task
    self.backend.on_task_call(P, task_id)
  File "A:\test\AnturajSurgut\.venv\Lib\site-packages\celery\backends\redis.py", line 373, in on_task_call
    self.result_consumer.consume_from(task_id)
  File "A:\test\AnturajSurgut\.venv\Lib\site-packages\celery\backends\redis.py", line 169, in consume_from
    return self.start(task_id)
           ^^^^^^^^^^^^^^^^^^^
  File "A:\test\AnturajSurgut\.venv\Lib\site-packages\celery\backends\redis.py", line 147, in start
    self._consume_from(initial_task_id)
  File "A:\test\AnturajSurgut\.venv\Lib\site-packages\celery\backends\redis.py", line 176, in _consume_from
    with self.reconnect_on_error():
  File "C:\Program Files\Python312\Lib\contextlib.py", line 158, in __exit__
    self.gen.throw(value)
  File "A:\test\AnturajSurgut\.venv\Lib\site-packages\celery\backends\redis.py", line 130, in reconnect_on_error
    self._ensure(self._reconnect_pubsub, ())
  File "A:\test\AnturajSurgut\.venv\Lib\site-packages\celery\backends\redis.py", line 384, in ensure
    return retry_over_time(
           ^^^^^^^^^^^^^^^^
  File "A:\test\AnturajSurgut\.venv\Lib\site-packages\kombu\utils\functional.py", line 318, in retry_over_time
    return fun(*args, **kwargs)
           ^^^^^^^^^^^^^^^^^^^^
  File "A:\test\AnturajSurgut\.venv\Lib\site-packages\celery\backends\redis.py", line 106, in _reconnect_pubsub
    metas = self.backend.client.mget(self.subscribed_to)
            ^^^^^^^^^^^^^^^^^^^^^^^^^^^^^^^^^^^^^^^^^^^^
  File "A:\test\AnturajSurgut\.venv\Lib\site-packages\redis\commands\core.py", line 2015, in mget
    return self.execute_command("MGET", *args, **options)
           ^^^^^^^^^^^^^^^^^^^^^^^^^^^^^^^^^^^^^^^^^^^^^^
  File "A:\test\AnturajSurgut\.venv\Lib\site-packages\redis\client.py", line 533, in execute_command
    conn = self.connection or pool.get_connection(command_name, **options)
                              ^^^^^^^^^^^^^^^^^^^^^^^^^^^^^^^^^^^^^^^^^^^^
  File "A:\test\AnturajSurgut\.venv\Lib\site-packages\redis\connection.py", line 1086, in get_connection
    connection.connect()
  File "A:\test\AnturajSurgut\.venv\Lib\site-packages\redis\connection.py", line 270, in connect
    raise ConnectionError(self._error_message(e))
redis.exceptions.ConnectionError: Error 11001 connecting to redis:6379. getaddrinfo failed.

The above exception was the direct cause of the following exception:

Traceback (most recent call last):
  File "A:\test\AnturajSurgut\.venv\Lib\site-packages\django\core\handlers\exception.py", line 55, in inner
    response = get_response(request)
               ^^^^^^^^^^^^^^^^^^^^^
  File "A:\test\AnturajSurgut\.venv\Lib\site-packages\django\core\handlers\base.py", line 197, in _get_response
    response = wrapped_callback(request, *callback_args, **callback_kwargs)
               ^^^^^^^^^^^^^^^^^^^^^^^^^^^^^^^^^^^^^^^^^^^^^^^^^^^^^^^^^^^^
  File "A:\test\AnturajSurgut\.venv\Lib\site-packages\django\views\decorators\csrf.py", line 65, in _view_wrapper
    return view_func(request, *args, **kwargs)
           ^^^^^^^^^^^^^^^^^^^^^^^^^^^^^^^^^^^
  File "A:\test\AnturajSurgut\.venv\Lib\site-packages\django\views\generic\base.py", line 104, in view
    return self.dispatch(request, *args, **kwargs)
           ^^^^^^^^^^^^^^^^^^^^^^^^^^^^^^^^^^^^^^^
  File "A:\test\AnturajSurgut\.venv\Lib\site-packages\rest_framework\views.py", line 509, in dispatch
    response = self.handle_exception(exc)
               ^^^^^^^^^^^^^^^^^^^^^^^^^^
  File "A:\test\AnturajSurgut\.venv\Lib\site-packages\rest_framework\views.py", line 469, in handle_exception
    self.raise_uncaught_exception(exc)
  File "A:\test\AnturajSurgut\.venv\Lib\site-packages\rest_framework\views.py", line 480, in raise_uncaught_exception
    raise exc
  File "A:\test\AnturajSurgut\.venv\Lib\site-packages\rest_framework\views.py", line 506, in dispatch
    response = handler(request, *args, **kwargs)
               ^^^^^^^^^^^^^^^^^^^^^^^^^^^^^^^^^
  File "A:\test\AnturajSurgut\.venv\Lib\site-packages\rest_framework\decorators.py", line 50, in handler
    return func(*args, **kwargs)
           ^^^^^^^^^^^^^^^^^^^^^
  File "A:\test\AnturajSurgut\backend\order\views.py", line 34, in create_order
    serializer.save()
  File "A:\test\AnturajSurgut\.venv\Lib\site-packages\rest_framework\serializers.py", line 212, in save
    self.instance = self.create(validated_data)
                    ^^^^^^^^^^^^^^^^^^^^^^^^^^^
  File "A:\test\AnturajSurgut\backend\order\serializers\OrderSerializers.py", line 121, in create
    order = Order.objects.create(**validated_data)
            ^^^^^^^^^^^^^^^^^^^^^^^^^^^^^^^^^^^^^^
  File "A:\test\AnturajSurgut\.venv\Lib\site-packages\django\db\models\manager.py", line 87, in manager_method
    return getattr(self.get_queryset(), name)(*args, **kwargs)
           ^^^^^^^^^^^^^^^^^^^^^^^^^^^^^^^^^^^^^^^^^^^^^^^^^^^
  File "A:\test\AnturajSurgut\.venv\Lib\site-packages\django\db\models\query.py", line 677, in create
    obj.save(force_insert=True, using=self.db)
  File "A:\test\AnturajSurgut\backend\order\models.py", line 171, in save
    super(Order, self).save(*args, **kwargs)
  File "A:\test\AnturajSurgut\.venv\Lib\site-packages\django\db\models\base.py", line 822, in save
    self.save_base(
  File "A:\test\AnturajSurgut\.venv\Lib\site-packages\django\db\models\base.py", line 924, in save_base
    post_save.send(
  File "A:\test\AnturajSurgut\.venv\Lib\site-packages\django\dispatch\dispatcher.py", line 189, in send
    response = receiver(signal=self, sender=sender, **named)
               ^^^^^^^^^^^^^^^^^^^^^^^^^^^^^^^^^^^^^^^^^^^^^
  File "A:\test\AnturajSurgut\backend\DB\Signals\Order\Notify\signal_order_create.py", line 28, in send_email_order
    send_order_confirmation_email.delay(instance.order_number)
  File "A:\test\AnturajSurgut\.venv\Lib\site-packages\celery\app\task.py", line 444, in delay
    return self.apply_async(args, kwargs)
           ^^^^^^^^^^^^^^^^^^^^^^^^^^^^^^
  File "A:\test\AnturajSurgut\.venv\Lib\site-packages\celery\app\task.py", line 594, in apply_async
    return app.send_task(
           ^^^^^^^^^^^^^^
  File "A:\test\AnturajSurgut\.venv\Lib\site-packages\celery\app\base.py", line 796, in send_task
    with P.connection._reraise_as_library_errors():
  File "C:\Program Files\Python312\Lib\contextlib.py", line 158, in __exit__
    self.gen.throw(value)
  File "A:\test\AnturajSurgut\.venv\Lib\site-packages\kombu\connection.py", line 476, in _reraise_as_library_errors
    raise ConnectionError(str(exc)) from exc
kombu.exceptions.OperationalError: Error 11001 connecting to redis:6379. getaddrinfo failed.
[03.04.2024 02:56:30 - ERROR] Internal Server Error: /api/docs/, PATH: A:\test\AnturajSurgut\.venv\Lib\site-packages\django\utils\log.py, line: 241
Traceback (most recent call last):
  File "A:\test\AnturajSurgut\.venv\Lib\site-packages\django\core\handlers\exception.py", line 55, in inner
    response = get_response(request)
               ^^^^^^^^^^^^^^^^^^^^^
  File "A:\test\AnturajSurgut\.venv\Lib\site-packages\django\core\handlers\base.py", line 220, in _get_response
    response = response.render()
               ^^^^^^^^^^^^^^^^^
  File "A:\test\AnturajSurgut\.venv\Lib\site-packages\django\template\response.py", line 114, in render
    self.content = self.rendered_content
                   ^^^^^^^^^^^^^^^^^^^^^
  File "A:\test\AnturajSurgut\.venv\Lib\site-packages\rest_framework\response.py", line 70, in rendered_content
    ret = renderer.render(self.data, accepted_media_type, context)
          ^^^^^^^^^^^^^^^^^^^^^^^^^^^^^^^^^^^^^^^^^^^^^^^^^^^^^^^^
  File "A:\test\AnturajSurgut\.venv\Lib\site-packages\drf_yasg\renderers.py", line 36, in render
    return codec.encode(data)
           ^^^^^^^^^^^^^^^^^^
  File "A:\test\AnturajSurgut\.venv\Lib\site-packages\drf_yasg\codecs.py", line 87, in encode
    return force_bytes(self._dump_dict(spec))
                       ^^^^^^^^^^^^^^^^^^^^^
  File "A:\test\AnturajSurgut\.venv\Lib\site-packages\drf_yasg\codecs.py", line 127, in _dump_dict
    return json.dumps(spec, ensure_ascii=False)
           ^^^^^^^^^^^^^^^^^^^^^^^^^^^^^^^^^^^^
  File "C:\Program Files\Python312\Lib\json\__init__.py", line 238, in dumps
    **kw).encode(obj)
          ^^^^^^^^^^^
  File "C:\Program Files\Python312\Lib\json\encoder.py", line 200, in encode
    chunks = self.iterencode(o, _one_shot=True)
             ^^^^^^^^^^^^^^^^^^^^^^^^^^^^^^^^^^
  File "C:\Program Files\Python312\Lib\json\encoder.py", line 258, in iterencode
    return _iterencode(o, 0)
           ^^^^^^^^^^^^^^^^^
  File "C:\Program Files\Python312\Lib\json\encoder.py", line 180, in default
    raise TypeError(f'Object of type {o.__class__.__name__} '
TypeError: Object of type ListSerializer is not JSON serializable
[03.04.2024 02:56:39 - ERROR] Internal Server Error: /api/docs/, PATH: A:\test\AnturajSurgut\.venv\Lib\site-packages\django\utils\log.py, line: 241
Traceback (most recent call last):
  File "A:\test\AnturajSurgut\.venv\Lib\site-packages\django\core\handlers\exception.py", line 55, in inner
    response = get_response(request)
               ^^^^^^^^^^^^^^^^^^^^^
  File "A:\test\AnturajSurgut\.venv\Lib\site-packages\django\core\handlers\base.py", line 220, in _get_response
    response = response.render()
               ^^^^^^^^^^^^^^^^^
  File "A:\test\AnturajSurgut\.venv\Lib\site-packages\django\template\response.py", line 114, in render
    self.content = self.rendered_content
                   ^^^^^^^^^^^^^^^^^^^^^
  File "A:\test\AnturajSurgut\.venv\Lib\site-packages\rest_framework\response.py", line 70, in rendered_content
    ret = renderer.render(self.data, accepted_media_type, context)
          ^^^^^^^^^^^^^^^^^^^^^^^^^^^^^^^^^^^^^^^^^^^^^^^^^^^^^^^^
  File "A:\test\AnturajSurgut\.venv\Lib\site-packages\drf_yasg\renderers.py", line 36, in render
    return codec.encode(data)
           ^^^^^^^^^^^^^^^^^^
  File "A:\test\AnturajSurgut\.venv\Lib\site-packages\drf_yasg\codecs.py", line 87, in encode
    return force_bytes(self._dump_dict(spec))
                       ^^^^^^^^^^^^^^^^^^^^^
  File "A:\test\AnturajSurgut\.venv\Lib\site-packages\drf_yasg\codecs.py", line 127, in _dump_dict
    return json.dumps(spec, ensure_ascii=False)
           ^^^^^^^^^^^^^^^^^^^^^^^^^^^^^^^^^^^^
  File "C:\Program Files\Python312\Lib\json\__init__.py", line 238, in dumps
    **kw).encode(obj)
          ^^^^^^^^^^^
  File "C:\Program Files\Python312\Lib\json\encoder.py", line 200, in encode
    chunks = self.iterencode(o, _one_shot=True)
             ^^^^^^^^^^^^^^^^^^^^^^^^^^^^^^^^^^
  File "C:\Program Files\Python312\Lib\json\encoder.py", line 258, in iterencode
    return _iterencode(o, 0)
           ^^^^^^^^^^^^^^^^^
  File "C:\Program Files\Python312\Lib\json\encoder.py", line 180, in default
    raise TypeError(f'Object of type {o.__class__.__name__} '
TypeError: Object of type ListSerializer is not JSON serializable
[03.04.2024 02:56:58 - ERROR] Internal Server Error: /api/docs/, PATH: A:\test\AnturajSurgut\.venv\Lib\site-packages\django\utils\log.py, line: 241
Traceback (most recent call last):
  File "A:\test\AnturajSurgut\.venv\Lib\site-packages\django\core\handlers\exception.py", line 55, in inner
    response = get_response(request)
               ^^^^^^^^^^^^^^^^^^^^^
  File "A:\test\AnturajSurgut\.venv\Lib\site-packages\django\core\handlers\base.py", line 220, in _get_response
    response = response.render()
               ^^^^^^^^^^^^^^^^^
  File "A:\test\AnturajSurgut\.venv\Lib\site-packages\django\template\response.py", line 114, in render
    self.content = self.rendered_content
                   ^^^^^^^^^^^^^^^^^^^^^
  File "A:\test\AnturajSurgut\.venv\Lib\site-packages\rest_framework\response.py", line 70, in rendered_content
    ret = renderer.render(self.data, accepted_media_type, context)
          ^^^^^^^^^^^^^^^^^^^^^^^^^^^^^^^^^^^^^^^^^^^^^^^^^^^^^^^^
  File "A:\test\AnturajSurgut\.venv\Lib\site-packages\drf_yasg\renderers.py", line 36, in render
    return codec.encode(data)
           ^^^^^^^^^^^^^^^^^^
  File "A:\test\AnturajSurgut\.venv\Lib\site-packages\drf_yasg\codecs.py", line 87, in encode
    return force_bytes(self._dump_dict(spec))
                       ^^^^^^^^^^^^^^^^^^^^^
  File "A:\test\AnturajSurgut\.venv\Lib\site-packages\drf_yasg\codecs.py", line 127, in _dump_dict
    return json.dumps(spec, ensure_ascii=False)
           ^^^^^^^^^^^^^^^^^^^^^^^^^^^^^^^^^^^^
  File "C:\Program Files\Python312\Lib\json\__init__.py", line 238, in dumps
    **kw).encode(obj)
          ^^^^^^^^^^^
  File "C:\Program Files\Python312\Lib\json\encoder.py", line 200, in encode
    chunks = self.iterencode(o, _one_shot=True)
             ^^^^^^^^^^^^^^^^^^^^^^^^^^^^^^^^^^
  File "C:\Program Files\Python312\Lib\json\encoder.py", line 258, in iterencode
    return _iterencode(o, 0)
           ^^^^^^^^^^^^^^^^^
  File "C:\Program Files\Python312\Lib\json\encoder.py", line 180, in default
    raise TypeError(f'Object of type {o.__class__.__name__} '
TypeError: Object of type ListSerializer is not JSON serializable
