[07.02.2024 15:08:20 - ERROR] Internal Server Error: /api/v1/product/products/, путь: A:\AnturajSurgut\backend\.venv\Lib\site-packages\django\utils\log.py, строка: 241
Traceback (most recent call last):
  File "A:\AnturajSurgut\backend\.venv\Lib\site-packages\rest_framework\fields.py", line 446, in get_attribute
    return get_attribute(instance, self.source_attrs)
           ^^^^^^^^^^^^^^^^^^^^^^^^^^^^^^^^^^^^^^^^^^
  File "A:\AnturajSurgut\backend\.venv\Lib\site-packages\rest_framework\fields.py", line 96, in get_attribute
    instance = getattr(instance, attr)
               ^^^^^^^^^^^^^^^^^^^^^^^
AttributeError: 'Product' object has no attribute 'catalog'

During handling of the above exception, another exception occurred:

Traceback (most recent call last):
  File "A:\AnturajSurgut\backend\.venv\Lib\site-packages\django\core\handlers\exception.py", line 55, in inner
    response = get_response(request)
               ^^^^^^^^^^^^^^^^^^^^^
  File "A:\AnturajSurgut\backend\.venv\Lib\site-packages\django\core\handlers\base.py", line 197, in _get_response
    response = wrapped_callback(request, *callback_args, **callback_kwargs)
               ^^^^^^^^^^^^^^^^^^^^^^^^^^^^^^^^^^^^^^^^^^^^^^^^^^^^^^^^^^^^
  File "A:\AnturajSurgut\backend\.venv\Lib\site-packages\django\views\decorators\csrf.py", line 65, in _view_wrapper
    return view_func(request, *args, **kwargs)
           ^^^^^^^^^^^^^^^^^^^^^^^^^^^^^^^^^^^
  File "A:\AnturajSurgut\backend\.venv\Lib\site-packages\rest_framework\viewsets.py", line 125, in view
    return self.dispatch(request, *args, **kwargs)
           ^^^^^^^^^^^^^^^^^^^^^^^^^^^^^^^^^^^^^^^
  File "A:\AnturajSurgut\backend\.venv\Lib\site-packages\rest_framework\views.py", line 509, in dispatch
    response = self.handle_exception(exc)
               ^^^^^^^^^^^^^^^^^^^^^^^^^^
  File "A:\AnturajSurgut\backend\.venv\Lib\site-packages\rest_framework\views.py", line 469, in handle_exception
    self.raise_uncaught_exception(exc)
  File "A:\AnturajSurgut\backend\.venv\Lib\site-packages\rest_framework\views.py", line 480, in raise_uncaught_exception
    raise exc
  File "A:\AnturajSurgut\backend\.venv\Lib\site-packages\rest_framework\views.py", line 506, in dispatch
    response = handler(request, *args, **kwargs)
               ^^^^^^^^^^^^^^^^^^^^^^^^^^^^^^^^^
  File "A:\AnturajSurgut\backend\.venv\Lib\site-packages\rest_framework\mixins.py", line 46, in list
    return Response(serializer.data)
                    ^^^^^^^^^^^^^^^
  File "A:\AnturajSurgut\backend\.venv\Lib\site-packages\rest_framework\serializers.py", line 768, in data
    ret = super().data
          ^^^^^^^^^^^^
  File "A:\AnturajSurgut\backend\.venv\Lib\site-packages\rest_framework\serializers.py", line 253, in data
    self._data = self.to_representation(self.instance)
                 ^^^^^^^^^^^^^^^^^^^^^^^^^^^^^^^^^^^^^
  File "A:\AnturajSurgut\backend\.venv\Lib\site-packages\rest_framework\serializers.py", line 686, in to_representation
    return [
           ^
  File "A:\AnturajSurgut\backend\.venv\Lib\site-packages\rest_framework\serializers.py", line 687, in <listcomp>
    self.child.to_representation(item) for item in iterable
    ^^^^^^^^^^^^^^^^^^^^^^^^^^^^^^^^^^
  File "A:\AnturajSurgut\backend\.venv\Lib\site-packages\rest_framework\serializers.py", line 509, in to_representation
    attribute = field.get_attribute(instance)
                ^^^^^^^^^^^^^^^^^^^^^^^^^^^^^
  File "A:\AnturajSurgut\backend\.venv\Lib\site-packages\rest_framework\fields.py", line 479, in get_attribute
    raise type(exc)(msg)
AttributeError: Got AttributeError when attempting to get a value for field `catalog` on serializer `ProductSerializer`.
The serializer field might be named incorrectly and not match any attribute or key on the `Product` instance.
Original exception text was: 'Product' object has no attribute 'catalog'.
[07.02.2024 15:08:30 - ERROR] Internal Server Error: /api/v1/product/products/, путь: A:\AnturajSurgut\backend\.venv\Lib\site-packages\django\utils\log.py, строка: 241
Traceback (most recent call last):
  File "A:\AnturajSurgut\backend\.venv\Lib\site-packages\rest_framework\fields.py", line 446, in get_attribute
    return get_attribute(instance, self.source_attrs)
           ^^^^^^^^^^^^^^^^^^^^^^^^^^^^^^^^^^^^^^^^^^
  File "A:\AnturajSurgut\backend\.venv\Lib\site-packages\rest_framework\fields.py", line 96, in get_attribute
    instance = getattr(instance, attr)
               ^^^^^^^^^^^^^^^^^^^^^^^
AttributeError: 'Product' object has no attribute 'catalog'

During handling of the above exception, another exception occurred:

Traceback (most recent call last):
  File "A:\AnturajSurgut\backend\.venv\Lib\site-packages\django\core\handlers\exception.py", line 55, in inner
    response = get_response(request)
               ^^^^^^^^^^^^^^^^^^^^^
  File "A:\AnturajSurgut\backend\.venv\Lib\site-packages\django\core\handlers\base.py", line 197, in _get_response
    response = wrapped_callback(request, *callback_args, **callback_kwargs)
               ^^^^^^^^^^^^^^^^^^^^^^^^^^^^^^^^^^^^^^^^^^^^^^^^^^^^^^^^^^^^
  File "A:\AnturajSurgut\backend\.venv\Lib\site-packages\django\views\decorators\csrf.py", line 65, in _view_wrapper
    return view_func(request, *args, **kwargs)
           ^^^^^^^^^^^^^^^^^^^^^^^^^^^^^^^^^^^
  File "A:\AnturajSurgut\backend\.venv\Lib\site-packages\rest_framework\viewsets.py", line 125, in view
    return self.dispatch(request, *args, **kwargs)
           ^^^^^^^^^^^^^^^^^^^^^^^^^^^^^^^^^^^^^^^
  File "A:\AnturajSurgut\backend\.venv\Lib\site-packages\rest_framework\views.py", line 509, in dispatch
    response = self.handle_exception(exc)
               ^^^^^^^^^^^^^^^^^^^^^^^^^^
  File "A:\AnturajSurgut\backend\.venv\Lib\site-packages\rest_framework\views.py", line 469, in handle_exception
    self.raise_uncaught_exception(exc)
  File "A:\AnturajSurgut\backend\.venv\Lib\site-packages\rest_framework\views.py", line 480, in raise_uncaught_exception
    raise exc
  File "A:\AnturajSurgut\backend\.venv\Lib\site-packages\rest_framework\views.py", line 506, in dispatch
    response = handler(request, *args, **kwargs)
               ^^^^^^^^^^^^^^^^^^^^^^^^^^^^^^^^^
  File "A:\AnturajSurgut\backend\.venv\Lib\site-packages\rest_framework\mixins.py", line 46, in list
    return Response(serializer.data)
                    ^^^^^^^^^^^^^^^
  File "A:\AnturajSurgut\backend\.venv\Lib\site-packages\rest_framework\serializers.py", line 768, in data
    ret = super().data
          ^^^^^^^^^^^^
  File "A:\AnturajSurgut\backend\.venv\Lib\site-packages\rest_framework\serializers.py", line 253, in data
    self._data = self.to_representation(self.instance)
                 ^^^^^^^^^^^^^^^^^^^^^^^^^^^^^^^^^^^^^
  File "A:\AnturajSurgut\backend\.venv\Lib\site-packages\rest_framework\serializers.py", line 686, in to_representation
    return [
           ^
  File "A:\AnturajSurgut\backend\.venv\Lib\site-packages\rest_framework\serializers.py", line 687, in <listcomp>
    self.child.to_representation(item) for item in iterable
    ^^^^^^^^^^^^^^^^^^^^^^^^^^^^^^^^^^
  File "A:\AnturajSurgut\backend\.venv\Lib\site-packages\rest_framework\serializers.py", line 509, in to_representation
    attribute = field.get_attribute(instance)
                ^^^^^^^^^^^^^^^^^^^^^^^^^^^^^
  File "A:\AnturajSurgut\backend\.venv\Lib\site-packages\rest_framework\fields.py", line 479, in get_attribute
    raise type(exc)(msg)
AttributeError: Got AttributeError when attempting to get a value for field `catalog` on serializer `ProductSerializer`.
The serializer field might be named incorrectly and not match any attribute or key on the `Product` instance.
Original exception text was: 'Product' object has no attribute 'catalog'.
[07.02.2024 15:08:33 - ERROR] Internal Server Error: /api/v1/product/products/, путь: A:\AnturajSurgut\backend\.venv\Lib\site-packages\django\utils\log.py, строка: 241
Traceback (most recent call last):
  File "A:\AnturajSurgut\backend\.venv\Lib\site-packages\rest_framework\fields.py", line 446, in get_attribute
    return get_attribute(instance, self.source_attrs)
           ^^^^^^^^^^^^^^^^^^^^^^^^^^^^^^^^^^^^^^^^^^
  File "A:\AnturajSurgut\backend\.venv\Lib\site-packages\rest_framework\fields.py", line 96, in get_attribute
    instance = getattr(instance, attr)
               ^^^^^^^^^^^^^^^^^^^^^^^
AttributeError: 'Product' object has no attribute 'catalog'

During handling of the above exception, another exception occurred:

Traceback (most recent call last):
  File "A:\AnturajSurgut\backend\.venv\Lib\site-packages\django\core\handlers\exception.py", line 55, in inner
    response = get_response(request)
               ^^^^^^^^^^^^^^^^^^^^^
  File "A:\AnturajSurgut\backend\.venv\Lib\site-packages\django\core\handlers\base.py", line 197, in _get_response
    response = wrapped_callback(request, *callback_args, **callback_kwargs)
               ^^^^^^^^^^^^^^^^^^^^^^^^^^^^^^^^^^^^^^^^^^^^^^^^^^^^^^^^^^^^
  File "A:\AnturajSurgut\backend\.venv\Lib\site-packages\django\views\decorators\csrf.py", line 65, in _view_wrapper
    return view_func(request, *args, **kwargs)
           ^^^^^^^^^^^^^^^^^^^^^^^^^^^^^^^^^^^
  File "A:\AnturajSurgut\backend\.venv\Lib\site-packages\rest_framework\viewsets.py", line 125, in view
    return self.dispatch(request, *args, **kwargs)
           ^^^^^^^^^^^^^^^^^^^^^^^^^^^^^^^^^^^^^^^
  File "A:\AnturajSurgut\backend\.venv\Lib\site-packages\rest_framework\views.py", line 509, in dispatch
    response = self.handle_exception(exc)
               ^^^^^^^^^^^^^^^^^^^^^^^^^^
  File "A:\AnturajSurgut\backend\.venv\Lib\site-packages\rest_framework\views.py", line 469, in handle_exception
    self.raise_uncaught_exception(exc)
  File "A:\AnturajSurgut\backend\.venv\Lib\site-packages\rest_framework\views.py", line 480, in raise_uncaught_exception
    raise exc
  File "A:\AnturajSurgut\backend\.venv\Lib\site-packages\rest_framework\views.py", line 506, in dispatch
    response = handler(request, *args, **kwargs)
               ^^^^^^^^^^^^^^^^^^^^^^^^^^^^^^^^^
  File "A:\AnturajSurgut\backend\.venv\Lib\site-packages\rest_framework\mixins.py", line 46, in list
    return Response(serializer.data)
                    ^^^^^^^^^^^^^^^
  File "A:\AnturajSurgut\backend\.venv\Lib\site-packages\rest_framework\serializers.py", line 768, in data
    ret = super().data
          ^^^^^^^^^^^^
  File "A:\AnturajSurgut\backend\.venv\Lib\site-packages\rest_framework\serializers.py", line 253, in data
    self._data = self.to_representation(self.instance)
                 ^^^^^^^^^^^^^^^^^^^^^^^^^^^^^^^^^^^^^
  File "A:\AnturajSurgut\backend\.venv\Lib\site-packages\rest_framework\serializers.py", line 686, in to_representation
    return [
           ^
  File "A:\AnturajSurgut\backend\.venv\Lib\site-packages\rest_framework\serializers.py", line 687, in <listcomp>
    self.child.to_representation(item) for item in iterable
    ^^^^^^^^^^^^^^^^^^^^^^^^^^^^^^^^^^
  File "A:\AnturajSurgut\backend\.venv\Lib\site-packages\rest_framework\serializers.py", line 509, in to_representation
    attribute = field.get_attribute(instance)
                ^^^^^^^^^^^^^^^^^^^^^^^^^^^^^
  File "A:\AnturajSurgut\backend\.venv\Lib\site-packages\rest_framework\fields.py", line 479, in get_attribute
    raise type(exc)(msg)
AttributeError: Got AttributeError when attempting to get a value for field `catalog` on serializer `ProductSerializer`.
The serializer field might be named incorrectly and not match any attribute or key on the `Product` instance.
Original exception text was: 'Product' object has no attribute 'catalog'.
[09.02.2024 17:25:38 - ERROR] Internal Server Error: /admin/database/favorite/add/, путь: A:\AnturajSurgut\.venv\Lib\site-packages\django\utils\log.py, строка: 241
Traceback (most recent call last):
  File "A:\AnturajSurgut\.venv\Lib\site-packages\django\core\handlers\exception.py", line 55, in inner
    response = get_response(request)
               ^^^^^^^^^^^^^^^^^^^^^
  File "A:\AnturajSurgut\.venv\Lib\site-packages\django\core\handlers\base.py", line 197, in _get_response
    response = wrapped_callback(request, *callback_args, **callback_kwargs)
               ^^^^^^^^^^^^^^^^^^^^^^^^^^^^^^^^^^^^^^^^^^^^^^^^^^^^^^^^^^^^
  File "A:\AnturajSurgut\.venv\Lib\site-packages\django\contrib\admin\options.py", line 714, in wrapper
    return self.admin_site.admin_view(view)(*args, **kwargs)
           ^^^^^^^^^^^^^^^^^^^^^^^^^^^^^^^^^^^^^^^^^^^^^^^^^
  File "A:\AnturajSurgut\.venv\Lib\site-packages\django\utils\decorators.py", line 188, in _view_wrapper
    result = _process_exception(request, e)
             ^^^^^^^^^^^^^^^^^^^^^^^^^^^^^^
  File "A:\AnturajSurgut\.venv\Lib\site-packages\django\utils\decorators.py", line 186, in _view_wrapper
    response = view_func(request, *args, **kwargs)
               ^^^^^^^^^^^^^^^^^^^^^^^^^^^^^^^^^^^
  File "A:\AnturajSurgut\.venv\Lib\site-packages\django\views\decorators\cache.py", line 80, in _view_wrapper
    response = view_func(request, *args, **kwargs)
               ^^^^^^^^^^^^^^^^^^^^^^^^^^^^^^^^^^^
  File "A:\AnturajSurgut\.venv\Lib\site-packages\django\contrib\admin\sites.py", line 240, in inner
    return view(request, *args, **kwargs)
           ^^^^^^^^^^^^^^^^^^^^^^^^^^^^^^
  File "A:\AnturajSurgut\.venv\Lib\site-packages\django\contrib\admin\options.py", line 1941, in add_view
    return self.changeform_view(request, None, form_url, extra_context)
           ^^^^^^^^^^^^^^^^^^^^^^^^^^^^^^^^^^^^^^^^^^^^^^^^^^^^^^^^^^^^
  File "A:\AnturajSurgut\.venv\Lib\site-packages\django\utils\decorators.py", line 48, in _wrapper
    return bound_method(*args, **kwargs)
           ^^^^^^^^^^^^^^^^^^^^^^^^^^^^^
  File "A:\AnturajSurgut\.venv\Lib\site-packages\django\utils\decorators.py", line 188, in _view_wrapper
    result = _process_exception(request, e)
             ^^^^^^^^^^^^^^^^^^^^^^^^^^^^^^
  File "A:\AnturajSurgut\.venv\Lib\site-packages\django\utils\decorators.py", line 186, in _view_wrapper
    response = view_func(request, *args, **kwargs)
               ^^^^^^^^^^^^^^^^^^^^^^^^^^^^^^^^^^^
  File "A:\AnturajSurgut\.venv\Lib\site-packages\django\contrib\admin\options.py", line 1802, in changeform_view
    return self._changeform_view(request, object_id, form_url, extra_context)
           ^^^^^^^^^^^^^^^^^^^^^^^^^^^^^^^^^^^^^^^^^^^^^^^^^^^^^^^^^^^^^^^^^^
  File "A:\AnturajSurgut\.venv\Lib\site-packages\django\contrib\admin\options.py", line 1859, in _changeform_view
    self.log_addition(request, new_object, change_message)
  File "A:\AnturajSurgut\.venv\Lib\site-packages\django\contrib\admin\options.py", line 952, in log_addition
    object_repr=str(obj),
                ^^^^^^^^
TypeError: __str__ returned non-string (type CustomUser)
[09.02.2024 17:45:53 - ERROR] Internal Server Error: /api/profile/favorite/, путь: A:\AnturajSurgut\.venv\Lib\site-packages\django\utils\log.py, строка: 241
Traceback (most recent call last):
  File "A:\AnturajSurgut\.venv\Lib\site-packages\django\db\utils.py", line 98, in inner
    return func(*args, **kwargs)
           ^^^^^^^^^^^^^^^^^^^^^
sqlite3.IntegrityError: FOREIGN KEY constraint failed

The above exception was the direct cause of the following exception:

Traceback (most recent call last):
  File "A:\AnturajSurgut\backend\profiles\views.py", line 38, in add_to_favorite
    favorite = Favorite.objects.create(user=user, product_id=product_id)
               ^^^^^^^^^^^^^^^^^^^^^^^^^^^^^^^^^^^^^^^^^^^^^^^^^^^^^^^^^
  File "A:\AnturajSurgut\.venv\Lib\site-packages\django\db\models\manager.py", line 87, in manager_method
    return getattr(self.get_queryset(), name)(*args, **kwargs)
           ^^^^^^^^^^^^^^^^^^^^^^^^^^^^^^^^^^^^^^^^^^^^^^^^^^^
  File "A:\AnturajSurgut\.venv\Lib\site-packages\django\db\models\query.py", line 677, in create
    obj.save(force_insert=True, using=self.db)
  File "A:\AnturajSurgut\.venv\Lib\site-packages\django\db\models\base.py", line 822, in save
    self.save_base(
  File "A:\AnturajSurgut\.venv\Lib\site-packages\django\db\models\base.py", line 909, in save_base
    updated = self._save_table(
              ^^^^^^^^^^^^^^^^^
  File "A:\AnturajSurgut\.venv\Lib\site-packages\django\db\models\base.py", line 1067, in _save_table
    results = self._do_insert(
              ^^^^^^^^^^^^^^^^
  File "A:\AnturajSurgut\.venv\Lib\site-packages\django\db\models\base.py", line 1108, in _do_insert
    return manager._insert(
           ^^^^^^^^^^^^^^^^
  File "A:\AnturajSurgut\.venv\Lib\site-packages\django\db\models\manager.py", line 87, in manager_method
    return getattr(self.get_queryset(), name)(*args, **kwargs)
           ^^^^^^^^^^^^^^^^^^^^^^^^^^^^^^^^^^^^^^^^^^^^^^^^^^^
  File "A:\AnturajSurgut\.venv\Lib\site-packages\django\db\models\query.py", line 1845, in _insert
    return query.get_compiler(using=using).execute_sql(returning_fields)
           ^^^^^^^^^^^^^^^^^^^^^^^^^^^^^^^^^^^^^^^^^^^^^^^^^^^^^^^^^^^^^
  File "A:\AnturajSurgut\.venv\Lib\site-packages\django\db\models\sql\compiler.py", line 1835, in execute_sql
    self.connection.ops.fetch_returned_insert_columns(
  File "A:\AnturajSurgut\.venv\Lib\site-packages\django\db\backends\base\operations.py", line 216, in fetch_returned_insert_columns
    return cursor.fetchone()
           ^^^^^^^^^^^^^^^^^
  File "A:\AnturajSurgut\.venv\Lib\site-packages\django\db\utils.py", line 97, in inner
    with self:
  File "A:\AnturajSurgut\.venv\Lib\site-packages\django\db\utils.py", line 91, in __exit__
    raise dj_exc_value.with_traceback(traceback) from exc_value
  File "A:\AnturajSurgut\.venv\Lib\site-packages\django\db\utils.py", line 98, in inner
    return func(*args, **kwargs)
           ^^^^^^^^^^^^^^^^^^^^^
django.db.utils.IntegrityError: FOREIGN KEY constraint failed

During handling of the above exception, another exception occurred:

Traceback (most recent call last):
  File "A:\AnturajSurgut\.venv\Lib\site-packages\django\core\handlers\exception.py", line 55, in inner
    response = get_response(request)
               ^^^^^^^^^^^^^^^^^^^^^
  File "A:\AnturajSurgut\.venv\Lib\site-packages\django\core\handlers\base.py", line 197, in _get_response
    response = wrapped_callback(request, *callback_args, **callback_kwargs)
               ^^^^^^^^^^^^^^^^^^^^^^^^^^^^^^^^^^^^^^^^^^^^^^^^^^^^^^^^^^^^
  File "A:\AnturajSurgut\.venv\Lib\site-packages\django\views\decorators\csrf.py", line 65, in _view_wrapper
    return view_func(request, *args, **kwargs)
           ^^^^^^^^^^^^^^^^^^^^^^^^^^^^^^^^^^^
  File "A:\AnturajSurgut\.venv\Lib\site-packages\django\views\generic\base.py", line 104, in view
    return self.dispatch(request, *args, **kwargs)
           ^^^^^^^^^^^^^^^^^^^^^^^^^^^^^^^^^^^^^^^
  File "A:\AnturajSurgut\.venv\Lib\site-packages\rest_framework\views.py", line 509, in dispatch
    response = self.handle_exception(exc)
               ^^^^^^^^^^^^^^^^^^^^^^^^^^
  File "A:\AnturajSurgut\.venv\Lib\site-packages\rest_framework\views.py", line 469, in handle_exception
    self.raise_uncaught_exception(exc)
  File "A:\AnturajSurgut\.venv\Lib\site-packages\rest_framework\views.py", line 480, in raise_uncaught_exception
    raise exc
  File "A:\AnturajSurgut\.venv\Lib\site-packages\rest_framework\views.py", line 506, in dispatch
    response = handler(request, *args, **kwargs)
               ^^^^^^^^^^^^^^^^^^^^^^^^^^^^^^^^^
  File "A:\AnturajSurgut\.venv\Lib\site-packages\rest_framework\decorators.py", line 50, in handler
    return func(*args, **kwargs)
           ^^^^^^^^^^^^^^^^^^^^^
  File "A:\AnturajSurgut\backend\profiles\views.py", line 41, in add_to_favorite
    except FOREIGN_KEY_ERROR:
           ^^^^^^^^^^^^^^^^^
NameError: name 'FOREIGN_KEY_ERROR' is not defined
[09.02.2024 17:46:18 - ERROR] Internal Server Error: /api/profile/favorite/, путь: A:\AnturajSurgut\.venv\Lib\site-packages\django\utils\log.py, строка: 241
Traceback (most recent call last):
  File "A:\AnturajSurgut\.venv\Lib\site-packages\django\db\utils.py", line 98, in inner
    return func(*args, **kwargs)
           ^^^^^^^^^^^^^^^^^^^^^
sqlite3.IntegrityError: FOREIGN KEY constraint failed

The above exception was the direct cause of the following exception:

Traceback (most recent call last):
  File "A:\AnturajSurgut\.venv\Lib\site-packages\django\core\handlers\exception.py", line 55, in inner
    response = get_response(request)
               ^^^^^^^^^^^^^^^^^^^^^
  File "A:\AnturajSurgut\.venv\Lib\site-packages\django\core\handlers\base.py", line 197, in _get_response
    response = wrapped_callback(request, *callback_args, **callback_kwargs)
               ^^^^^^^^^^^^^^^^^^^^^^^^^^^^^^^^^^^^^^^^^^^^^^^^^^^^^^^^^^^^
  File "A:\AnturajSurgut\.venv\Lib\site-packages\django\views\decorators\csrf.py", line 65, in _view_wrapper
    return view_func(request, *args, **kwargs)
           ^^^^^^^^^^^^^^^^^^^^^^^^^^^^^^^^^^^
  File "A:\AnturajSurgut\.venv\Lib\site-packages\django\views\generic\base.py", line 104, in view
    return self.dispatch(request, *args, **kwargs)
           ^^^^^^^^^^^^^^^^^^^^^^^^^^^^^^^^^^^^^^^
  File "A:\AnturajSurgut\.venv\Lib\site-packages\rest_framework\views.py", line 509, in dispatch
    response = self.handle_exception(exc)
               ^^^^^^^^^^^^^^^^^^^^^^^^^^
  File "A:\AnturajSurgut\.venv\Lib\site-packages\rest_framework\views.py", line 469, in handle_exception
    self.raise_uncaught_exception(exc)
  File "A:\AnturajSurgut\.venv\Lib\site-packages\rest_framework\views.py", line 480, in raise_uncaught_exception
    raise exc
  File "A:\AnturajSurgut\.venv\Lib\site-packages\rest_framework\views.py", line 506, in dispatch
    response = handler(request, *args, **kwargs)
               ^^^^^^^^^^^^^^^^^^^^^^^^^^^^^^^^^
  File "A:\AnturajSurgut\.venv\Lib\site-packages\rest_framework\decorators.py", line 50, in handler
    return func(*args, **kwargs)
           ^^^^^^^^^^^^^^^^^^^^^
  File "A:\AnturajSurgut\backend\profiles\views.py", line 37, in add_to_favorite
    favorite = Favorite.objects.create(user=user, product_id=product_id)
               ^^^^^^^^^^^^^^^^^^^^^^^^^^^^^^^^^^^^^^^^^^^^^^^^^^^^^^^^^
  File "A:\AnturajSurgut\.venv\Lib\site-packages\django\db\models\manager.py", line 87, in manager_method
    return getattr(self.get_queryset(), name)(*args, **kwargs)
           ^^^^^^^^^^^^^^^^^^^^^^^^^^^^^^^^^^^^^^^^^^^^^^^^^^^
  File "A:\AnturajSurgut\.venv\Lib\site-packages\django\db\models\query.py", line 677, in create
    obj.save(force_insert=True, using=self.db)
  File "A:\AnturajSurgut\.venv\Lib\site-packages\django\db\models\base.py", line 822, in save
    self.save_base(
  File "A:\AnturajSurgut\.venv\Lib\site-packages\django\db\models\base.py", line 909, in save_base
    updated = self._save_table(
              ^^^^^^^^^^^^^^^^^
  File "A:\AnturajSurgut\.venv\Lib\site-packages\django\db\models\base.py", line 1067, in _save_table
    results = self._do_insert(
              ^^^^^^^^^^^^^^^^
  File "A:\AnturajSurgut\.venv\Lib\site-packages\django\db\models\base.py", line 1108, in _do_insert
    return manager._insert(
           ^^^^^^^^^^^^^^^^
  File "A:\AnturajSurgut\.venv\Lib\site-packages\django\db\models\manager.py", line 87, in manager_method
    return getattr(self.get_queryset(), name)(*args, **kwargs)
           ^^^^^^^^^^^^^^^^^^^^^^^^^^^^^^^^^^^^^^^^^^^^^^^^^^^
  File "A:\AnturajSurgut\.venv\Lib\site-packages\django\db\models\query.py", line 1845, in _insert
    return query.get_compiler(using=using).execute_sql(returning_fields)
           ^^^^^^^^^^^^^^^^^^^^^^^^^^^^^^^^^^^^^^^^^^^^^^^^^^^^^^^^^^^^^
  File "A:\AnturajSurgut\.venv\Lib\site-packages\django\db\models\sql\compiler.py", line 1835, in execute_sql
    self.connection.ops.fetch_returned_insert_columns(
  File "A:\AnturajSurgut\.venv\Lib\site-packages\django\db\backends\base\operations.py", line 216, in fetch_returned_insert_columns
    return cursor.fetchone()
           ^^^^^^^^^^^^^^^^^
  File "A:\AnturajSurgut\.venv\Lib\site-packages\django\db\utils.py", line 97, in inner
    with self:
  File "A:\AnturajSurgut\.venv\Lib\site-packages\django\db\utils.py", line 91, in __exit__
    raise dj_exc_value.with_traceback(traceback) from exc_value
  File "A:\AnturajSurgut\.venv\Lib\site-packages\django\db\utils.py", line 98, in inner
    return func(*args, **kwargs)
           ^^^^^^^^^^^^^^^^^^^^^
django.db.utils.IntegrityError: FOREIGN KEY constraint failed
[10.02.2024 16:15:52 - ERROR] Internal Server Error: /api/auth/test/, путь: A:\AnturajSurgut\.venv\Lib\site-packages\django\utils\log.py, строка: 241
Traceback (most recent call last):
  File "A:\AnturajSurgut\.venv\Lib\site-packages\django\core\handlers\exception.py", line 55, in inner
    response = get_response(request)
               ^^^^^^^^^^^^^^^^^^^^^
  File "A:\AnturajSurgut\.venv\Lib\site-packages\allauth\account\middleware.py", line 29, in middleware
    _remove_dangling_login(request, response)
  File "A:\AnturajSurgut\.venv\Lib\site-packages\allauth\account\middleware.py", line 38, in _remove_dangling_login
    content_type = response.headers.get("content-type")
                   ^^^^^^^^^^^^^^^^
AttributeError: 'function' object has no attribute 'headers'
[13.02.2024 14:00:42 - ERROR] Internal Server Error: /api/profile/info/, путь: A:\Project\AnturajSurgut\.venv\Lib\site-packages\django\utils\log.py, строка: 241
Traceback (most recent call last):
  File "A:\Project\AnturajSurgut\.venv\Lib\site-packages\django\core\handlers\exception.py", line 55, in inner
    response = get_response(request)
               ^^^^^^^^^^^^^^^^^^^^^
  File "A:\Project\AnturajSurgut\.venv\Lib\site-packages\django\core\handlers\base.py", line 220, in _get_response
    response = response.render()
               ^^^^^^^^^^^^^^^^^
  File "A:\Project\AnturajSurgut\.venv\Lib\site-packages\django\template\response.py", line 114, in render
    self.content = self.rendered_content
                   ^^^^^^^^^^^^^^^^^^^^^
  File "A:\Project\AnturajSurgut\.venv\Lib\site-packages\rest_framework\response.py", line 70, in rendered_content
    ret = renderer.render(self.data, accepted_media_type, context)
          ^^^^^^^^^^^^^^^^^^^^^^^^^^^^^^^^^^^^^^^^^^^^^^^^^^^^^^^^
  File "A:\Project\AnturajSurgut\.venv\Lib\site-packages\rest_framework\renderers.py", line 99, in render
    ret = json.dumps(
          ^^^^^^^^^^^
  File "A:\Project\AnturajSurgut\.venv\Lib\site-packages\rest_framework\utils\json.py", line 25, in dumps
    return json.dumps(*args, **kwargs)
           ^^^^^^^^^^^^^^^^^^^^^^^^^^^
  File "C:\Program Files\WindowsApps\PythonSoftwareFoundation.Python.3.11_3.11.2288.0_x64__qbz5n2kfra8p0\Lib\json\__init__.py", line 238, in dumps
    **kw).encode(obj)
          ^^^^^^^^^^^
  File "C:\Program Files\WindowsApps\PythonSoftwareFoundation.Python.3.11_3.11.2288.0_x64__qbz5n2kfra8p0\Lib\json\encoder.py", line 200, in encode
    chunks = self.iterencode(o, _one_shot=True)
             ^^^^^^^^^^^^^^^^^^^^^^^^^^^^^^^^^^
  File "C:\Program Files\WindowsApps\PythonSoftwareFoundation.Python.3.11_3.11.2288.0_x64__qbz5n2kfra8p0\Lib\json\encoder.py", line 258, in iterencode
    return _iterencode(o, 0)
           ^^^^^^^^^^^^^^^^^
  File "A:\Project\AnturajSurgut\.venv\Lib\site-packages\rest_framework\utils\encoders.py", line 67, in default
    return super().default(obj)
           ^^^^^^^^^^^^^^^^^^^^
  File "C:\Program Files\WindowsApps\PythonSoftwareFoundation.Python.3.11_3.11.2288.0_x64__qbz5n2kfra8p0\Lib\json\encoder.py", line 180, in default
    raise TypeError(f'Object of type {o.__class__.__name__} '
TypeError: Object of type Favorite is not JSON serializable
[13.02.2024 14:00:43 - ERROR] Internal Server Error: /api/profile/info/, путь: A:\Project\AnturajSurgut\.venv\Lib\site-packages\django\utils\log.py, строка: 241
Traceback (most recent call last):
  File "A:\Project\AnturajSurgut\.venv\Lib\site-packages\django\core\handlers\exception.py", line 55, in inner
    response = get_response(request)
               ^^^^^^^^^^^^^^^^^^^^^
  File "A:\Project\AnturajSurgut\.venv\Lib\site-packages\django\core\handlers\base.py", line 220, in _get_response
    response = response.render()
               ^^^^^^^^^^^^^^^^^
  File "A:\Project\AnturajSurgut\.venv\Lib\site-packages\django\template\response.py", line 114, in render
    self.content = self.rendered_content
                   ^^^^^^^^^^^^^^^^^^^^^
  File "A:\Project\AnturajSurgut\.venv\Lib\site-packages\rest_framework\response.py", line 70, in rendered_content
    ret = renderer.render(self.data, accepted_media_type, context)
          ^^^^^^^^^^^^^^^^^^^^^^^^^^^^^^^^^^^^^^^^^^^^^^^^^^^^^^^^
  File "A:\Project\AnturajSurgut\.venv\Lib\site-packages\rest_framework\renderers.py", line 99, in render
    ret = json.dumps(
          ^^^^^^^^^^^
  File "A:\Project\AnturajSurgut\.venv\Lib\site-packages\rest_framework\utils\json.py", line 25, in dumps
    return json.dumps(*args, **kwargs)
           ^^^^^^^^^^^^^^^^^^^^^^^^^^^
  File "C:\Program Files\WindowsApps\PythonSoftwareFoundation.Python.3.11_3.11.2288.0_x64__qbz5n2kfra8p0\Lib\json\__init__.py", line 238, in dumps
    **kw).encode(obj)
          ^^^^^^^^^^^
  File "C:\Program Files\WindowsApps\PythonSoftwareFoundation.Python.3.11_3.11.2288.0_x64__qbz5n2kfra8p0\Lib\json\encoder.py", line 200, in encode
    chunks = self.iterencode(o, _one_shot=True)
             ^^^^^^^^^^^^^^^^^^^^^^^^^^^^^^^^^^
  File "C:\Program Files\WindowsApps\PythonSoftwareFoundation.Python.3.11_3.11.2288.0_x64__qbz5n2kfra8p0\Lib\json\encoder.py", line 258, in iterencode
    return _iterencode(o, 0)
           ^^^^^^^^^^^^^^^^^
  File "A:\Project\AnturajSurgut\.venv\Lib\site-packages\rest_framework\utils\encoders.py", line 67, in default
    return super().default(obj)
           ^^^^^^^^^^^^^^^^^^^^
  File "C:\Program Files\WindowsApps\PythonSoftwareFoundation.Python.3.11_3.11.2288.0_x64__qbz5n2kfra8p0\Lib\json\encoder.py", line 180, in default
    raise TypeError(f'Object of type {o.__class__.__name__} '
TypeError: Object of type Favorite is not JSON serializable
[13.02.2024 16:49:37 - ERROR] Internal Server Error: /admin/database/cart/, путь: A:\Project\AnturajSurgut\.venv\Lib\site-packages\django\utils\log.py, строка: 241
Traceback (most recent call last):
  File "A:\Project\AnturajSurgut\.venv\Lib\site-packages\django\db\backends\utils.py", line 105, in _execute
    return self.cursor.execute(sql, params)
           ^^^^^^^^^^^^^^^^^^^^^^^^^^^^^^^^
  File "A:\Project\AnturajSurgut\.venv\Lib\site-packages\django\db\backends\sqlite3\base.py", line 328, in execute
    return super().execute(query, params)
           ^^^^^^^^^^^^^^^^^^^^^^^^^^^^^^
sqlite3.OperationalError: no such column: database_cart.price

The above exception was the direct cause of the following exception:

Traceback (most recent call last):
  File "A:\Project\AnturajSurgut\.venv\Lib\site-packages\django\core\handlers\exception.py", line 55, in inner
    response = get_response(request)
               ^^^^^^^^^^^^^^^^^^^^^
  File "A:\Project\AnturajSurgut\.venv\Lib\site-packages\django\core\handlers\base.py", line 197, in _get_response
    response = wrapped_callback(request, *callback_args, **callback_kwargs)
               ^^^^^^^^^^^^^^^^^^^^^^^^^^^^^^^^^^^^^^^^^^^^^^^^^^^^^^^^^^^^
  File "A:\Project\AnturajSurgut\.venv\Lib\site-packages\django\contrib\admin\options.py", line 714, in wrapper
    return self.admin_site.admin_view(view)(*args, **kwargs)
           ^^^^^^^^^^^^^^^^^^^^^^^^^^^^^^^^^^^^^^^^^^^^^^^^^
  File "A:\Project\AnturajSurgut\.venv\Lib\site-packages\django\utils\decorators.py", line 188, in _view_wrapper
    result = _process_exception(request, e)
             ^^^^^^^^^^^^^^^^^^^^^^^^^^^^^^
  File "A:\Project\AnturajSurgut\.venv\Lib\site-packages\django\utils\decorators.py", line 186, in _view_wrapper
    response = view_func(request, *args, **kwargs)
               ^^^^^^^^^^^^^^^^^^^^^^^^^^^^^^^^^^^
  File "A:\Project\AnturajSurgut\.venv\Lib\site-packages\django\views\decorators\cache.py", line 80, in _view_wrapper
    response = view_func(request, *args, **kwargs)
               ^^^^^^^^^^^^^^^^^^^^^^^^^^^^^^^^^^^
  File "A:\Project\AnturajSurgut\.venv\Lib\site-packages\django\contrib\admin\sites.py", line 240, in inner
    return view(request, *args, **kwargs)
           ^^^^^^^^^^^^^^^^^^^^^^^^^^^^^^
  File "A:\Project\AnturajSurgut\.venv\Lib\site-packages\django\utils\decorators.py", line 48, in _wrapper
    return bound_method(*args, **kwargs)
           ^^^^^^^^^^^^^^^^^^^^^^^^^^^^^
  File "A:\Project\AnturajSurgut\.venv\Lib\site-packages\django\utils\decorators.py", line 188, in _view_wrapper
    result = _process_exception(request, e)
             ^^^^^^^^^^^^^^^^^^^^^^^^^^^^^^
  File "A:\Project\AnturajSurgut\.venv\Lib\site-packages\django\utils\decorators.py", line 186, in _view_wrapper
    response = view_func(request, *args, **kwargs)
               ^^^^^^^^^^^^^^^^^^^^^^^^^^^^^^^^^^^
  File "A:\Project\AnturajSurgut\.venv\Lib\site-packages\django\contrib\admin\options.py", line 2120, in changelist_view
    "selection_note": _("0 of %(cnt)s selected") % {"cnt": len(cl.result_list)},
                                                           ^^^^^^^^^^^^^^^^^^^
  File "A:\Project\AnturajSurgut\.venv\Lib\site-packages\django\db\models\query.py", line 380, in __len__
    self._fetch_all()
  File "A:\Project\AnturajSurgut\.venv\Lib\site-packages\django\db\models\query.py", line 1926, in _fetch_all
    self._result_cache = list(self._iterable_class(self))
                         ^^^^^^^^^^^^^^^^^^^^^^^^^^^^^^^^
  File "A:\Project\AnturajSurgut\.venv\Lib\site-packages\django\db\models\query.py", line 91, in __iter__
    results = compiler.execute_sql(
              ^^^^^^^^^^^^^^^^^^^^^
  File "A:\Project\AnturajSurgut\.venv\Lib\site-packages\django\db\models\sql\compiler.py", line 1562, in execute_sql
    cursor.execute(sql, params)
  File "A:\Project\AnturajSurgut\.venv\Lib\site-packages\django\db\backends\utils.py", line 122, in execute
    return super().execute(sql, params)
           ^^^^^^^^^^^^^^^^^^^^^^^^^^^^
  File "A:\Project\AnturajSurgut\.venv\Lib\site-packages\django\db\backends\utils.py", line 79, in execute
    return self._execute_with_wrappers(
           ^^^^^^^^^^^^^^^^^^^^^^^^^^^^
  File "A:\Project\AnturajSurgut\.venv\Lib\site-packages\django\db\backends\utils.py", line 92, in _execute_with_wrappers
    return executor(sql, params, many, context)
           ^^^^^^^^^^^^^^^^^^^^^^^^^^^^^^^^^^^^
  File "A:\Project\AnturajSurgut\.venv\Lib\site-packages\django\db\backends\utils.py", line 100, in _execute
    with self.db.wrap_database_errors:
  File "A:\Project\AnturajSurgut\.venv\Lib\site-packages\django\db\utils.py", line 91, in __exit__
    raise dj_exc_value.with_traceback(traceback) from exc_value
  File "A:\Project\AnturajSurgut\.venv\Lib\site-packages\django\db\backends\utils.py", line 105, in _execute
    return self.cursor.execute(sql, params)
           ^^^^^^^^^^^^^^^^^^^^^^^^^^^^^^^^
  File "A:\Project\AnturajSurgut\.venv\Lib\site-packages\django\db\backends\sqlite3\base.py", line 328, in execute
    return super().execute(query, params)
           ^^^^^^^^^^^^^^^^^^^^^^^^^^^^^^
django.db.utils.OperationalError: no such column: database_cart.price
[13.02.2024 23:10:19 - ERROR] Internal Server Error: /api/profile/cart/, путь: A:\Project\AnturajSurgut\.venv\Lib\site-packages\django\utils\log.py, строка: 241
Traceback (most recent call last):
  File "A:\Project\AnturajSurgut\.venv\Lib\site-packages\django\db\backends\utils.py", line 105, in _execute
    return self.cursor.execute(sql, params)
           ^^^^^^^^^^^^^^^^^^^^^^^^^^^^^^^^
  File "A:\Project\AnturajSurgut\.venv\Lib\site-packages\django\db\backends\sqlite3\base.py", line 328, in execute
    return super().execute(query, params)
           ^^^^^^^^^^^^^^^^^^^^^^^^^^^^^^
sqlite3.OperationalError: no such column: database_cart.created_at

The above exception was the direct cause of the following exception:

Traceback (most recent call last):
  File "A:\Project\AnturajSurgut\.venv\Lib\site-packages\django\core\handlers\exception.py", line 55, in inner
    response = get_response(request)
               ^^^^^^^^^^^^^^^^^^^^^
  File "A:\Project\AnturajSurgut\.venv\Lib\site-packages\django\core\handlers\base.py", line 197, in _get_response
    response = wrapped_callback(request, *callback_args, **callback_kwargs)
               ^^^^^^^^^^^^^^^^^^^^^^^^^^^^^^^^^^^^^^^^^^^^^^^^^^^^^^^^^^^^
  File "A:\Project\AnturajSurgut\.venv\Lib\site-packages\django\views\decorators\csrf.py", line 65, in _view_wrapper
    return view_func(request, *args, **kwargs)
           ^^^^^^^^^^^^^^^^^^^^^^^^^^^^^^^^^^^
  File "A:\Project\AnturajSurgut\.venv\Lib\site-packages\django\views\generic\base.py", line 104, in view
    return self.dispatch(request, *args, **kwargs)
           ^^^^^^^^^^^^^^^^^^^^^^^^^^^^^^^^^^^^^^^
  File "A:\Project\AnturajSurgut\.venv\Lib\site-packages\rest_framework\views.py", line 509, in dispatch
    response = self.handle_exception(exc)
               ^^^^^^^^^^^^^^^^^^^^^^^^^^
  File "A:\Project\AnturajSurgut\.venv\Lib\site-packages\rest_framework\views.py", line 469, in handle_exception
    self.raise_uncaught_exception(exc)
  File "A:\Project\AnturajSurgut\.venv\Lib\site-packages\rest_framework\views.py", line 480, in raise_uncaught_exception
    raise exc
  File "A:\Project\AnturajSurgut\.venv\Lib\site-packages\rest_framework\views.py", line 506, in dispatch
    response = handler(request, *args, **kwargs)
               ^^^^^^^^^^^^^^^^^^^^^^^^^^^^^^^^^
  File "A:\Project\AnturajSurgut\.venv\Lib\site-packages\rest_framework\generics.py", line 239, in get
    return self.list(request, *args, **kwargs)
           ^^^^^^^^^^^^^^^^^^^^^^^^^^^^^^^^^^^
  File "A:\Project\AnturajSurgut\.venv\Lib\site-packages\rest_framework\mixins.py", line 46, in list
    return Response(serializer.data)
                    ^^^^^^^^^^^^^^^
  File "A:\Project\AnturajSurgut\.venv\Lib\site-packages\rest_framework\serializers.py", line 768, in data
    ret = super().data
          ^^^^^^^^^^^^
  File "A:\Project\AnturajSurgut\.venv\Lib\site-packages\rest_framework\serializers.py", line 253, in data
    self._data = self.to_representation(self.instance)
                 ^^^^^^^^^^^^^^^^^^^^^^^^^^^^^^^^^^^^^
  File "A:\Project\AnturajSurgut\.venv\Lib\site-packages\rest_framework\serializers.py", line 686, in to_representation
    return [
           ^
  File "A:\Project\AnturajSurgut\.venv\Lib\site-packages\django\db\models\query.py", line 398, in __iter__
    self._fetch_all()
  File "A:\Project\AnturajSurgut\.venv\Lib\site-packages\django\db\models\query.py", line 1926, in _fetch_all
    self._result_cache = list(self._iterable_class(self))
                         ^^^^^^^^^^^^^^^^^^^^^^^^^^^^^^^^
  File "A:\Project\AnturajSurgut\.venv\Lib\site-packages\django\db\models\query.py", line 91, in __iter__
    results = compiler.execute_sql(
              ^^^^^^^^^^^^^^^^^^^^^
  File "A:\Project\AnturajSurgut\.venv\Lib\site-packages\django\db\models\sql\compiler.py", line 1562, in execute_sql
    cursor.execute(sql, params)
  File "A:\Project\AnturajSurgut\.venv\Lib\site-packages\django\db\backends\utils.py", line 122, in execute
    return super().execute(sql, params)
           ^^^^^^^^^^^^^^^^^^^^^^^^^^^^
  File "A:\Project\AnturajSurgut\.venv\Lib\site-packages\django\db\backends\utils.py", line 79, in execute
    return self._execute_with_wrappers(
           ^^^^^^^^^^^^^^^^^^^^^^^^^^^^
  File "A:\Project\AnturajSurgut\.venv\Lib\site-packages\django\db\backends\utils.py", line 92, in _execute_with_wrappers
    return executor(sql, params, many, context)
           ^^^^^^^^^^^^^^^^^^^^^^^^^^^^^^^^^^^^
  File "A:\Project\AnturajSurgut\.venv\Lib\site-packages\django\db\backends\utils.py", line 100, in _execute
    with self.db.wrap_database_errors:
  File "A:\Project\AnturajSurgut\.venv\Lib\site-packages\django\db\utils.py", line 91, in __exit__
    raise dj_exc_value.with_traceback(traceback) from exc_value
  File "A:\Project\AnturajSurgut\.venv\Lib\site-packages\django\db\backends\utils.py", line 105, in _execute
    return self.cursor.execute(sql, params)
           ^^^^^^^^^^^^^^^^^^^^^^^^^^^^^^^^
  File "A:\Project\AnturajSurgut\.venv\Lib\site-packages\django\db\backends\sqlite3\base.py", line 328, in execute
    return super().execute(query, params)
           ^^^^^^^^^^^^^^^^^^^^^^^^^^^^^^
django.db.utils.OperationalError: no such column: database_cart.created_at
[13.02.2024 23:17:45 - ERROR] Internal Server Error: /api/profile/cart/, путь: A:\Project\AnturajSurgut\.venv\Lib\site-packages\django\utils\log.py, строка: 241
Traceback (most recent call last):
  File "A:\Project\AnturajSurgut\.venv\Lib\site-packages\rest_framework\fields.py", line 446, in get_attribute
    return get_attribute(instance, self.source_attrs)
           ^^^^^^^^^^^^^^^^^^^^^^^^^^^^^^^^^^^^^^^^^^
  File "A:\Project\AnturajSurgut\.venv\Lib\site-packages\rest_framework\fields.py", line 96, in get_attribute
    instance = getattr(instance, attr)
               ^^^^^^^^^^^^^^^^^^^^^^^
AttributeError: 'Cart' object has no attribute 'product'

During handling of the above exception, another exception occurred:

Traceback (most recent call last):
  File "A:\Project\AnturajSurgut\.venv\Lib\site-packages\django\core\handlers\exception.py", line 55, in inner
    response = get_response(request)
               ^^^^^^^^^^^^^^^^^^^^^
  File "A:\Project\AnturajSurgut\.venv\Lib\site-packages\django\core\handlers\base.py", line 197, in _get_response
    response = wrapped_callback(request, *callback_args, **callback_kwargs)
               ^^^^^^^^^^^^^^^^^^^^^^^^^^^^^^^^^^^^^^^^^^^^^^^^^^^^^^^^^^^^
  File "A:\Project\AnturajSurgut\.venv\Lib\site-packages\django\views\decorators\csrf.py", line 65, in _view_wrapper
    return view_func(request, *args, **kwargs)
           ^^^^^^^^^^^^^^^^^^^^^^^^^^^^^^^^^^^
  File "A:\Project\AnturajSurgut\.venv\Lib\site-packages\django\views\generic\base.py", line 104, in view
    return self.dispatch(request, *args, **kwargs)
           ^^^^^^^^^^^^^^^^^^^^^^^^^^^^^^^^^^^^^^^
  File "A:\Project\AnturajSurgut\.venv\Lib\site-packages\rest_framework\views.py", line 509, in dispatch
    response = self.handle_exception(exc)
               ^^^^^^^^^^^^^^^^^^^^^^^^^^
  File "A:\Project\AnturajSurgut\.venv\Lib\site-packages\rest_framework\views.py", line 469, in handle_exception
    self.raise_uncaught_exception(exc)
  File "A:\Project\AnturajSurgut\.venv\Lib\site-packages\rest_framework\views.py", line 480, in raise_uncaught_exception
    raise exc
  File "A:\Project\AnturajSurgut\.venv\Lib\site-packages\rest_framework\views.py", line 506, in dispatch
    response = handler(request, *args, **kwargs)
               ^^^^^^^^^^^^^^^^^^^^^^^^^^^^^^^^^
  File "A:\Project\AnturajSurgut\.venv\Lib\site-packages\rest_framework\generics.py", line 239, in get
    return self.list(request, *args, **kwargs)
           ^^^^^^^^^^^^^^^^^^^^^^^^^^^^^^^^^^^
  File "A:\Project\AnturajSurgut\.venv\Lib\site-packages\rest_framework\mixins.py", line 46, in list
    return Response(serializer.data)
                    ^^^^^^^^^^^^^^^
  File "A:\Project\AnturajSurgut\.venv\Lib\site-packages\rest_framework\serializers.py", line 768, in data
    ret = super().data
          ^^^^^^^^^^^^
  File "A:\Project\AnturajSurgut\.venv\Lib\site-packages\rest_framework\serializers.py", line 253, in data
    self._data = self.to_representation(self.instance)
                 ^^^^^^^^^^^^^^^^^^^^^^^^^^^^^^^^^^^^^
  File "A:\Project\AnturajSurgut\.venv\Lib\site-packages\rest_framework\serializers.py", line 686, in to_representation
    return [
           ^
  File "A:\Project\AnturajSurgut\.venv\Lib\site-packages\rest_framework\serializers.py", line 687, in <listcomp>
    self.child.to_representation(item) for item in iterable
    ^^^^^^^^^^^^^^^^^^^^^^^^^^^^^^^^^^
  File "A:\Project\AnturajSurgut\.venv\Lib\site-packages\rest_framework\serializers.py", line 509, in to_representation
    attribute = field.get_attribute(instance)
                ^^^^^^^^^^^^^^^^^^^^^^^^^^^^^
  File "A:\Project\AnturajSurgut\.venv\Lib\site-packages\rest_framework\fields.py", line 479, in get_attribute
    raise type(exc)(msg)
AttributeError: Got AttributeError when attempting to get a value for field `product` on serializer `CartSerializer`.
The serializer field might be named incorrectly and not match any attribute or key on the `Cart` instance.
Original exception text was: 'Cart' object has no attribute 'product'.
[13.02.2024 23:17:55 - ERROR] Internal Server Error: /api/profile/cart/, путь: A:\Project\AnturajSurgut\.venv\Lib\site-packages\django\utils\log.py, строка: 241
Traceback (most recent call last):
  File "A:\Project\AnturajSurgut\.venv\Lib\site-packages\rest_framework\fields.py", line 446, in get_attribute
    return get_attribute(instance, self.source_attrs)
           ^^^^^^^^^^^^^^^^^^^^^^^^^^^^^^^^^^^^^^^^^^
  File "A:\Project\AnturajSurgut\.venv\Lib\site-packages\rest_framework\fields.py", line 96, in get_attribute
    instance = getattr(instance, attr)
               ^^^^^^^^^^^^^^^^^^^^^^^
AttributeError: 'ManyRelatedManager' object has no attribute 'created_at'

During handling of the above exception, another exception occurred:

Traceback (most recent call last):
  File "A:\Project\AnturajSurgut\.venv\Lib\site-packages\django\core\handlers\exception.py", line 55, in inner
    response = get_response(request)
               ^^^^^^^^^^^^^^^^^^^^^
  File "A:\Project\AnturajSurgut\.venv\Lib\site-packages\django\core\handlers\base.py", line 197, in _get_response
    response = wrapped_callback(request, *callback_args, **callback_kwargs)
               ^^^^^^^^^^^^^^^^^^^^^^^^^^^^^^^^^^^^^^^^^^^^^^^^^^^^^^^^^^^^
  File "A:\Project\AnturajSurgut\.venv\Lib\site-packages\django\views\decorators\csrf.py", line 65, in _view_wrapper
    return view_func(request, *args, **kwargs)
           ^^^^^^^^^^^^^^^^^^^^^^^^^^^^^^^^^^^
  File "A:\Project\AnturajSurgut\.venv\Lib\site-packages\django\views\generic\base.py", line 104, in view
    return self.dispatch(request, *args, **kwargs)
           ^^^^^^^^^^^^^^^^^^^^^^^^^^^^^^^^^^^^^^^
  File "A:\Project\AnturajSurgut\.venv\Lib\site-packages\rest_framework\views.py", line 509, in dispatch
    response = self.handle_exception(exc)
               ^^^^^^^^^^^^^^^^^^^^^^^^^^
  File "A:\Project\AnturajSurgut\.venv\Lib\site-packages\rest_framework\views.py", line 469, in handle_exception
    self.raise_uncaught_exception(exc)
  File "A:\Project\AnturajSurgut\.venv\Lib\site-packages\rest_framework\views.py", line 480, in raise_uncaught_exception
    raise exc
  File "A:\Project\AnturajSurgut\.venv\Lib\site-packages\rest_framework\views.py", line 506, in dispatch
    response = handler(request, *args, **kwargs)
               ^^^^^^^^^^^^^^^^^^^^^^^^^^^^^^^^^
  File "A:\Project\AnturajSurgut\.venv\Lib\site-packages\rest_framework\generics.py", line 239, in get
    return self.list(request, *args, **kwargs)
           ^^^^^^^^^^^^^^^^^^^^^^^^^^^^^^^^^^^
  File "A:\Project\AnturajSurgut\.venv\Lib\site-packages\rest_framework\mixins.py", line 46, in list
    return Response(serializer.data)
                    ^^^^^^^^^^^^^^^
  File "A:\Project\AnturajSurgut\.venv\Lib\site-packages\rest_framework\serializers.py", line 768, in data
    ret = super().data
          ^^^^^^^^^^^^
  File "A:\Project\AnturajSurgut\.venv\Lib\site-packages\rest_framework\serializers.py", line 253, in data
    self._data = self.to_representation(self.instance)
                 ^^^^^^^^^^^^^^^^^^^^^^^^^^^^^^^^^^^^^
  File "A:\Project\AnturajSurgut\.venv\Lib\site-packages\rest_framework\serializers.py", line 686, in to_representation
    return [
           ^
  File "A:\Project\AnturajSurgut\.venv\Lib\site-packages\rest_framework\serializers.py", line 687, in <listcomp>
    self.child.to_representation(item) for item in iterable
    ^^^^^^^^^^^^^^^^^^^^^^^^^^^^^^^^^^
  File "A:\Project\AnturajSurgut\.venv\Lib\site-packages\rest_framework\serializers.py", line 522, in to_representation
    ret[field.field_name] = field.to_representation(attribute)
                            ^^^^^^^^^^^^^^^^^^^^^^^^^^^^^^^^^^
  File "A:\Project\AnturajSurgut\backend\ProductAPI\serializers.py", line 64, in to_representation
    data = super().to_representation(instance)
           ^^^^^^^^^^^^^^^^^^^^^^^^^^^^^^^^^^^
  File "A:\Project\AnturajSurgut\.venv\Lib\site-packages\rest_framework\serializers.py", line 509, in to_representation
    attribute = field.get_attribute(instance)
                ^^^^^^^^^^^^^^^^^^^^^^^^^^^^^
  File "A:\Project\AnturajSurgut\.venv\Lib\site-packages\rest_framework\fields.py", line 479, in get_attribute
    raise type(exc)(msg)
AttributeError: Got AttributeError when attempting to get a value for field `created_at` on serializer `ProductSerializer`.
The serializer field might be named incorrectly and not match any attribute or key on the `ManyRelatedManager` instance.
Original exception text was: 'ManyRelatedManager' object has no attribute 'created_at'.
[13.02.2024 23:17:56 - ERROR] Internal Server Error: /api/profile/cart/, путь: A:\Project\AnturajSurgut\.venv\Lib\site-packages\django\utils\log.py, строка: 241
Traceback (most recent call last):
  File "A:\Project\AnturajSurgut\.venv\Lib\site-packages\rest_framework\fields.py", line 446, in get_attribute
    return get_attribute(instance, self.source_attrs)
           ^^^^^^^^^^^^^^^^^^^^^^^^^^^^^^^^^^^^^^^^^^
  File "A:\Project\AnturajSurgut\.venv\Lib\site-packages\rest_framework\fields.py", line 96, in get_attribute
    instance = getattr(instance, attr)
               ^^^^^^^^^^^^^^^^^^^^^^^
AttributeError: 'ManyRelatedManager' object has no attribute 'created_at'

During handling of the above exception, another exception occurred:

Traceback (most recent call last):
  File "A:\Project\AnturajSurgut\.venv\Lib\site-packages\django\core\handlers\exception.py", line 55, in inner
    response = get_response(request)
               ^^^^^^^^^^^^^^^^^^^^^
  File "A:\Project\AnturajSurgut\.venv\Lib\site-packages\django\core\handlers\base.py", line 197, in _get_response
    response = wrapped_callback(request, *callback_args, **callback_kwargs)
               ^^^^^^^^^^^^^^^^^^^^^^^^^^^^^^^^^^^^^^^^^^^^^^^^^^^^^^^^^^^^
  File "A:\Project\AnturajSurgut\.venv\Lib\site-packages\django\views\decorators\csrf.py", line 65, in _view_wrapper
    return view_func(request, *args, **kwargs)
           ^^^^^^^^^^^^^^^^^^^^^^^^^^^^^^^^^^^
  File "A:\Project\AnturajSurgut\.venv\Lib\site-packages\django\views\generic\base.py", line 104, in view
    return self.dispatch(request, *args, **kwargs)
           ^^^^^^^^^^^^^^^^^^^^^^^^^^^^^^^^^^^^^^^
  File "A:\Project\AnturajSurgut\.venv\Lib\site-packages\rest_framework\views.py", line 509, in dispatch
    response = self.handle_exception(exc)
               ^^^^^^^^^^^^^^^^^^^^^^^^^^
  File "A:\Project\AnturajSurgut\.venv\Lib\site-packages\rest_framework\views.py", line 469, in handle_exception
    self.raise_uncaught_exception(exc)
  File "A:\Project\AnturajSurgut\.venv\Lib\site-packages\rest_framework\views.py", line 480, in raise_uncaught_exception
    raise exc
  File "A:\Project\AnturajSurgut\.venv\Lib\site-packages\rest_framework\views.py", line 506, in dispatch
    response = handler(request, *args, **kwargs)
               ^^^^^^^^^^^^^^^^^^^^^^^^^^^^^^^^^
  File "A:\Project\AnturajSurgut\.venv\Lib\site-packages\rest_framework\generics.py", line 239, in get
    return self.list(request, *args, **kwargs)
           ^^^^^^^^^^^^^^^^^^^^^^^^^^^^^^^^^^^
  File "A:\Project\AnturajSurgut\.venv\Lib\site-packages\rest_framework\mixins.py", line 46, in list
    return Response(serializer.data)
                    ^^^^^^^^^^^^^^^
  File "A:\Project\AnturajSurgut\.venv\Lib\site-packages\rest_framework\serializers.py", line 768, in data
    ret = super().data
          ^^^^^^^^^^^^
  File "A:\Project\AnturajSurgut\.venv\Lib\site-packages\rest_framework\serializers.py", line 253, in data
    self._data = self.to_representation(self.instance)
                 ^^^^^^^^^^^^^^^^^^^^^^^^^^^^^^^^^^^^^
  File "A:\Project\AnturajSurgut\.venv\Lib\site-packages\rest_framework\serializers.py", line 686, in to_representation
    return [
           ^
  File "A:\Project\AnturajSurgut\.venv\Lib\site-packages\rest_framework\serializers.py", line 687, in <listcomp>
    self.child.to_representation(item) for item in iterable
    ^^^^^^^^^^^^^^^^^^^^^^^^^^^^^^^^^^
  File "A:\Project\AnturajSurgut\.venv\Lib\site-packages\rest_framework\serializers.py", line 522, in to_representation
    ret[field.field_name] = field.to_representation(attribute)
                            ^^^^^^^^^^^^^^^^^^^^^^^^^^^^^^^^^^
  File "A:\Project\AnturajSurgut\backend\ProductAPI\serializers.py", line 64, in to_representation
    data = super().to_representation(instance)
           ^^^^^^^^^^^^^^^^^^^^^^^^^^^^^^^^^^^
  File "A:\Project\AnturajSurgut\.venv\Lib\site-packages\rest_framework\serializers.py", line 509, in to_representation
    attribute = field.get_attribute(instance)
                ^^^^^^^^^^^^^^^^^^^^^^^^^^^^^
  File "A:\Project\AnturajSurgut\.venv\Lib\site-packages\rest_framework\fields.py", line 479, in get_attribute
    raise type(exc)(msg)
AttributeError: Got AttributeError when attempting to get a value for field `created_at` on serializer `ProductSerializer`.
The serializer field might be named incorrectly and not match any attribute or key on the `ManyRelatedManager` instance.
Original exception text was: 'ManyRelatedManager' object has no attribute 'created_at'.
[13.02.2024 23:18:24 - ERROR] Internal Server Error: /api/profile/cart/, путь: A:\Project\AnturajSurgut\.venv\Lib\site-packages\django\utils\log.py, строка: 241
Traceback (most recent call last):
  File "A:\Project\AnturajSurgut\.venv\Lib\site-packages\rest_framework\fields.py", line 446, in get_attribute
    return get_attribute(instance, self.source_attrs)
           ^^^^^^^^^^^^^^^^^^^^^^^^^^^^^^^^^^^^^^^^^^
  File "A:\Project\AnturajSurgut\.venv\Lib\site-packages\rest_framework\fields.py", line 96, in get_attribute
    instance = getattr(instance, attr)
               ^^^^^^^^^^^^^^^^^^^^^^^
AttributeError: 'ManyRelatedManager' object has no attribute 'created_at'

During handling of the above exception, another exception occurred:

Traceback (most recent call last):
  File "A:\Project\AnturajSurgut\.venv\Lib\site-packages\django\core\handlers\exception.py", line 55, in inner
    response = get_response(request)
               ^^^^^^^^^^^^^^^^^^^^^
  File "A:\Project\AnturajSurgut\.venv\Lib\site-packages\django\core\handlers\base.py", line 197, in _get_response
    response = wrapped_callback(request, *callback_args, **callback_kwargs)
               ^^^^^^^^^^^^^^^^^^^^^^^^^^^^^^^^^^^^^^^^^^^^^^^^^^^^^^^^^^^^
  File "A:\Project\AnturajSurgut\.venv\Lib\site-packages\django\views\decorators\csrf.py", line 65, in _view_wrapper
    return view_func(request, *args, **kwargs)
           ^^^^^^^^^^^^^^^^^^^^^^^^^^^^^^^^^^^
  File "A:\Project\AnturajSurgut\.venv\Lib\site-packages\django\views\generic\base.py", line 104, in view
    return self.dispatch(request, *args, **kwargs)
           ^^^^^^^^^^^^^^^^^^^^^^^^^^^^^^^^^^^^^^^
  File "A:\Project\AnturajSurgut\.venv\Lib\site-packages\rest_framework\views.py", line 509, in dispatch
    response = self.handle_exception(exc)
               ^^^^^^^^^^^^^^^^^^^^^^^^^^
  File "A:\Project\AnturajSurgut\.venv\Lib\site-packages\rest_framework\views.py", line 469, in handle_exception
    self.raise_uncaught_exception(exc)
  File "A:\Project\AnturajSurgut\.venv\Lib\site-packages\rest_framework\views.py", line 480, in raise_uncaught_exception
    raise exc
  File "A:\Project\AnturajSurgut\.venv\Lib\site-packages\rest_framework\views.py", line 506, in dispatch
    response = handler(request, *args, **kwargs)
               ^^^^^^^^^^^^^^^^^^^^^^^^^^^^^^^^^
  File "A:\Project\AnturajSurgut\.venv\Lib\site-packages\rest_framework\generics.py", line 239, in get
    return self.list(request, *args, **kwargs)
           ^^^^^^^^^^^^^^^^^^^^^^^^^^^^^^^^^^^
  File "A:\Project\AnturajSurgut\.venv\Lib\site-packages\rest_framework\mixins.py", line 46, in list
    return Response(serializer.data)
                    ^^^^^^^^^^^^^^^
  File "A:\Project\AnturajSurgut\.venv\Lib\site-packages\rest_framework\serializers.py", line 768, in data
    ret = super().data
          ^^^^^^^^^^^^
  File "A:\Project\AnturajSurgut\.venv\Lib\site-packages\rest_framework\serializers.py", line 253, in data
    self._data = self.to_representation(self.instance)
                 ^^^^^^^^^^^^^^^^^^^^^^^^^^^^^^^^^^^^^
  File "A:\Project\AnturajSurgut\.venv\Lib\site-packages\rest_framework\serializers.py", line 686, in to_representation
    return [
           ^
  File "A:\Project\AnturajSurgut\.venv\Lib\site-packages\rest_framework\serializers.py", line 687, in <listcomp>
    self.child.to_representation(item) for item in iterable
    ^^^^^^^^^^^^^^^^^^^^^^^^^^^^^^^^^^
  File "A:\Project\AnturajSurgut\.venv\Lib\site-packages\rest_framework\serializers.py", line 522, in to_representation
    ret[field.field_name] = field.to_representation(attribute)
                            ^^^^^^^^^^^^^^^^^^^^^^^^^^^^^^^^^^
  File "A:\Project\AnturajSurgut\backend\ProductAPI\serializers.py", line 64, in to_representation
    data = super().to_representation(instance)
           ^^^^^^^^^^^^^^^^^^^^^^^^^^^^^^^^^^^
  File "A:\Project\AnturajSurgut\.venv\Lib\site-packages\rest_framework\serializers.py", line 509, in to_representation
    attribute = field.get_attribute(instance)
                ^^^^^^^^^^^^^^^^^^^^^^^^^^^^^
  File "A:\Project\AnturajSurgut\.venv\Lib\site-packages\rest_framework\fields.py", line 479, in get_attribute
    raise type(exc)(msg)
AttributeError: Got AttributeError when attempting to get a value for field `created_at` on serializer `ProductSerializer`.
The serializer field might be named incorrectly and not match any attribute or key on the `ManyRelatedManager` instance.
Original exception text was: 'ManyRelatedManager' object has no attribute 'created_at'.
[13.02.2024 23:18:25 - ERROR] Internal Server Error: /api/profile/cart/, путь: A:\Project\AnturajSurgut\.venv\Lib\site-packages\django\utils\log.py, строка: 241
Traceback (most recent call last):
  File "A:\Project\AnturajSurgut\.venv\Lib\site-packages\rest_framework\fields.py", line 446, in get_attribute
    return get_attribute(instance, self.source_attrs)
           ^^^^^^^^^^^^^^^^^^^^^^^^^^^^^^^^^^^^^^^^^^
  File "A:\Project\AnturajSurgut\.venv\Lib\site-packages\rest_framework\fields.py", line 96, in get_attribute
    instance = getattr(instance, attr)
               ^^^^^^^^^^^^^^^^^^^^^^^
AttributeError: 'ManyRelatedManager' object has no attribute 'created_at'

During handling of the above exception, another exception occurred:

Traceback (most recent call last):
  File "A:\Project\AnturajSurgut\.venv\Lib\site-packages\django\core\handlers\exception.py", line 55, in inner
    response = get_response(request)
               ^^^^^^^^^^^^^^^^^^^^^
  File "A:\Project\AnturajSurgut\.venv\Lib\site-packages\django\core\handlers\base.py", line 197, in _get_response
    response = wrapped_callback(request, *callback_args, **callback_kwargs)
               ^^^^^^^^^^^^^^^^^^^^^^^^^^^^^^^^^^^^^^^^^^^^^^^^^^^^^^^^^^^^
  File "A:\Project\AnturajSurgut\.venv\Lib\site-packages\django\views\decorators\csrf.py", line 65, in _view_wrapper
    return view_func(request, *args, **kwargs)
           ^^^^^^^^^^^^^^^^^^^^^^^^^^^^^^^^^^^
  File "A:\Project\AnturajSurgut\.venv\Lib\site-packages\django\views\generic\base.py", line 104, in view
    return self.dispatch(request, *args, **kwargs)
           ^^^^^^^^^^^^^^^^^^^^^^^^^^^^^^^^^^^^^^^
  File "A:\Project\AnturajSurgut\.venv\Lib\site-packages\rest_framework\views.py", line 509, in dispatch
    response = self.handle_exception(exc)
               ^^^^^^^^^^^^^^^^^^^^^^^^^^
  File "A:\Project\AnturajSurgut\.venv\Lib\site-packages\rest_framework\views.py", line 469, in handle_exception
    self.raise_uncaught_exception(exc)
  File "A:\Project\AnturajSurgut\.venv\Lib\site-packages\rest_framework\views.py", line 480, in raise_uncaught_exception
    raise exc
  File "A:\Project\AnturajSurgut\.venv\Lib\site-packages\rest_framework\views.py", line 506, in dispatch
    response = handler(request, *args, **kwargs)
               ^^^^^^^^^^^^^^^^^^^^^^^^^^^^^^^^^
  File "A:\Project\AnturajSurgut\.venv\Lib\site-packages\rest_framework\generics.py", line 239, in get
    return self.list(request, *args, **kwargs)
           ^^^^^^^^^^^^^^^^^^^^^^^^^^^^^^^^^^^
  File "A:\Project\AnturajSurgut\.venv\Lib\site-packages\rest_framework\mixins.py", line 46, in list
    return Response(serializer.data)
                    ^^^^^^^^^^^^^^^
  File "A:\Project\AnturajSurgut\.venv\Lib\site-packages\rest_framework\serializers.py", line 768, in data
    ret = super().data
          ^^^^^^^^^^^^
  File "A:\Project\AnturajSurgut\.venv\Lib\site-packages\rest_framework\serializers.py", line 253, in data
    self._data = self.to_representation(self.instance)
                 ^^^^^^^^^^^^^^^^^^^^^^^^^^^^^^^^^^^^^
  File "A:\Project\AnturajSurgut\.venv\Lib\site-packages\rest_framework\serializers.py", line 686, in to_representation
    return [
           ^
  File "A:\Project\AnturajSurgut\.venv\Lib\site-packages\rest_framework\serializers.py", line 687, in <listcomp>
    self.child.to_representation(item) for item in iterable
    ^^^^^^^^^^^^^^^^^^^^^^^^^^^^^^^^^^
  File "A:\Project\AnturajSurgut\.venv\Lib\site-packages\rest_framework\serializers.py", line 522, in to_representation
    ret[field.field_name] = field.to_representation(attribute)
                            ^^^^^^^^^^^^^^^^^^^^^^^^^^^^^^^^^^
  File "A:\Project\AnturajSurgut\backend\ProductAPI\serializers.py", line 64, in to_representation
    data = super().to_representation(instance)
           ^^^^^^^^^^^^^^^^^^^^^^^^^^^^^^^^^^^
  File "A:\Project\AnturajSurgut\.venv\Lib\site-packages\rest_framework\serializers.py", line 509, in to_representation
    attribute = field.get_attribute(instance)
                ^^^^^^^^^^^^^^^^^^^^^^^^^^^^^
  File "A:\Project\AnturajSurgut\.venv\Lib\site-packages\rest_framework\fields.py", line 479, in get_attribute
    raise type(exc)(msg)
AttributeError: Got AttributeError when attempting to get a value for field `created_at` on serializer `ProductSerializer`.
The serializer field might be named incorrectly and not match any attribute or key on the `ManyRelatedManager` instance.
Original exception text was: 'ManyRelatedManager' object has no attribute 'created_at'.
[13.02.2024 23:18:39 - ERROR] Internal Server Error: /api/profile/cart/, путь: A:\Project\AnturajSurgut\.venv\Lib\site-packages\django\utils\log.py, строка: 241
Traceback (most recent call last):
  File "A:\Project\AnturajSurgut\.venv\Lib\site-packages\rest_framework\fields.py", line 446, in get_attribute
    return get_attribute(instance, self.source_attrs)
           ^^^^^^^^^^^^^^^^^^^^^^^^^^^^^^^^^^^^^^^^^^
  File "A:\Project\AnturajSurgut\.venv\Lib\site-packages\rest_framework\fields.py", line 96, in get_attribute
    instance = getattr(instance, attr)
               ^^^^^^^^^^^^^^^^^^^^^^^
AttributeError: 'ManyRelatedManager' object has no attribute 'created_at'

During handling of the above exception, another exception occurred:

Traceback (most recent call last):
  File "A:\Project\AnturajSurgut\.venv\Lib\site-packages\django\core\handlers\exception.py", line 55, in inner
    response = get_response(request)
               ^^^^^^^^^^^^^^^^^^^^^
  File "A:\Project\AnturajSurgut\.venv\Lib\site-packages\django\core\handlers\base.py", line 197, in _get_response
    response = wrapped_callback(request, *callback_args, **callback_kwargs)
               ^^^^^^^^^^^^^^^^^^^^^^^^^^^^^^^^^^^^^^^^^^^^^^^^^^^^^^^^^^^^
  File "A:\Project\AnturajSurgut\.venv\Lib\site-packages\django\views\decorators\csrf.py", line 65, in _view_wrapper
    return view_func(request, *args, **kwargs)
           ^^^^^^^^^^^^^^^^^^^^^^^^^^^^^^^^^^^
  File "A:\Project\AnturajSurgut\.venv\Lib\site-packages\django\views\generic\base.py", line 104, in view
    return self.dispatch(request, *args, **kwargs)
           ^^^^^^^^^^^^^^^^^^^^^^^^^^^^^^^^^^^^^^^
  File "A:\Project\AnturajSurgut\.venv\Lib\site-packages\rest_framework\views.py", line 509, in dispatch
    response = self.handle_exception(exc)
               ^^^^^^^^^^^^^^^^^^^^^^^^^^
  File "A:\Project\AnturajSurgut\.venv\Lib\site-packages\rest_framework\views.py", line 469, in handle_exception
    self.raise_uncaught_exception(exc)
  File "A:\Project\AnturajSurgut\.venv\Lib\site-packages\rest_framework\views.py", line 480, in raise_uncaught_exception
    raise exc
  File "A:\Project\AnturajSurgut\.venv\Lib\site-packages\rest_framework\views.py", line 506, in dispatch
    response = handler(request, *args, **kwargs)
               ^^^^^^^^^^^^^^^^^^^^^^^^^^^^^^^^^
  File "A:\Project\AnturajSurgut\.venv\Lib\site-packages\rest_framework\generics.py", line 239, in get
    return self.list(request, *args, **kwargs)
           ^^^^^^^^^^^^^^^^^^^^^^^^^^^^^^^^^^^
  File "A:\Project\AnturajSurgut\.venv\Lib\site-packages\rest_framework\mixins.py", line 46, in list
    return Response(serializer.data)
                    ^^^^^^^^^^^^^^^
  File "A:\Project\AnturajSurgut\.venv\Lib\site-packages\rest_framework\serializers.py", line 768, in data
    ret = super().data
          ^^^^^^^^^^^^
  File "A:\Project\AnturajSurgut\.venv\Lib\site-packages\rest_framework\serializers.py", line 253, in data
    self._data = self.to_representation(self.instance)
                 ^^^^^^^^^^^^^^^^^^^^^^^^^^^^^^^^^^^^^
  File "A:\Project\AnturajSurgut\.venv\Lib\site-packages\rest_framework\serializers.py", line 686, in to_representation
    return [
           ^
  File "A:\Project\AnturajSurgut\.venv\Lib\site-packages\rest_framework\serializers.py", line 687, in <listcomp>
    self.child.to_representation(item) for item in iterable
    ^^^^^^^^^^^^^^^^^^^^^^^^^^^^^^^^^^
  File "A:\Project\AnturajSurgut\.venv\Lib\site-packages\rest_framework\serializers.py", line 522, in to_representation
    ret[field.field_name] = field.to_representation(attribute)
                            ^^^^^^^^^^^^^^^^^^^^^^^^^^^^^^^^^^
  File "A:\Project\AnturajSurgut\backend\ProductAPI\serializers.py", line 64, in to_representation
    data = super().to_representation(instance)
           ^^^^^^^^^^^^^^^^^^^^^^^^^^^^^^^^^^^
  File "A:\Project\AnturajSurgut\.venv\Lib\site-packages\rest_framework\serializers.py", line 509, in to_representation
    attribute = field.get_attribute(instance)
                ^^^^^^^^^^^^^^^^^^^^^^^^^^^^^
  File "A:\Project\AnturajSurgut\.venv\Lib\site-packages\rest_framework\fields.py", line 479, in get_attribute
    raise type(exc)(msg)
AttributeError: Got AttributeError when attempting to get a value for field `created_at` on serializer `ProductSerializer`.
The serializer field might be named incorrectly and not match any attribute or key on the `ManyRelatedManager` instance.
Original exception text was: 'ManyRelatedManager' object has no attribute 'created_at'.
[13.02.2024 23:25:16 - ERROR] Internal Server Error: /api/profile/cart/1/, путь: A:\Project\AnturajSurgut\.venv\Lib\site-packages\django\utils\log.py, строка: 241
Traceback (most recent call last):
  File "A:\Project\AnturajSurgut\.venv\Lib\site-packages\django\core\handlers\exception.py", line 55, in inner
    response = get_response(request)
               ^^^^^^^^^^^^^^^^^^^^^
  File "A:\Project\AnturajSurgut\.venv\Lib\site-packages\django\core\handlers\base.py", line 197, in _get_response
    response = wrapped_callback(request, *callback_args, **callback_kwargs)
               ^^^^^^^^^^^^^^^^^^^^^^^^^^^^^^^^^^^^^^^^^^^^^^^^^^^^^^^^^^^^
  File "A:\Project\AnturajSurgut\.venv\Lib\site-packages\django\views\decorators\csrf.py", line 65, in _view_wrapper
    return view_func(request, *args, **kwargs)
           ^^^^^^^^^^^^^^^^^^^^^^^^^^^^^^^^^^^
  File "A:\Project\AnturajSurgut\.venv\Lib\site-packages\django\views\generic\base.py", line 104, in view
    return self.dispatch(request, *args, **kwargs)
           ^^^^^^^^^^^^^^^^^^^^^^^^^^^^^^^^^^^^^^^
  File "A:\Project\AnturajSurgut\.venv\Lib\site-packages\rest_framework\views.py", line 509, in dispatch
    response = self.handle_exception(exc)
               ^^^^^^^^^^^^^^^^^^^^^^^^^^
  File "A:\Project\AnturajSurgut\.venv\Lib\site-packages\rest_framework\views.py", line 469, in handle_exception
    self.raise_uncaught_exception(exc)
  File "A:\Project\AnturajSurgut\.venv\Lib\site-packages\rest_framework\views.py", line 480, in raise_uncaught_exception
    raise exc
  File "A:\Project\AnturajSurgut\.venv\Lib\site-packages\rest_framework\views.py", line 506, in dispatch
    response = handler(request, *args, **kwargs)
               ^^^^^^^^^^^^^^^^^^^^^^^^^^^^^^^^^
  File "A:\Project\AnturajSurgut\.venv\Lib\site-packages\rest_framework\generics.py", line 282, in get
    return self.retrieve(request, *args, **kwargs)
           ^^^^^^^^^^^^^^^^^^^^^^^^^^^^^^^^^^^^^^^
  File "A:\Project\AnturajSurgut\.venv\Lib\site-packages\rest_framework\mixins.py", line 56, in retrieve
    return Response(serializer.data)
                    ^^^^^^^^^^^^^^^
  File "A:\Project\AnturajSurgut\.venv\Lib\site-packages\rest_framework\serializers.py", line 555, in data
    ret = super().data
          ^^^^^^^^^^^^
  File "A:\Project\AnturajSurgut\.venv\Lib\site-packages\rest_framework\serializers.py", line 253, in data
    self._data = self.to_representation(self.instance)
                 ^^^^^^^^^^^^^^^^^^^^^^^^^^^^^^^^^^^^^
  File "A:\Project\AnturajSurgut\.venv\Lib\site-packages\rest_framework\serializers.py", line 522, in to_representation
    ret[field.field_name] = field.to_representation(attribute)
                            ^^^^^^^^^^^^^^^^^^^^^^^^^^^^^^^^^^
  File "A:\Project\AnturajSurgut\.venv\Lib\site-packages\rest_framework\serializers.py", line 507, in to_representation
    for field in fields:
  File "A:\Project\AnturajSurgut\.venv\Lib\site-packages\rest_framework\serializers.py", line 368, in _readable_fields
    for field in self.fields.values():
                 ^^^^^^^^^^^
  File "A:\Project\AnturajSurgut\.venv\Lib\site-packages\django\utils\functional.py", line 47, in __get__
    res = instance.__dict__[self.name] = self.func(instance)
                                         ^^^^^^^^^^^^^^^^^^^
  File "A:\Project\AnturajSurgut\.venv\Lib\site-packages\rest_framework\serializers.py", line 356, in fields
    for key, value in self.get_fields().items():
                      ^^^^^^^^^^^^^^^^^
  File "A:\Project\AnturajSurgut\.venv\Lib\site-packages\rest_framework\serializers.py", line 1052, in get_fields
    field_names = self.get_field_names(declared_fields, info)
                  ^^^^^^^^^^^^^^^^^^^^^^^^^^^^^^^^^^^^^^^^^^^
  File "A:\Project\AnturajSurgut\.venv\Lib\site-packages\rest_framework\serializers.py", line 1148, in get_field_names
    assert field_name in fields, (
           ^^^^^^^^^^^^^^^^^^^^
AssertionError: The field 'product' was declared on serializer CartSerializer, but has not been included in the 'fields' option.
[13.02.2024 23:25:22 - ERROR] Internal Server Error: /api/profile/cart/1/, путь: A:\Project\AnturajSurgut\.venv\Lib\site-packages\django\utils\log.py, строка: 241
Traceback (most recent call last):
  File "A:\Project\AnturajSurgut\.venv\Lib\site-packages\django\core\handlers\exception.py", line 55, in inner
    response = get_response(request)
               ^^^^^^^^^^^^^^^^^^^^^
  File "A:\Project\AnturajSurgut\.venv\Lib\site-packages\django\core\handlers\base.py", line 197, in _get_response
    response = wrapped_callback(request, *callback_args, **callback_kwargs)
               ^^^^^^^^^^^^^^^^^^^^^^^^^^^^^^^^^^^^^^^^^^^^^^^^^^^^^^^^^^^^
  File "A:\Project\AnturajSurgut\.venv\Lib\site-packages\django\views\decorators\csrf.py", line 65, in _view_wrapper
    return view_func(request, *args, **kwargs)
           ^^^^^^^^^^^^^^^^^^^^^^^^^^^^^^^^^^^
  File "A:\Project\AnturajSurgut\.venv\Lib\site-packages\django\views\generic\base.py", line 104, in view
    return self.dispatch(request, *args, **kwargs)
           ^^^^^^^^^^^^^^^^^^^^^^^^^^^^^^^^^^^^^^^
  File "A:\Project\AnturajSurgut\.venv\Lib\site-packages\rest_framework\views.py", line 509, in dispatch
    response = self.handle_exception(exc)
               ^^^^^^^^^^^^^^^^^^^^^^^^^^
  File "A:\Project\AnturajSurgut\.venv\Lib\site-packages\rest_framework\views.py", line 469, in handle_exception
    self.raise_uncaught_exception(exc)
  File "A:\Project\AnturajSurgut\.venv\Lib\site-packages\rest_framework\views.py", line 480, in raise_uncaught_exception
    raise exc
  File "A:\Project\AnturajSurgut\.venv\Lib\site-packages\rest_framework\views.py", line 506, in dispatch
    response = handler(request, *args, **kwargs)
               ^^^^^^^^^^^^^^^^^^^^^^^^^^^^^^^^^
  File "A:\Project\AnturajSurgut\.venv\Lib\site-packages\rest_framework\generics.py", line 282, in get
    return self.retrieve(request, *args, **kwargs)
           ^^^^^^^^^^^^^^^^^^^^^^^^^^^^^^^^^^^^^^^
  File "A:\Project\AnturajSurgut\.venv\Lib\site-packages\rest_framework\mixins.py", line 56, in retrieve
    return Response(serializer.data)
                    ^^^^^^^^^^^^^^^
  File "A:\Project\AnturajSurgut\.venv\Lib\site-packages\rest_framework\serializers.py", line 555, in data
    ret = super().data
          ^^^^^^^^^^^^
  File "A:\Project\AnturajSurgut\.venv\Lib\site-packages\rest_framework\serializers.py", line 253, in data
    self._data = self.to_representation(self.instance)
                 ^^^^^^^^^^^^^^^^^^^^^^^^^^^^^^^^^^^^^
  File "A:\Project\AnturajSurgut\.venv\Lib\site-packages\rest_framework\serializers.py", line 522, in to_representation
    ret[field.field_name] = field.to_representation(attribute)
                            ^^^^^^^^^^^^^^^^^^^^^^^^^^^^^^^^^^
  File "A:\Project\AnturajSurgut\.venv\Lib\site-packages\rest_framework\serializers.py", line 507, in to_representation
    for field in fields:
  File "A:\Project\AnturajSurgut\.venv\Lib\site-packages\rest_framework\serializers.py", line 368, in _readable_fields
    for field in self.fields.values():
                 ^^^^^^^^^^^
  File "A:\Project\AnturajSurgut\.venv\Lib\site-packages\django\utils\functional.py", line 47, in __get__
    res = instance.__dict__[self.name] = self.func(instance)
                                         ^^^^^^^^^^^^^^^^^^^
  File "A:\Project\AnturajSurgut\.venv\Lib\site-packages\rest_framework\serializers.py", line 356, in fields
    for key, value in self.get_fields().items():
                      ^^^^^^^^^^^^^^^^^
  File "A:\Project\AnturajSurgut\.venv\Lib\site-packages\rest_framework\serializers.py", line 1052, in get_fields
    field_names = self.get_field_names(declared_fields, info)
                  ^^^^^^^^^^^^^^^^^^^^^^^^^^^^^^^^^^^^^^^^^^^
  File "A:\Project\AnturajSurgut\.venv\Lib\site-packages\rest_framework\serializers.py", line 1148, in get_field_names
    assert field_name in fields, (
           ^^^^^^^^^^^^^^^^^^^^
AssertionError: The field 'product' was declared on serializer CartSerializer, but has not been included in the 'fields' option.
[13.02.2024 23:25:23 - ERROR] Internal Server Error: /api/profile/cart/1/, путь: A:\Project\AnturajSurgut\.venv\Lib\site-packages\django\utils\log.py, строка: 241
Traceback (most recent call last):
  File "A:\Project\AnturajSurgut\.venv\Lib\site-packages\django\core\handlers\exception.py", line 55, in inner
    response = get_response(request)
               ^^^^^^^^^^^^^^^^^^^^^
  File "A:\Project\AnturajSurgut\.venv\Lib\site-packages\django\core\handlers\base.py", line 197, in _get_response
    response = wrapped_callback(request, *callback_args, **callback_kwargs)
               ^^^^^^^^^^^^^^^^^^^^^^^^^^^^^^^^^^^^^^^^^^^^^^^^^^^^^^^^^^^^
  File "A:\Project\AnturajSurgut\.venv\Lib\site-packages\django\views\decorators\csrf.py", line 65, in _view_wrapper
    return view_func(request, *args, **kwargs)
           ^^^^^^^^^^^^^^^^^^^^^^^^^^^^^^^^^^^
  File "A:\Project\AnturajSurgut\.venv\Lib\site-packages\django\views\generic\base.py", line 104, in view
    return self.dispatch(request, *args, **kwargs)
           ^^^^^^^^^^^^^^^^^^^^^^^^^^^^^^^^^^^^^^^
  File "A:\Project\AnturajSurgut\.venv\Lib\site-packages\rest_framework\views.py", line 509, in dispatch
    response = self.handle_exception(exc)
               ^^^^^^^^^^^^^^^^^^^^^^^^^^
  File "A:\Project\AnturajSurgut\.venv\Lib\site-packages\rest_framework\views.py", line 469, in handle_exception
    self.raise_uncaught_exception(exc)
  File "A:\Project\AnturajSurgut\.venv\Lib\site-packages\rest_framework\views.py", line 480, in raise_uncaught_exception
    raise exc
  File "A:\Project\AnturajSurgut\.venv\Lib\site-packages\rest_framework\views.py", line 506, in dispatch
    response = handler(request, *args, **kwargs)
               ^^^^^^^^^^^^^^^^^^^^^^^^^^^^^^^^^
  File "A:\Project\AnturajSurgut\.venv\Lib\site-packages\rest_framework\generics.py", line 282, in get
    return self.retrieve(request, *args, **kwargs)
           ^^^^^^^^^^^^^^^^^^^^^^^^^^^^^^^^^^^^^^^
  File "A:\Project\AnturajSurgut\.venv\Lib\site-packages\rest_framework\mixins.py", line 56, in retrieve
    return Response(serializer.data)
                    ^^^^^^^^^^^^^^^
  File "A:\Project\AnturajSurgut\.venv\Lib\site-packages\rest_framework\serializers.py", line 555, in data
    ret = super().data
          ^^^^^^^^^^^^
  File "A:\Project\AnturajSurgut\.venv\Lib\site-packages\rest_framework\serializers.py", line 253, in data
    self._data = self.to_representation(self.instance)
                 ^^^^^^^^^^^^^^^^^^^^^^^^^^^^^^^^^^^^^
  File "A:\Project\AnturajSurgut\.venv\Lib\site-packages\rest_framework\serializers.py", line 522, in to_representation
    ret[field.field_name] = field.to_representation(attribute)
                            ^^^^^^^^^^^^^^^^^^^^^^^^^^^^^^^^^^
  File "A:\Project\AnturajSurgut\.venv\Lib\site-packages\rest_framework\serializers.py", line 507, in to_representation
    for field in fields:
  File "A:\Project\AnturajSurgut\.venv\Lib\site-packages\rest_framework\serializers.py", line 368, in _readable_fields
    for field in self.fields.values():
                 ^^^^^^^^^^^
  File "A:\Project\AnturajSurgut\.venv\Lib\site-packages\django\utils\functional.py", line 47, in __get__
    res = instance.__dict__[self.name] = self.func(instance)
                                         ^^^^^^^^^^^^^^^^^^^
  File "A:\Project\AnturajSurgut\.venv\Lib\site-packages\rest_framework\serializers.py", line 356, in fields
    for key, value in self.get_fields().items():
                      ^^^^^^^^^^^^^^^^^
  File "A:\Project\AnturajSurgut\.venv\Lib\site-packages\rest_framework\serializers.py", line 1052, in get_fields
    field_names = self.get_field_names(declared_fields, info)
                  ^^^^^^^^^^^^^^^^^^^^^^^^^^^^^^^^^^^^^^^^^^^
  File "A:\Project\AnturajSurgut\.venv\Lib\site-packages\rest_framework\serializers.py", line 1148, in get_field_names
    assert field_name in fields, (
           ^^^^^^^^^^^^^^^^^^^^
AssertionError: The field 'product' was declared on serializer CartSerializer, but has not been included in the 'fields' option.
[13.02.2024 23:26:29 - ERROR] Internal Server Error: /api/profile/cart/1/, путь: A:\Project\AnturajSurgut\.venv\Lib\site-packages\django\utils\log.py, строка: 241
Traceback (most recent call last):
  File "A:\Project\AnturajSurgut\.venv\Lib\site-packages\rest_framework\fields.py", line 446, in get_attribute
    return get_attribute(instance, self.source_attrs)
           ^^^^^^^^^^^^^^^^^^^^^^^^^^^^^^^^^^^^^^^^^^
  File "A:\Project\AnturajSurgut\.venv\Lib\site-packages\rest_framework\fields.py", line 96, in get_attribute
    instance = getattr(instance, attr)
               ^^^^^^^^^^^^^^^^^^^^^^^
AttributeError: 'Cart' object has no attribute 'product'

During handling of the above exception, another exception occurred:

Traceback (most recent call last):
  File "A:\Project\AnturajSurgut\.venv\Lib\site-packages\django\core\handlers\exception.py", line 55, in inner
    response = get_response(request)
               ^^^^^^^^^^^^^^^^^^^^^
  File "A:\Project\AnturajSurgut\.venv\Lib\site-packages\django\core\handlers\base.py", line 197, in _get_response
    response = wrapped_callback(request, *callback_args, **callback_kwargs)
               ^^^^^^^^^^^^^^^^^^^^^^^^^^^^^^^^^^^^^^^^^^^^^^^^^^^^^^^^^^^^
  File "A:\Project\AnturajSurgut\.venv\Lib\site-packages\django\views\decorators\csrf.py", line 65, in _view_wrapper
    return view_func(request, *args, **kwargs)
           ^^^^^^^^^^^^^^^^^^^^^^^^^^^^^^^^^^^
  File "A:\Project\AnturajSurgut\.venv\Lib\site-packages\django\views\generic\base.py", line 104, in view
    return self.dispatch(request, *args, **kwargs)
           ^^^^^^^^^^^^^^^^^^^^^^^^^^^^^^^^^^^^^^^
  File "A:\Project\AnturajSurgut\.venv\Lib\site-packages\rest_framework\views.py", line 509, in dispatch
    response = self.handle_exception(exc)
               ^^^^^^^^^^^^^^^^^^^^^^^^^^
  File "A:\Project\AnturajSurgut\.venv\Lib\site-packages\rest_framework\views.py", line 469, in handle_exception
    self.raise_uncaught_exception(exc)
  File "A:\Project\AnturajSurgut\.venv\Lib\site-packages\rest_framework\views.py", line 480, in raise_uncaught_exception
    raise exc
  File "A:\Project\AnturajSurgut\.venv\Lib\site-packages\rest_framework\views.py", line 506, in dispatch
    response = handler(request, *args, **kwargs)
               ^^^^^^^^^^^^^^^^^^^^^^^^^^^^^^^^^
  File "A:\Project\AnturajSurgut\.venv\Lib\site-packages\rest_framework\generics.py", line 282, in get
    return self.retrieve(request, *args, **kwargs)
           ^^^^^^^^^^^^^^^^^^^^^^^^^^^^^^^^^^^^^^^
  File "A:\Project\AnturajSurgut\.venv\Lib\site-packages\rest_framework\mixins.py", line 56, in retrieve
    return Response(serializer.data)
                    ^^^^^^^^^^^^^^^
  File "A:\Project\AnturajSurgut\.venv\Lib\site-packages\rest_framework\serializers.py", line 555, in data
    ret = super().data
          ^^^^^^^^^^^^
  File "A:\Project\AnturajSurgut\.venv\Lib\site-packages\rest_framework\serializers.py", line 253, in data
    self._data = self.to_representation(self.instance)
                 ^^^^^^^^^^^^^^^^^^^^^^^^^^^^^^^^^^^^^
  File "A:\Project\AnturajSurgut\.venv\Lib\site-packages\rest_framework\serializers.py", line 522, in to_representation
    ret[field.field_name] = field.to_representation(attribute)
                            ^^^^^^^^^^^^^^^^^^^^^^^^^^^^^^^^^^
  File "A:\Project\AnturajSurgut\.venv\Lib\site-packages\rest_framework\serializers.py", line 509, in to_representation
    attribute = field.get_attribute(instance)
                ^^^^^^^^^^^^^^^^^^^^^^^^^^^^^
  File "A:\Project\AnturajSurgut\.venv\Lib\site-packages\rest_framework\relations.py", line 190, in get_attribute
    return super().get_attribute(instance)
           ^^^^^^^^^^^^^^^^^^^^^^^^^^^^^^^
  File "A:\Project\AnturajSurgut\.venv\Lib\site-packages\rest_framework\fields.py", line 479, in get_attribute
    raise type(exc)(msg)
AttributeError: Got AttributeError when attempting to get a value for field `product` on serializer `CartSerializer`.
The serializer field might be named incorrectly and not match any attribute or key on the `Cart` instance.
Original exception text was: 'Cart' object has no attribute 'product'.
[13.02.2024 23:26:30 - ERROR] Internal Server Error: /api/profile/cart/1/, путь: A:\Project\AnturajSurgut\.venv\Lib\site-packages\django\utils\log.py, строка: 241
Traceback (most recent call last):
  File "A:\Project\AnturajSurgut\.venv\Lib\site-packages\rest_framework\fields.py", line 446, in get_attribute
    return get_attribute(instance, self.source_attrs)
           ^^^^^^^^^^^^^^^^^^^^^^^^^^^^^^^^^^^^^^^^^^
  File "A:\Project\AnturajSurgut\.venv\Lib\site-packages\rest_framework\fields.py", line 96, in get_attribute
    instance = getattr(instance, attr)
               ^^^^^^^^^^^^^^^^^^^^^^^
AttributeError: 'Cart' object has no attribute 'product'

During handling of the above exception, another exception occurred:

Traceback (most recent call last):
  File "A:\Project\AnturajSurgut\.venv\Lib\site-packages\django\core\handlers\exception.py", line 55, in inner
    response = get_response(request)
               ^^^^^^^^^^^^^^^^^^^^^
  File "A:\Project\AnturajSurgut\.venv\Lib\site-packages\django\core\handlers\base.py", line 197, in _get_response
    response = wrapped_callback(request, *callback_args, **callback_kwargs)
               ^^^^^^^^^^^^^^^^^^^^^^^^^^^^^^^^^^^^^^^^^^^^^^^^^^^^^^^^^^^^
  File "A:\Project\AnturajSurgut\.venv\Lib\site-packages\django\views\decorators\csrf.py", line 65, in _view_wrapper
    return view_func(request, *args, **kwargs)
           ^^^^^^^^^^^^^^^^^^^^^^^^^^^^^^^^^^^
  File "A:\Project\AnturajSurgut\.venv\Lib\site-packages\django\views\generic\base.py", line 104, in view
    return self.dispatch(request, *args, **kwargs)
           ^^^^^^^^^^^^^^^^^^^^^^^^^^^^^^^^^^^^^^^
  File "A:\Project\AnturajSurgut\.venv\Lib\site-packages\rest_framework\views.py", line 509, in dispatch
    response = self.handle_exception(exc)
               ^^^^^^^^^^^^^^^^^^^^^^^^^^
  File "A:\Project\AnturajSurgut\.venv\Lib\site-packages\rest_framework\views.py", line 469, in handle_exception
    self.raise_uncaught_exception(exc)
  File "A:\Project\AnturajSurgut\.venv\Lib\site-packages\rest_framework\views.py", line 480, in raise_uncaught_exception
    raise exc
  File "A:\Project\AnturajSurgut\.venv\Lib\site-packages\rest_framework\views.py", line 506, in dispatch
    response = handler(request, *args, **kwargs)
               ^^^^^^^^^^^^^^^^^^^^^^^^^^^^^^^^^
  File "A:\Project\AnturajSurgut\.venv\Lib\site-packages\rest_framework\generics.py", line 282, in get
    return self.retrieve(request, *args, **kwargs)
           ^^^^^^^^^^^^^^^^^^^^^^^^^^^^^^^^^^^^^^^
  File "A:\Project\AnturajSurgut\.venv\Lib\site-packages\rest_framework\mixins.py", line 56, in retrieve
    return Response(serializer.data)
                    ^^^^^^^^^^^^^^^
  File "A:\Project\AnturajSurgut\.venv\Lib\site-packages\rest_framework\serializers.py", line 555, in data
    ret = super().data
          ^^^^^^^^^^^^
  File "A:\Project\AnturajSurgut\.venv\Lib\site-packages\rest_framework\serializers.py", line 253, in data
    self._data = self.to_representation(self.instance)
                 ^^^^^^^^^^^^^^^^^^^^^^^^^^^^^^^^^^^^^
  File "A:\Project\AnturajSurgut\.venv\Lib\site-packages\rest_framework\serializers.py", line 522, in to_representation
    ret[field.field_name] = field.to_representation(attribute)
                            ^^^^^^^^^^^^^^^^^^^^^^^^^^^^^^^^^^
  File "A:\Project\AnturajSurgut\.venv\Lib\site-packages\rest_framework\serializers.py", line 509, in to_representation
    attribute = field.get_attribute(instance)
                ^^^^^^^^^^^^^^^^^^^^^^^^^^^^^
  File "A:\Project\AnturajSurgut\.venv\Lib\site-packages\rest_framework\relations.py", line 190, in get_attribute
    return super().get_attribute(instance)
           ^^^^^^^^^^^^^^^^^^^^^^^^^^^^^^^
  File "A:\Project\AnturajSurgut\.venv\Lib\site-packages\rest_framework\fields.py", line 479, in get_attribute
    raise type(exc)(msg)
AttributeError: Got AttributeError when attempting to get a value for field `product` on serializer `CartSerializer`.
The serializer field might be named incorrectly and not match any attribute or key on the `Cart` instance.
Original exception text was: 'Cart' object has no attribute 'product'.
[16.02.2024 01:31:29 - ERROR] Internal Server Error: /api/profile/test/, путь: A:\Project\AnturajSurgut\.venv\Lib\site-packages\django\utils\log.py, строка: 241
Traceback (most recent call last):
  File "A:\Project\AnturajSurgut\.venv\Lib\site-packages\django\core\handlers\exception.py", line 55, in inner
    response = get_response(request)
               ^^^^^^^^^^^^^^^^^^^^^
  File "A:\Project\AnturajSurgut\.venv\Lib\site-packages\django\core\handlers\base.py", line 197, in _get_response
    response = wrapped_callback(request, *callback_args, **callback_kwargs)
               ^^^^^^^^^^^^^^^^^^^^^^^^^^^^^^^^^^^^^^^^^^^^^^^^^^^^^^^^^^^^
  File "A:\Project\AnturajSurgut\.venv\Lib\site-packages\django\views\decorators\csrf.py", line 65, in _view_wrapper
    return view_func(request, *args, **kwargs)
           ^^^^^^^^^^^^^^^^^^^^^^^^^^^^^^^^^^^
  File "A:\Project\AnturajSurgut\.venv\Lib\site-packages\django\views\generic\base.py", line 104, in view
    return self.dispatch(request, *args, **kwargs)
           ^^^^^^^^^^^^^^^^^^^^^^^^^^^^^^^^^^^^^^^
  File "A:\Project\AnturajSurgut\.venv\Lib\site-packages\rest_framework\views.py", line 509, in dispatch
    response = self.handle_exception(exc)
               ^^^^^^^^^^^^^^^^^^^^^^^^^^
  File "A:\Project\AnturajSurgut\.venv\Lib\site-packages\rest_framework\views.py", line 469, in handle_exception
    self.raise_uncaught_exception(exc)
  File "A:\Project\AnturajSurgut\.venv\Lib\site-packages\rest_framework\views.py", line 480, in raise_uncaught_exception
    raise exc
  File "A:\Project\AnturajSurgut\.venv\Lib\site-packages\rest_framework\views.py", line 506, in dispatch
    response = handler(request, *args, **kwargs)
               ^^^^^^^^^^^^^^^^^^^^^^^^^^^^^^^^^
TypeError: UserCartView.get() takes 1 positional argument but 2 were given
[16.02.2024 01:40:29 - ERROR] Internal Server Error: /api/profile/test/, путь: A:\Project\AnturajSurgut\.venv\Lib\site-packages\django\utils\log.py, строка: 241
Traceback (most recent call last):
  File "A:\Project\AnturajSurgut\.venv\Lib\site-packages\django\core\handlers\exception.py", line 55, in inner
    response = get_response(request)
               ^^^^^^^^^^^^^^^^^^^^^
  File "A:\Project\AnturajSurgut\.venv\Lib\site-packages\django\core\handlers\base.py", line 197, in _get_response
    response = wrapped_callback(request, *callback_args, **callback_kwargs)
               ^^^^^^^^^^^^^^^^^^^^^^^^^^^^^^^^^^^^^^^^^^^^^^^^^^^^^^^^^^^^
  File "A:\Project\AnturajSurgut\.venv\Lib\site-packages\django\views\decorators\csrf.py", line 65, in _view_wrapper
    return view_func(request, *args, **kwargs)
           ^^^^^^^^^^^^^^^^^^^^^^^^^^^^^^^^^^^
  File "A:\Project\AnturajSurgut\.venv\Lib\site-packages\django\views\generic\base.py", line 104, in view
    return self.dispatch(request, *args, **kwargs)
           ^^^^^^^^^^^^^^^^^^^^^^^^^^^^^^^^^^^^^^^
  File "A:\Project\AnturajSurgut\.venv\Lib\site-packages\rest_framework\views.py", line 509, in dispatch
    response = self.handle_exception(exc)
               ^^^^^^^^^^^^^^^^^^^^^^^^^^
  File "A:\Project\AnturajSurgut\.venv\Lib\site-packages\rest_framework\views.py", line 469, in handle_exception
    self.raise_uncaught_exception(exc)
  File "A:\Project\AnturajSurgut\.venv\Lib\site-packages\rest_framework\views.py", line 480, in raise_uncaught_exception
    raise exc
  File "A:\Project\AnturajSurgut\.venv\Lib\site-packages\rest_framework\views.py", line 506, in dispatch
    response = handler(request, *args, **kwargs)
               ^^^^^^^^^^^^^^^^^^^^^^^^^^^^^^^^^
  File "A:\Project\AnturajSurgut\backend\profiles\views.py", line 91, in get
    return Response(serializer.data)
                    ^^^^^^^^^^^^^^^
  File "A:\Project\AnturajSurgut\.venv\Lib\site-packages\rest_framework\serializers.py", line 768, in data
    ret = super().data
          ^^^^^^^^^^^^
  File "A:\Project\AnturajSurgut\.venv\Lib\site-packages\rest_framework\serializers.py", line 253, in data
    self._data = self.to_representation(self.instance)
                 ^^^^^^^^^^^^^^^^^^^^^^^^^^^^^^^^^^^^^
  File "A:\Project\AnturajSurgut\.venv\Lib\site-packages\rest_framework\serializers.py", line 686, in to_representation
    return [
           ^
  File "A:\Project\AnturajSurgut\.venv\Lib\site-packages\rest_framework\serializers.py", line 687, in <listcomp>
    self.child.to_representation(item) for item in iterable
    ^^^^^^^^^^^^^^^^^^^^^^^^^^^^^^^^^^
  File "A:\Project\AnturajSurgut\.venv\Lib\site-packages\rest_framework\serializers.py", line 522, in to_representation
    ret[field.field_name] = field.to_representation(attribute)
                            ^^^^^^^^^^^^^^^^^^^^^^^^^^^^^^^^^^
  File "A:\Project\AnturajSurgut\.venv\Lib\site-packages\rest_framework\serializers.py", line 507, in to_representation
    for field in fields:
  File "A:\Project\AnturajSurgut\.venv\Lib\site-packages\rest_framework\serializers.py", line 368, in _readable_fields
    for field in self.fields.values():
                 ^^^^^^^^^^^
  File "A:\Project\AnturajSurgut\.venv\Lib\site-packages\django\utils\functional.py", line 47, in __get__
    res = instance.__dict__[self.name] = self.func(instance)
                                         ^^^^^^^^^^^^^^^^^^^
  File "A:\Project\AnturajSurgut\.venv\Lib\site-packages\rest_framework\serializers.py", line 356, in fields
    for key, value in self.get_fields().items():
                      ^^^^^^^^^^^^^^^^^
  File "A:\Project\AnturajSurgut\.venv\Lib\site-packages\rest_framework\serializers.py", line 1052, in get_fields
    field_names = self.get_field_names(declared_fields, info)
                  ^^^^^^^^^^^^^^^^^^^^^^^^^^^^^^^^^^^^^^^^^^^
  File "A:\Project\AnturajSurgut\.venv\Lib\site-packages\rest_framework\serializers.py", line 1148, in get_field_names
    assert field_name in fields, (
           ^^^^^^^^^^^^^^^^^^^^
AssertionError: The field 'product' was declared on serializer CartSerializer, but has not been included in the 'fields' option.
[16.02.2024 01:40:30 - ERROR] Internal Server Error: /api/profile/test/, путь: A:\Project\AnturajSurgut\.venv\Lib\site-packages\django\utils\log.py, строка: 241
Traceback (most recent call last):
  File "A:\Project\AnturajSurgut\.venv\Lib\site-packages\django\core\handlers\exception.py", line 55, in inner
    response = get_response(request)
               ^^^^^^^^^^^^^^^^^^^^^
  File "A:\Project\AnturajSurgut\.venv\Lib\site-packages\django\core\handlers\base.py", line 197, in _get_response
    response = wrapped_callback(request, *callback_args, **callback_kwargs)
               ^^^^^^^^^^^^^^^^^^^^^^^^^^^^^^^^^^^^^^^^^^^^^^^^^^^^^^^^^^^^
  File "A:\Project\AnturajSurgut\.venv\Lib\site-packages\django\views\decorators\csrf.py", line 65, in _view_wrapper
    return view_func(request, *args, **kwargs)
           ^^^^^^^^^^^^^^^^^^^^^^^^^^^^^^^^^^^
  File "A:\Project\AnturajSurgut\.venv\Lib\site-packages\django\views\generic\base.py", line 104, in view
    return self.dispatch(request, *args, **kwargs)
           ^^^^^^^^^^^^^^^^^^^^^^^^^^^^^^^^^^^^^^^
  File "A:\Project\AnturajSurgut\.venv\Lib\site-packages\rest_framework\views.py", line 509, in dispatch
    response = self.handle_exception(exc)
               ^^^^^^^^^^^^^^^^^^^^^^^^^^
  File "A:\Project\AnturajSurgut\.venv\Lib\site-packages\rest_framework\views.py", line 469, in handle_exception
    self.raise_uncaught_exception(exc)
  File "A:\Project\AnturajSurgut\.venv\Lib\site-packages\rest_framework\views.py", line 480, in raise_uncaught_exception
    raise exc
  File "A:\Project\AnturajSurgut\.venv\Lib\site-packages\rest_framework\views.py", line 506, in dispatch
    response = handler(request, *args, **kwargs)
               ^^^^^^^^^^^^^^^^^^^^^^^^^^^^^^^^^
  File "A:\Project\AnturajSurgut\backend\profiles\views.py", line 91, in get
    return Response(serializer.data)
                    ^^^^^^^^^^^^^^^
  File "A:\Project\AnturajSurgut\.venv\Lib\site-packages\rest_framework\serializers.py", line 768, in data
    ret = super().data
          ^^^^^^^^^^^^
  File "A:\Project\AnturajSurgut\.venv\Lib\site-packages\rest_framework\serializers.py", line 253, in data
    self._data = self.to_representation(self.instance)
                 ^^^^^^^^^^^^^^^^^^^^^^^^^^^^^^^^^^^^^
  File "A:\Project\AnturajSurgut\.venv\Lib\site-packages\rest_framework\serializers.py", line 686, in to_representation
    return [
           ^
  File "A:\Project\AnturajSurgut\.venv\Lib\site-packages\rest_framework\serializers.py", line 687, in <listcomp>
    self.child.to_representation(item) for item in iterable
    ^^^^^^^^^^^^^^^^^^^^^^^^^^^^^^^^^^
  File "A:\Project\AnturajSurgut\.venv\Lib\site-packages\rest_framework\serializers.py", line 522, in to_representation
    ret[field.field_name] = field.to_representation(attribute)
                            ^^^^^^^^^^^^^^^^^^^^^^^^^^^^^^^^^^
  File "A:\Project\AnturajSurgut\.venv\Lib\site-packages\rest_framework\serializers.py", line 507, in to_representation
    for field in fields:
  File "A:\Project\AnturajSurgut\.venv\Lib\site-packages\rest_framework\serializers.py", line 368, in _readable_fields
    for field in self.fields.values():
                 ^^^^^^^^^^^
  File "A:\Project\AnturajSurgut\.venv\Lib\site-packages\django\utils\functional.py", line 47, in __get__
    res = instance.__dict__[self.name] = self.func(instance)
                                         ^^^^^^^^^^^^^^^^^^^
  File "A:\Project\AnturajSurgut\.venv\Lib\site-packages\rest_framework\serializers.py", line 356, in fields
    for key, value in self.get_fields().items():
                      ^^^^^^^^^^^^^^^^^
  File "A:\Project\AnturajSurgut\.venv\Lib\site-packages\rest_framework\serializers.py", line 1052, in get_fields
    field_names = self.get_field_names(declared_fields, info)
                  ^^^^^^^^^^^^^^^^^^^^^^^^^^^^^^^^^^^^^^^^^^^
  File "A:\Project\AnturajSurgut\.venv\Lib\site-packages\rest_framework\serializers.py", line 1148, in get_field_names
    assert field_name in fields, (
           ^^^^^^^^^^^^^^^^^^^^
AssertionError: The field 'product' was declared on serializer CartSerializer, but has not been included in the 'fields' option.
[16.02.2024 01:40:42 - ERROR] Internal Server Error: /api/profile/test/, путь: A:\Project\AnturajSurgut\.venv\Lib\site-packages\django\utils\log.py, строка: 241
Traceback (most recent call last):
  File "A:\Project\AnturajSurgut\.venv\Lib\site-packages\django\core\handlers\exception.py", line 55, in inner
    response = get_response(request)
               ^^^^^^^^^^^^^^^^^^^^^
  File "A:\Project\AnturajSurgut\.venv\Lib\site-packages\django\core\handlers\base.py", line 197, in _get_response
    response = wrapped_callback(request, *callback_args, **callback_kwargs)
               ^^^^^^^^^^^^^^^^^^^^^^^^^^^^^^^^^^^^^^^^^^^^^^^^^^^^^^^^^^^^
  File "A:\Project\AnturajSurgut\.venv\Lib\site-packages\django\views\decorators\csrf.py", line 65, in _view_wrapper
    return view_func(request, *args, **kwargs)
           ^^^^^^^^^^^^^^^^^^^^^^^^^^^^^^^^^^^
  File "A:\Project\AnturajSurgut\.venv\Lib\site-packages\django\views\generic\base.py", line 104, in view
    return self.dispatch(request, *args, **kwargs)
           ^^^^^^^^^^^^^^^^^^^^^^^^^^^^^^^^^^^^^^^
  File "A:\Project\AnturajSurgut\.venv\Lib\site-packages\rest_framework\views.py", line 509, in dispatch
    response = self.handle_exception(exc)
               ^^^^^^^^^^^^^^^^^^^^^^^^^^
  File "A:\Project\AnturajSurgut\.venv\Lib\site-packages\rest_framework\views.py", line 469, in handle_exception
    self.raise_uncaught_exception(exc)
  File "A:\Project\AnturajSurgut\.venv\Lib\site-packages\rest_framework\views.py", line 480, in raise_uncaught_exception
    raise exc
  File "A:\Project\AnturajSurgut\.venv\Lib\site-packages\rest_framework\views.py", line 506, in dispatch
    response = handler(request, *args, **kwargs)
               ^^^^^^^^^^^^^^^^^^^^^^^^^^^^^^^^^
  File "A:\Project\AnturajSurgut\backend\profiles\views.py", line 91, in get
    return Response(serializer.data)
                    ^^^^^^^^^^^^^^^
  File "A:\Project\AnturajSurgut\.venv\Lib\site-packages\rest_framework\serializers.py", line 768, in data
    ret = super().data
          ^^^^^^^^^^^^
  File "A:\Project\AnturajSurgut\.venv\Lib\site-packages\rest_framework\serializers.py", line 253, in data
    self._data = self.to_representation(self.instance)
                 ^^^^^^^^^^^^^^^^^^^^^^^^^^^^^^^^^^^^^
  File "A:\Project\AnturajSurgut\.venv\Lib\site-packages\rest_framework\serializers.py", line 686, in to_representation
    return [
           ^
  File "A:\Project\AnturajSurgut\.venv\Lib\site-packages\rest_framework\serializers.py", line 687, in <listcomp>
    self.child.to_representation(item) for item in iterable
    ^^^^^^^^^^^^^^^^^^^^^^^^^^^^^^^^^^
  File "A:\Project\AnturajSurgut\.venv\Lib\site-packages\rest_framework\serializers.py", line 522, in to_representation
    ret[field.field_name] = field.to_representation(attribute)
                            ^^^^^^^^^^^^^^^^^^^^^^^^^^^^^^^^^^
  File "A:\Project\AnturajSurgut\.venv\Lib\site-packages\rest_framework\serializers.py", line 507, in to_representation
    for field in fields:
  File "A:\Project\AnturajSurgut\.venv\Lib\site-packages\rest_framework\serializers.py", line 368, in _readable_fields
    for field in self.fields.values():
                 ^^^^^^^^^^^
  File "A:\Project\AnturajSurgut\.venv\Lib\site-packages\django\utils\functional.py", line 47, in __get__
    res = instance.__dict__[self.name] = self.func(instance)
                                         ^^^^^^^^^^^^^^^^^^^
  File "A:\Project\AnturajSurgut\.venv\Lib\site-packages\rest_framework\serializers.py", line 356, in fields
    for key, value in self.get_fields().items():
                      ^^^^^^^^^^^^^^^^^
  File "A:\Project\AnturajSurgut\.venv\Lib\site-packages\rest_framework\serializers.py", line 1052, in get_fields
    field_names = self.get_field_names(declared_fields, info)
                  ^^^^^^^^^^^^^^^^^^^^^^^^^^^^^^^^^^^^^^^^^^^
  File "A:\Project\AnturajSurgut\.venv\Lib\site-packages\rest_framework\serializers.py", line 1148, in get_field_names
    assert field_name in fields, (
           ^^^^^^^^^^^^^^^^^^^^
AssertionError: The field 'product' was declared on serializer CartSerializer, but has not been included in the 'fields' option.
[16.02.2024 01:45:18 - ERROR] Internal Server Error: /api/profile/test/, путь: A:\Project\AnturajSurgut\.venv\Lib\site-packages\django\utils\log.py, строка: 241
Traceback (most recent call last):
  File "A:\Project\AnturajSurgut\.venv\Lib\site-packages\rest_framework\fields.py", line 446, in get_attribute
    return get_attribute(instance, self.source_attrs)
           ^^^^^^^^^^^^^^^^^^^^^^^^^^^^^^^^^^^^^^^^^^
  File "A:\Project\AnturajSurgut\.venv\Lib\site-packages\rest_framework\fields.py", line 96, in get_attribute
    instance = getattr(instance, attr)
               ^^^^^^^^^^^^^^^^^^^^^^^
AttributeError: 'CartItem' object has no attribute 'user'

During handling of the above exception, another exception occurred:

Traceback (most recent call last):
  File "A:\Project\AnturajSurgut\.venv\Lib\site-packages\django\core\handlers\exception.py", line 55, in inner
    response = get_response(request)
               ^^^^^^^^^^^^^^^^^^^^^
  File "A:\Project\AnturajSurgut\.venv\Lib\site-packages\django\core\handlers\base.py", line 197, in _get_response
    response = wrapped_callback(request, *callback_args, **callback_kwargs)
               ^^^^^^^^^^^^^^^^^^^^^^^^^^^^^^^^^^^^^^^^^^^^^^^^^^^^^^^^^^^^
  File "A:\Project\AnturajSurgut\.venv\Lib\site-packages\django\views\decorators\csrf.py", line 65, in _view_wrapper
    return view_func(request, *args, **kwargs)
           ^^^^^^^^^^^^^^^^^^^^^^^^^^^^^^^^^^^
  File "A:\Project\AnturajSurgut\.venv\Lib\site-packages\django\views\generic\base.py", line 104, in view
    return self.dispatch(request, *args, **kwargs)
           ^^^^^^^^^^^^^^^^^^^^^^^^^^^^^^^^^^^^^^^
  File "A:\Project\AnturajSurgut\.venv\Lib\site-packages\rest_framework\views.py", line 509, in dispatch
    response = self.handle_exception(exc)
               ^^^^^^^^^^^^^^^^^^^^^^^^^^
  File "A:\Project\AnturajSurgut\.venv\Lib\site-packages\rest_framework\views.py", line 469, in handle_exception
    self.raise_uncaught_exception(exc)
  File "A:\Project\AnturajSurgut\.venv\Lib\site-packages\rest_framework\views.py", line 480, in raise_uncaught_exception
    raise exc
  File "A:\Project\AnturajSurgut\.venv\Lib\site-packages\rest_framework\views.py", line 506, in dispatch
    response = handler(request, *args, **kwargs)
               ^^^^^^^^^^^^^^^^^^^^^^^^^^^^^^^^^
  File "A:\Project\AnturajSurgut\backend\profiles\views.py", line 91, in get
    return Response(serializer.data)
                    ^^^^^^^^^^^^^^^
  File "A:\Project\AnturajSurgut\.venv\Lib\site-packages\rest_framework\serializers.py", line 768, in data
    ret = super().data
          ^^^^^^^^^^^^
  File "A:\Project\AnturajSurgut\.venv\Lib\site-packages\rest_framework\serializers.py", line 253, in data
    self._data = self.to_representation(self.instance)
                 ^^^^^^^^^^^^^^^^^^^^^^^^^^^^^^^^^^^^^
  File "A:\Project\AnturajSurgut\.venv\Lib\site-packages\rest_framework\serializers.py", line 686, in to_representation
    return [
           ^
  File "A:\Project\AnturajSurgut\.venv\Lib\site-packages\rest_framework\serializers.py", line 687, in <listcomp>
    self.child.to_representation(item) for item in iterable
    ^^^^^^^^^^^^^^^^^^^^^^^^^^^^^^^^^^
  File "A:\Project\AnturajSurgut\.venv\Lib\site-packages\rest_framework\serializers.py", line 509, in to_representation
    attribute = field.get_attribute(instance)
                ^^^^^^^^^^^^^^^^^^^^^^^^^^^^^
  File "A:\Project\AnturajSurgut\.venv\Lib\site-packages\rest_framework\relations.py", line 190, in get_attribute
    return super().get_attribute(instance)
           ^^^^^^^^^^^^^^^^^^^^^^^^^^^^^^^
  File "A:\Project\AnturajSurgut\.venv\Lib\site-packages\rest_framework\fields.py", line 479, in get_attribute
    raise type(exc)(msg)
AttributeError: Got AttributeError when attempting to get a value for field `user` on serializer `CartSerializer`.
The serializer field might be named incorrectly and not match any attribute or key on the `CartItem` instance.
Original exception text was: 'CartItem' object has no attribute 'user'.
[16.02.2024 01:45:47 - ERROR] Internal Server Error: /api/profile/test/, путь: A:\Project\AnturajSurgut\.venv\Lib\site-packages\django\utils\log.py, строка: 241
Traceback (most recent call last):
  File "A:\Project\AnturajSurgut\.venv\Lib\site-packages\django\core\handlers\exception.py", line 55, in inner
    response = get_response(request)
               ^^^^^^^^^^^^^^^^^^^^^
  File "A:\Project\AnturajSurgut\.venv\Lib\site-packages\django\core\handlers\base.py", line 197, in _get_response
    response = wrapped_callback(request, *callback_args, **callback_kwargs)
               ^^^^^^^^^^^^^^^^^^^^^^^^^^^^^^^^^^^^^^^^^^^^^^^^^^^^^^^^^^^^
  File "A:\Project\AnturajSurgut\.venv\Lib\site-packages\django\views\decorators\csrf.py", line 65, in _view_wrapper
    return view_func(request, *args, **kwargs)
           ^^^^^^^^^^^^^^^^^^^^^^^^^^^^^^^^^^^
  File "A:\Project\AnturajSurgut\.venv\Lib\site-packages\django\views\generic\base.py", line 104, in view
    return self.dispatch(request, *args, **kwargs)
           ^^^^^^^^^^^^^^^^^^^^^^^^^^^^^^^^^^^^^^^
  File "A:\Project\AnturajSurgut\.venv\Lib\site-packages\rest_framework\views.py", line 509, in dispatch
    response = self.handle_exception(exc)
               ^^^^^^^^^^^^^^^^^^^^^^^^^^
  File "A:\Project\AnturajSurgut\.venv\Lib\site-packages\rest_framework\views.py", line 469, in handle_exception
    self.raise_uncaught_exception(exc)
  File "A:\Project\AnturajSurgut\.venv\Lib\site-packages\rest_framework\views.py", line 480, in raise_uncaught_exception
    raise exc
  File "A:\Project\AnturajSurgut\.venv\Lib\site-packages\rest_framework\views.py", line 506, in dispatch
    response = handler(request, *args, **kwargs)
               ^^^^^^^^^^^^^^^^^^^^^^^^^^^^^^^^^
  File "A:\Project\AnturajSurgut\backend\profiles\views.py", line 89, in get
    cart_items = CartSerializer.objects.filter(cart__user=user)
                 ^^^^^^^^^^^^^^^^^^^^^^
AttributeError: type object 'CartSerializer' has no attribute 'objects'
[16.02.2024 01:47:33 - ERROR] Internal Server Error: /api/profile/test/, путь: A:\Project\AnturajSurgut\.venv\Lib\site-packages\django\utils\log.py, строка: 241
Traceback (most recent call last):
  File "A:\Project\AnturajSurgut\.venv\Lib\site-packages\django\core\handlers\exception.py", line 55, in inner
    response = get_response(request)
               ^^^^^^^^^^^^^^^^^^^^^
  File "A:\Project\AnturajSurgut\.venv\Lib\site-packages\django\core\handlers\base.py", line 197, in _get_response
    response = wrapped_callback(request, *callback_args, **callback_kwargs)
               ^^^^^^^^^^^^^^^^^^^^^^^^^^^^^^^^^^^^^^^^^^^^^^^^^^^^^^^^^^^^
  File "A:\Project\AnturajSurgut\.venv\Lib\site-packages\django\views\decorators\csrf.py", line 65, in _view_wrapper
    return view_func(request, *args, **kwargs)
           ^^^^^^^^^^^^^^^^^^^^^^^^^^^^^^^^^^^
  File "A:\Project\AnturajSurgut\.venv\Lib\site-packages\django\views\generic\base.py", line 104, in view
    return self.dispatch(request, *args, **kwargs)
           ^^^^^^^^^^^^^^^^^^^^^^^^^^^^^^^^^^^^^^^
  File "A:\Project\AnturajSurgut\.venv\Lib\site-packages\rest_framework\views.py", line 509, in dispatch
    response = self.handle_exception(exc)
               ^^^^^^^^^^^^^^^^^^^^^^^^^^
  File "A:\Project\AnturajSurgut\.venv\Lib\site-packages\rest_framework\views.py", line 469, in handle_exception
    self.raise_uncaught_exception(exc)
  File "A:\Project\AnturajSurgut\.venv\Lib\site-packages\rest_framework\views.py", line 480, in raise_uncaught_exception
    raise exc
  File "A:\Project\AnturajSurgut\.venv\Lib\site-packages\rest_framework\views.py", line 506, in dispatch
    response = handler(request, *args, **kwargs)
               ^^^^^^^^^^^^^^^^^^^^^^^^^^^^^^^^^
  File "A:\Project\AnturajSurgut\backend\profiles\views.py", line 91, in get
    return Response(serializer.data)
                    ^^^^^^^^^^^^^^^
  File "A:\Project\AnturajSurgut\.venv\Lib\site-packages\rest_framework\serializers.py", line 768, in data
    ret = super().data
          ^^^^^^^^^^^^
  File "A:\Project\AnturajSurgut\.venv\Lib\site-packages\rest_framework\serializers.py", line 253, in data
    self._data = self.to_representation(self.instance)
                 ^^^^^^^^^^^^^^^^^^^^^^^^^^^^^^^^^^^^^
  File "A:\Project\AnturajSurgut\.venv\Lib\site-packages\rest_framework\serializers.py", line 686, in to_representation
    return [
           ^
  File "A:\Project\AnturajSurgut\.venv\Lib\site-packages\rest_framework\serializers.py", line 687, in <listcomp>
    self.child.to_representation(item) for item in iterable
    ^^^^^^^^^^^^^^^^^^^^^^^^^^^^^^^^^^
  File "A:\Project\AnturajSurgut\.venv\Lib\site-packages\rest_framework\serializers.py", line 507, in to_representation
    for field in fields:
  File "A:\Project\AnturajSurgut\.venv\Lib\site-packages\rest_framework\serializers.py", line 368, in _readable_fields
    for field in self.fields.values():
                 ^^^^^^^^^^^
  File "A:\Project\AnturajSurgut\.venv\Lib\site-packages\django\utils\functional.py", line 47, in __get__
    res = instance.__dict__[self.name] = self.func(instance)
                                         ^^^^^^^^^^^^^^^^^^^
  File "A:\Project\AnturajSurgut\.venv\Lib\site-packages\rest_framework\serializers.py", line 357, in fields
    fields[key] = value
    ~~~~~~^^^^^
  File "A:\Project\AnturajSurgut\.venv\Lib\site-packages\rest_framework\utils\serializer_helpers.py", line 169, in __setitem__
    field.bind(field_name=key, parent=self.serializer)
  File "A:\Project\AnturajSurgut\.venv\Lib\site-packages\rest_framework\fields.py", line 367, in bind
    assert self.source != field_name, (
           ^^^^^^^^^^^^^^^^^^^^^^^^^
AssertionError: It is redundant to specify `source='product'` on field 'PrimaryKeyRelatedField' in serializer 'CartItemSerializer', because it is the same as the field name. Remove the `source` keyword argument.
[16.02.2024 01:50:00 - ERROR] Internal Server Error: /api/profile/test/, путь: A:\Project\AnturajSurgut\.venv\Lib\site-packages\django\utils\log.py, строка: 241
Traceback (most recent call last):
  File "A:\Project\AnturajSurgut\.venv\Lib\site-packages\rest_framework\fields.py", line 446, in get_attribute
    return get_attribute(instance, self.source_attrs)
           ^^^^^^^^^^^^^^^^^^^^^^^^^^^^^^^^^^^^^^^^^^
  File "A:\Project\AnturajSurgut\.venv\Lib\site-packages\rest_framework\fields.py", line 96, in get_attribute
    instance = getattr(instance, attr)
               ^^^^^^^^^^^^^^^^^^^^^^^
AttributeError: 'CartItem' object has no attribute 'user'

During handling of the above exception, another exception occurred:

Traceback (most recent call last):
  File "A:\Project\AnturajSurgut\.venv\Lib\site-packages\django\core\handlers\exception.py", line 55, in inner
    response = get_response(request)
               ^^^^^^^^^^^^^^^^^^^^^
  File "A:\Project\AnturajSurgut\.venv\Lib\site-packages\django\core\handlers\base.py", line 197, in _get_response
    response = wrapped_callback(request, *callback_args, **callback_kwargs)
               ^^^^^^^^^^^^^^^^^^^^^^^^^^^^^^^^^^^^^^^^^^^^^^^^^^^^^^^^^^^^
  File "A:\Project\AnturajSurgut\.venv\Lib\site-packages\django\views\decorators\csrf.py", line 65, in _view_wrapper
    return view_func(request, *args, **kwargs)
           ^^^^^^^^^^^^^^^^^^^^^^^^^^^^^^^^^^^
  File "A:\Project\AnturajSurgut\.venv\Lib\site-packages\django\views\generic\base.py", line 104, in view
    return self.dispatch(request, *args, **kwargs)
           ^^^^^^^^^^^^^^^^^^^^^^^^^^^^^^^^^^^^^^^
  File "A:\Project\AnturajSurgut\.venv\Lib\site-packages\rest_framework\views.py", line 509, in dispatch
    response = self.handle_exception(exc)
               ^^^^^^^^^^^^^^^^^^^^^^^^^^
  File "A:\Project\AnturajSurgut\.venv\Lib\site-packages\rest_framework\views.py", line 469, in handle_exception
    self.raise_uncaught_exception(exc)
  File "A:\Project\AnturajSurgut\.venv\Lib\site-packages\rest_framework\views.py", line 480, in raise_uncaught_exception
    raise exc
  File "A:\Project\AnturajSurgut\.venv\Lib\site-packages\rest_framework\views.py", line 506, in dispatch
    response = handler(request, *args, **kwargs)
               ^^^^^^^^^^^^^^^^^^^^^^^^^^^^^^^^^
  File "A:\Project\AnturajSurgut\backend\profiles\views.py", line 91, in get
    return Response(serializer.data)
                    ^^^^^^^^^^^^^^^
  File "A:\Project\AnturajSurgut\.venv\Lib\site-packages\rest_framework\serializers.py", line 768, in data
    ret = super().data
          ^^^^^^^^^^^^
  File "A:\Project\AnturajSurgut\.venv\Lib\site-packages\rest_framework\serializers.py", line 253, in data
    self._data = self.to_representation(self.instance)
                 ^^^^^^^^^^^^^^^^^^^^^^^^^^^^^^^^^^^^^
  File "A:\Project\AnturajSurgut\.venv\Lib\site-packages\rest_framework\serializers.py", line 686, in to_representation
    return [
           ^
  File "A:\Project\AnturajSurgut\.venv\Lib\site-packages\rest_framework\serializers.py", line 687, in <listcomp>
    self.child.to_representation(item) for item in iterable
    ^^^^^^^^^^^^^^^^^^^^^^^^^^^^^^^^^^
  File "A:\Project\AnturajSurgut\.venv\Lib\site-packages\rest_framework\serializers.py", line 509, in to_representation
    attribute = field.get_attribute(instance)
                ^^^^^^^^^^^^^^^^^^^^^^^^^^^^^
  File "A:\Project\AnturajSurgut\.venv\Lib\site-packages\rest_framework\fields.py", line 479, in get_attribute
    raise type(exc)(msg)
AttributeError: Got AttributeError when attempting to get a value for field `user` on serializer `CartItemSerializer`.
The serializer field might be named incorrectly and not match any attribute or key on the `CartItem` instance.
Original exception text was: 'CartItem' object has no attribute 'user'.
[16.02.2024 01:50:02 - ERROR] Internal Server Error: /api/profile/test/, путь: A:\Project\AnturajSurgut\.venv\Lib\site-packages\django\utils\log.py, строка: 241
Traceback (most recent call last):
  File "A:\Project\AnturajSurgut\.venv\Lib\site-packages\rest_framework\fields.py", line 446, in get_attribute
    return get_attribute(instance, self.source_attrs)
           ^^^^^^^^^^^^^^^^^^^^^^^^^^^^^^^^^^^^^^^^^^
  File "A:\Project\AnturajSurgut\.venv\Lib\site-packages\rest_framework\fields.py", line 96, in get_attribute
    instance = getattr(instance, attr)
               ^^^^^^^^^^^^^^^^^^^^^^^
AttributeError: 'CartItem' object has no attribute 'user'

During handling of the above exception, another exception occurred:

Traceback (most recent call last):
  File "A:\Project\AnturajSurgut\.venv\Lib\site-packages\django\core\handlers\exception.py", line 55, in inner
    response = get_response(request)
               ^^^^^^^^^^^^^^^^^^^^^
  File "A:\Project\AnturajSurgut\.venv\Lib\site-packages\django\core\handlers\base.py", line 197, in _get_response
    response = wrapped_callback(request, *callback_args, **callback_kwargs)
               ^^^^^^^^^^^^^^^^^^^^^^^^^^^^^^^^^^^^^^^^^^^^^^^^^^^^^^^^^^^^
  File "A:\Project\AnturajSurgut\.venv\Lib\site-packages\django\views\decorators\csrf.py", line 65, in _view_wrapper
    return view_func(request, *args, **kwargs)
           ^^^^^^^^^^^^^^^^^^^^^^^^^^^^^^^^^^^
  File "A:\Project\AnturajSurgut\.venv\Lib\site-packages\django\views\generic\base.py", line 104, in view
    return self.dispatch(request, *args, **kwargs)
           ^^^^^^^^^^^^^^^^^^^^^^^^^^^^^^^^^^^^^^^
  File "A:\Project\AnturajSurgut\.venv\Lib\site-packages\rest_framework\views.py", line 509, in dispatch
    response = self.handle_exception(exc)
               ^^^^^^^^^^^^^^^^^^^^^^^^^^
  File "A:\Project\AnturajSurgut\.venv\Lib\site-packages\rest_framework\views.py", line 469, in handle_exception
    self.raise_uncaught_exception(exc)
  File "A:\Project\AnturajSurgut\.venv\Lib\site-packages\rest_framework\views.py", line 480, in raise_uncaught_exception
    raise exc
  File "A:\Project\AnturajSurgut\.venv\Lib\site-packages\rest_framework\views.py", line 506, in dispatch
    response = handler(request, *args, **kwargs)
               ^^^^^^^^^^^^^^^^^^^^^^^^^^^^^^^^^
  File "A:\Project\AnturajSurgut\backend\profiles\views.py", line 91, in get
    return Response(serializer.data)
                    ^^^^^^^^^^^^^^^
  File "A:\Project\AnturajSurgut\.venv\Lib\site-packages\rest_framework\serializers.py", line 768, in data
    ret = super().data
          ^^^^^^^^^^^^
  File "A:\Project\AnturajSurgut\.venv\Lib\site-packages\rest_framework\serializers.py", line 253, in data
    self._data = self.to_representation(self.instance)
                 ^^^^^^^^^^^^^^^^^^^^^^^^^^^^^^^^^^^^^
  File "A:\Project\AnturajSurgut\.venv\Lib\site-packages\rest_framework\serializers.py", line 686, in to_representation
    return [
           ^
  File "A:\Project\AnturajSurgut\.venv\Lib\site-packages\rest_framework\serializers.py", line 687, in <listcomp>
    self.child.to_representation(item) for item in iterable
    ^^^^^^^^^^^^^^^^^^^^^^^^^^^^^^^^^^
  File "A:\Project\AnturajSurgut\.venv\Lib\site-packages\rest_framework\serializers.py", line 509, in to_representation
    attribute = field.get_attribute(instance)
                ^^^^^^^^^^^^^^^^^^^^^^^^^^^^^
  File "A:\Project\AnturajSurgut\.venv\Lib\site-packages\rest_framework\fields.py", line 479, in get_attribute
    raise type(exc)(msg)
AttributeError: Got AttributeError when attempting to get a value for field `user` on serializer `CartItemSerializer`.
The serializer field might be named incorrectly and not match any attribute or key on the `CartItem` instance.
Original exception text was: 'CartItem' object has no attribute 'user'.
[16.02.2024 01:50:33 - ERROR] Internal Server Error: /api/profile/test/, путь: A:\Project\AnturajSurgut\.venv\Lib\site-packages\django\utils\log.py, строка: 241
Traceback (most recent call last):
  File "A:\Project\AnturajSurgut\.venv\Lib\site-packages\django\core\handlers\exception.py", line 55, in inner
    response = get_response(request)
               ^^^^^^^^^^^^^^^^^^^^^
  File "A:\Project\AnturajSurgut\.venv\Lib\site-packages\django\core\handlers\base.py", line 197, in _get_response
    response = wrapped_callback(request, *callback_args, **callback_kwargs)
               ^^^^^^^^^^^^^^^^^^^^^^^^^^^^^^^^^^^^^^^^^^^^^^^^^^^^^^^^^^^^
  File "A:\Project\AnturajSurgut\.venv\Lib\site-packages\django\views\decorators\csrf.py", line 65, in _view_wrapper
    return view_func(request, *args, **kwargs)
           ^^^^^^^^^^^^^^^^^^^^^^^^^^^^^^^^^^^
  File "A:\Project\AnturajSurgut\.venv\Lib\site-packages\django\views\generic\base.py", line 104, in view
    return self.dispatch(request, *args, **kwargs)
           ^^^^^^^^^^^^^^^^^^^^^^^^^^^^^^^^^^^^^^^
  File "A:\Project\AnturajSurgut\.venv\Lib\site-packages\rest_framework\views.py", line 509, in dispatch
    response = self.handle_exception(exc)
               ^^^^^^^^^^^^^^^^^^^^^^^^^^
  File "A:\Project\AnturajSurgut\.venv\Lib\site-packages\rest_framework\views.py", line 469, in handle_exception
    self.raise_uncaught_exception(exc)
  File "A:\Project\AnturajSurgut\.venv\Lib\site-packages\rest_framework\views.py", line 480, in raise_uncaught_exception
    raise exc
  File "A:\Project\AnturajSurgut\.venv\Lib\site-packages\rest_framework\views.py", line 506, in dispatch
    response = handler(request, *args, **kwargs)
               ^^^^^^^^^^^^^^^^^^^^^^^^^^^^^^^^^
  File "A:\Project\AnturajSurgut\backend\profiles\views.py", line 91, in get
    return Response(serializer.data)
                    ^^^^^^^^^^^^^^^
  File "A:\Project\AnturajSurgut\.venv\Lib\site-packages\rest_framework\serializers.py", line 768, in data
    ret = super().data
          ^^^^^^^^^^^^
  File "A:\Project\AnturajSurgut\.venv\Lib\site-packages\rest_framework\serializers.py", line 253, in data
    self._data = self.to_representation(self.instance)
                 ^^^^^^^^^^^^^^^^^^^^^^^^^^^^^^^^^^^^^
  File "A:\Project\AnturajSurgut\.venv\Lib\site-packages\rest_framework\serializers.py", line 686, in to_representation
    return [
           ^
  File "A:\Project\AnturajSurgut\.venv\Lib\site-packages\rest_framework\serializers.py", line 687, in <listcomp>
    self.child.to_representation(item) for item in iterable
    ^^^^^^^^^^^^^^^^^^^^^^^^^^^^^^^^^^
  File "A:\Project\AnturajSurgut\.venv\Lib\site-packages\rest_framework\serializers.py", line 507, in to_representation
    for field in fields:
  File "A:\Project\AnturajSurgut\.venv\Lib\site-packages\rest_framework\serializers.py", line 368, in _readable_fields
    for field in self.fields.values():
                 ^^^^^^^^^^^
  File "A:\Project\AnturajSurgut\.venv\Lib\site-packages\django\utils\functional.py", line 47, in __get__
    res = instance.__dict__[self.name] = self.func(instance)
                                         ^^^^^^^^^^^^^^^^^^^
  File "A:\Project\AnturajSurgut\.venv\Lib\site-packages\rest_framework\serializers.py", line 356, in fields
    for key, value in self.get_fields().items():
                      ^^^^^^^^^^^^^^^^^
  File "A:\Project\AnturajSurgut\.venv\Lib\site-packages\rest_framework\serializers.py", line 1052, in get_fields
    field_names = self.get_field_names(declared_fields, info)
                  ^^^^^^^^^^^^^^^^^^^^^^^^^^^^^^^^^^^^^^^^^^^
  File "A:\Project\AnturajSurgut\.venv\Lib\site-packages\rest_framework\serializers.py", line 1148, in get_field_names
    assert field_name in fields, (
           ^^^^^^^^^^^^^^^^^^^^
AssertionError: The field 'cart' was declared on serializer CartItemSerializer, but has not been included in the 'fields' option.
[16.02.2024 01:57:43 - ERROR] Internal Server Error: /api/profile/test/, путь: A:\Project\AnturajSurgut\.venv\Lib\site-packages\django\utils\log.py, строка: 241
Traceback (most recent call last):
  File "A:\Project\AnturajSurgut\.venv\Lib\site-packages\django\core\handlers\exception.py", line 55, in inner
    response = get_response(request)
               ^^^^^^^^^^^^^^^^^^^^^
  File "A:\Project\AnturajSurgut\.venv\Lib\site-packages\django\core\handlers\base.py", line 197, in _get_response
    response = wrapped_callback(request, *callback_args, **callback_kwargs)
               ^^^^^^^^^^^^^^^^^^^^^^^^^^^^^^^^^^^^^^^^^^^^^^^^^^^^^^^^^^^^
  File "A:\Project\AnturajSurgut\.venv\Lib\site-packages\django\views\decorators\csrf.py", line 65, in _view_wrapper
    return view_func(request, *args, **kwargs)
           ^^^^^^^^^^^^^^^^^^^^^^^^^^^^^^^^^^^
  File "A:\Project\AnturajSurgut\.venv\Lib\site-packages\django\views\generic\base.py", line 104, in view
    return self.dispatch(request, *args, **kwargs)
           ^^^^^^^^^^^^^^^^^^^^^^^^^^^^^^^^^^^^^^^
  File "A:\Project\AnturajSurgut\.venv\Lib\site-packages\rest_framework\views.py", line 509, in dispatch
    response = self.handle_exception(exc)
               ^^^^^^^^^^^^^^^^^^^^^^^^^^
  File "A:\Project\AnturajSurgut\.venv\Lib\site-packages\rest_framework\views.py", line 469, in handle_exception
    self.raise_uncaught_exception(exc)
  File "A:\Project\AnturajSurgut\.venv\Lib\site-packages\rest_framework\views.py", line 480, in raise_uncaught_exception
    raise exc
  File "A:\Project\AnturajSurgut\.venv\Lib\site-packages\rest_framework\views.py", line 506, in dispatch
    response = handler(request, *args, **kwargs)
               ^^^^^^^^^^^^^^^^^^^^^^^^^^^^^^^^^
  File "A:\Project\AnturajSurgut\.venv\Lib\site-packages\rest_framework\generics.py", line 199, in get
    return self.list(request, *args, **kwargs)
           ^^^^^^^^^^^^^^^^^^^^^^^^^^^^^^^^^^^
  File "A:\Project\AnturajSurgut\backend\profiles\views.py", line 94, in list
    return Response(serializer.data)
                    ^^^^^^^^^^^^^^^
  File "A:\Project\AnturajSurgut\.venv\Lib\site-packages\rest_framework\serializers.py", line 768, in data
    ret = super().data
          ^^^^^^^^^^^^
  File "A:\Project\AnturajSurgut\.venv\Lib\site-packages\rest_framework\serializers.py", line 253, in data
    self._data = self.to_representation(self.instance)
                 ^^^^^^^^^^^^^^^^^^^^^^^^^^^^^^^^^^^^^
  File "A:\Project\AnturajSurgut\.venv\Lib\site-packages\rest_framework\serializers.py", line 686, in to_representation
    return [
           ^
  File "A:\Project\AnturajSurgut\.venv\Lib\site-packages\rest_framework\serializers.py", line 687, in <listcomp>
    self.child.to_representation(item) for item in iterable
    ^^^^^^^^^^^^^^^^^^^^^^^^^^^^^^^^^^
  File "A:\Project\AnturajSurgut\.venv\Lib\site-packages\rest_framework\serializers.py", line 507, in to_representation
    for field in fields:
  File "A:\Project\AnturajSurgut\.venv\Lib\site-packages\rest_framework\serializers.py", line 368, in _readable_fields
    for field in self.fields.values():
                 ^^^^^^^^^^^
  File "A:\Project\AnturajSurgut\.venv\Lib\site-packages\django\utils\functional.py", line 47, in __get__
    res = instance.__dict__[self.name] = self.func(instance)
                                         ^^^^^^^^^^^^^^^^^^^
  File "A:\Project\AnturajSurgut\.venv\Lib\site-packages\rest_framework\serializers.py", line 356, in fields
    for key, value in self.get_fields().items():
                      ^^^^^^^^^^^^^^^^^
  File "A:\Project\AnturajSurgut\.venv\Lib\site-packages\rest_framework\serializers.py", line 1052, in get_fields
    field_names = self.get_field_names(declared_fields, info)
                  ^^^^^^^^^^^^^^^^^^^^^^^^^^^^^^^^^^^^^^^^^^^
  File "A:\Project\AnturajSurgut\.venv\Lib\site-packages\rest_framework\serializers.py", line 1148, in get_field_names
    assert field_name in fields, (
           ^^^^^^^^^^^^^^^^^^^^
AssertionError: The field 'cart_items' was declared on serializer CartSerializer, but has not been included in the 'fields' option.
[16.02.2024 01:57:44 - ERROR] Internal Server Error: /api/profile/test/, путь: A:\Project\AnturajSurgut\.venv\Lib\site-packages\django\utils\log.py, строка: 241
Traceback (most recent call last):
  File "A:\Project\AnturajSurgut\.venv\Lib\site-packages\django\core\handlers\exception.py", line 55, in inner
    response = get_response(request)
               ^^^^^^^^^^^^^^^^^^^^^
  File "A:\Project\AnturajSurgut\.venv\Lib\site-packages\django\core\handlers\base.py", line 197, in _get_response
    response = wrapped_callback(request, *callback_args, **callback_kwargs)
               ^^^^^^^^^^^^^^^^^^^^^^^^^^^^^^^^^^^^^^^^^^^^^^^^^^^^^^^^^^^^
  File "A:\Project\AnturajSurgut\.venv\Lib\site-packages\django\views\decorators\csrf.py", line 65, in _view_wrapper
    return view_func(request, *args, **kwargs)
           ^^^^^^^^^^^^^^^^^^^^^^^^^^^^^^^^^^^
  File "A:\Project\AnturajSurgut\.venv\Lib\site-packages\django\views\generic\base.py", line 104, in view
    return self.dispatch(request, *args, **kwargs)
           ^^^^^^^^^^^^^^^^^^^^^^^^^^^^^^^^^^^^^^^
  File "A:\Project\AnturajSurgut\.venv\Lib\site-packages\rest_framework\views.py", line 509, in dispatch
    response = self.handle_exception(exc)
               ^^^^^^^^^^^^^^^^^^^^^^^^^^
  File "A:\Project\AnturajSurgut\.venv\Lib\site-packages\rest_framework\views.py", line 469, in handle_exception
    self.raise_uncaught_exception(exc)
  File "A:\Project\AnturajSurgut\.venv\Lib\site-packages\rest_framework\views.py", line 480, in raise_uncaught_exception
    raise exc
  File "A:\Project\AnturajSurgut\.venv\Lib\site-packages\rest_framework\views.py", line 506, in dispatch
    response = handler(request, *args, **kwargs)
               ^^^^^^^^^^^^^^^^^^^^^^^^^^^^^^^^^
  File "A:\Project\AnturajSurgut\.venv\Lib\site-packages\rest_framework\generics.py", line 199, in get
    return self.list(request, *args, **kwargs)
           ^^^^^^^^^^^^^^^^^^^^^^^^^^^^^^^^^^^
  File "A:\Project\AnturajSurgut\backend\profiles\views.py", line 94, in list
    return Response(serializer.data)
                    ^^^^^^^^^^^^^^^
  File "A:\Project\AnturajSurgut\.venv\Lib\site-packages\rest_framework\serializers.py", line 768, in data
    ret = super().data
          ^^^^^^^^^^^^
  File "A:\Project\AnturajSurgut\.venv\Lib\site-packages\rest_framework\serializers.py", line 253, in data
    self._data = self.to_representation(self.instance)
                 ^^^^^^^^^^^^^^^^^^^^^^^^^^^^^^^^^^^^^
  File "A:\Project\AnturajSurgut\.venv\Lib\site-packages\rest_framework\serializers.py", line 686, in to_representation
    return [
           ^
  File "A:\Project\AnturajSurgut\.venv\Lib\site-packages\rest_framework\serializers.py", line 687, in <listcomp>
    self.child.to_representation(item) for item in iterable
    ^^^^^^^^^^^^^^^^^^^^^^^^^^^^^^^^^^
  File "A:\Project\AnturajSurgut\.venv\Lib\site-packages\rest_framework\serializers.py", line 507, in to_representation
    for field in fields:
  File "A:\Project\AnturajSurgut\.venv\Lib\site-packages\rest_framework\serializers.py", line 368, in _readable_fields
    for field in self.fields.values():
                 ^^^^^^^^^^^
  File "A:\Project\AnturajSurgut\.venv\Lib\site-packages\django\utils\functional.py", line 47, in __get__
    res = instance.__dict__[self.name] = self.func(instance)
                                         ^^^^^^^^^^^^^^^^^^^
  File "A:\Project\AnturajSurgut\.venv\Lib\site-packages\rest_framework\serializers.py", line 356, in fields
    for key, value in self.get_fields().items():
                      ^^^^^^^^^^^^^^^^^
  File "A:\Project\AnturajSurgut\.venv\Lib\site-packages\rest_framework\serializers.py", line 1052, in get_fields
    field_names = self.get_field_names(declared_fields, info)
                  ^^^^^^^^^^^^^^^^^^^^^^^^^^^^^^^^^^^^^^^^^^^
  File "A:\Project\AnturajSurgut\.venv\Lib\site-packages\rest_framework\serializers.py", line 1148, in get_field_names
    assert field_name in fields, (
           ^^^^^^^^^^^^^^^^^^^^
AssertionError: The field 'cart_items' was declared on serializer CartSerializer, but has not been included in the 'fields' option.
